Workbook

Sheet PETUNJUK
B1: Mantam Product
B2: Akuntansi Terintegrasi
B3: Dari jurnal umum ke neraca saldo, laba rugi, dan neraca secara otomatis. Cukup isi jurnal; semua laporan ikut berubah.
B5: Lisensi | C5: VERSI DEMO. Kapasitas dan fitur dibatasi. Pesan versi lengkap: WhatsApp 089623291732
B7: Cara memakai
B8: Langkah 1 | C8: Buka PARAMETER, isi nama perusahaan dan tanggal periode laporan.
B9: Langkah 2 | C9: Periksa atau tambah akun di COA (kode unik, tipe, saldo normal D/K, grup laporan).
B10: Langkah 3 | C10: Catat transaksi di JURNAL: satu nomor bukti per transaksi, total debit harus sama dengan kredit (kolom Cek harus OK).
B11: Langkah 4 | C11: Baca laporan di NERACA_SALDO, LABA_RUGI, NERACA. Cek keseimbangan harus berstatus SEIMBANG.
B13: Isi berkas
B14: PARAMETER | C14: Nama perusahaan, awal tahun buku, periode laporan, tarif pajak.
B15: COA | C15: Daftar akun (kode, tipe, saldo normal, grup laporan). Kapasitas 30 akun.
B16: JURNAL | C16: Jurnal umum. Kapasitas 80 baris; kolom pengecekan keseimbangan per bukti otomatis.
B17: NERACA_SALDO | C17: Mutasi dan saldo tiap akun sampai akhir periode, dengan cek debit = kredit.
B18: LABA_RUGI | C18: Laporan laba rugi per periode dengan rincian dan persentase terhadap pendapatan.
B19: NERACA | C19: Laporan posisi keuangan per akhir periode, dengan cek keseimbangan otomatis.
B21: Legenda warna
B22: Teks biru | C22: Sel input: boleh Anda ubah (tidak terkunci).
B23: Sel kuning | C23: Parameter kunci: periksa terlebih dulu.
B24: Teks hitam | C24: Rumus otomatis (terkunci; Review > Unprotect Sheet tanpa kata sandi bila perlu).
B26: Catatan
C27: • Seluruh data adalah simulasi buatan, bukan data perusahaan nyata.
C28: • Hasil perhitungan adalah alat bantu; verifikasi dengan akuntan/konsultan sebelum dipakai untuk keputusan atau pelaporan resmi.
C29: • Untuk akun baru: pilih grup laporan yang sudah ada agar otomatis masuk ke laporan (baris 'lainnya').
C30: • Estimasi pajak penghasilan bersifat sederhana (tarif × laba sebelum pajak); sesuaikan dengan ketentuan perpajakan Anda.

Sheet PARAMETER
A1: Parameter
A2: Isi sel kuning sebelum membaca laporan.
A3: VERSI DEMO: kapasitas & fitur dibatasi, data simulasi. Versi lengkap: WhatsApp 089623291732
B5: Nama perusahaan | C5: PT Contoh Sejahtera (simulasi)
B6: Awal tahun buku | C6: 46023
B7: Awal periode laporan | C7: 46023 | D7: Laba rugi menghitung dari tanggal ini
B8: Akhir periode laporan | C8: 46081 | D8: Neraca & neraca saldo per tanggal ini
B9: Tarif pajak penghasilan (estimasi) | C9: 0.22 | D9: Sederhana; sesuaikan dengan ketentuan Anda

Sheet COA
A1: Daftar Akun (Chart of Accounts)
A2: Kapasitas 30 akun
A3: VERSI DEMO: kapasitas & fitur dibatasi, data simulasi. Versi lengkap: WhatsApp 089623291732
A5: Kode | B5: Nama Akun | C5: Tipe | D5: Saldo Normal | E5: Grup Laporan
A6: 1101 | B6: Kas | C6: Aset | D6: D | E6: Aset Lancar
A7: 1102 | B7: Bank | C7: Aset | D7: D | E7: Aset Lancar
A8: 1201 | B8: Piutang Usaha | C8: Aset | D8: D | E8: Aset Lancar
A9: 1301 | B9: Persediaan Barang Dagang | C9: Aset | D9: D | E9: Aset Lancar
A10: 1401 | B10: Beban Dibayar Dimuka | C10: Aset | D10: D | E10: Aset Lancar
A11: 1501 | B11: Peralatan Kantor | C11: Aset | D11: D | E11: Aset Tetap
A12: 1502 | B12: Akumulasi Penyusutan Peralatan | C12: Aset | D12: K | E12: Aset Tetap
A13: 2101 | B13: Utang Usaha | C13: Kewajiban | D13: K | E13: Kewajiban Lancar
A14: 2102 | B14: Utang Gaji | C14: Kewajiban | D14: K | E14: Kewajiban Lancar
A15: 2103 | B15: Utang Pajak | C15: Kewajiban | D15: K | E15: Kewajiban Lancar
A16: 2201 | B16: Utang Bank Jangka Panjang | C16: Kewajiban | D16: K | E16: Kewajiban Jangka Panjang
A17: 3101 | B17: Modal Disetor | C17: Ekuitas | D17: K | E17: Ekuitas
... A29: 7201 | B29: Beban Bunga | C29: Beban | D29: D | E29: Pendapatan/Beban Lain

Sheet JURNAL
A1: Jurnal Umum
A2: Kapasitas 80 baris. Isi kolom bertulisan biru.
A3: VERSI DEMO: kapasitas & fitur dibatasi, data simulasi. Versi lengkap: WhatsApp 089623291732
E4: Total | F4: =SUM(F6:F85) | G4: =SUM(G6:G85) | H4: =IF(ROUND(F4-G4,0)=0,"SEIMBANG","SELISIH")
A5: Tanggal | B5: No. Bukti | C5: Kode Akun | D5: Nama Akun | E5: Keterangan | F5: Debit (Rp) | G5: Kredit (Rp) | H5: Cek Bukti | I5: Tipe | J5: Grup
A6: 46023 | B6: JU-2026-001 | C6: 1101 | D6: =IF(C6="","",IFERROR(INDEX(COA!$B$6:$B$35,MATCH(C6,COA!$A$6:$A$35,0)),"AKUN TIDAK ADA")) | E6: Saldo awal | F6: 25000000 | H6: =IF(B6="","",IF(ROUND(SUMIFS($F$6:$F$85,$B$6:$B$85,B6)-SUMIFS($G$6:$G$85,$B$6:$B$85,B6),0)=0,"OK","TIDAK SEIMBANG")) | I6: =IF(C6="","",IFERROR(INDEX(COA!$C$6:$C$35,MATCH(C6,COA!$A$6:$A$35,0)),"")) | J6: =IF(C6="","",IFERROR(INDEX(COA!$E$6:$E$35,MATCH(C6,COA!$A$6:$A$35,0)),""))
A7: 46023 | B7: JU-2026-001 | C7: 1102 | D7: =IF(C7="","",IFERROR(INDEX(COA!$B$6:$B$35,MATCH(C7,COA!$A$6:$A$35,0)),"AKUN TIDAK ADA")) | E7: Saldo awal | F7: 150000000 | H7: =IF(B7="","",IF(ROUND(SUMIFS($F$6:$F$85,$B$6:$B$85,B7)-SUMIFS($G$6:$G$85,$B$6:$B$85,B7),0)=0,"OK","TIDAK SEIMBANG")) | I7: =IF(C7="","",IFERROR(INDEX(COA!$C$6:$C$35,MATCH(C7,COA!$A$6:$A$35,0)),"")) | J7: =IF(C7="","",IFERROR(INDEX(COA!$E$6:$E$35,MATCH(C7,COA!$A$6:$A$35,0)),""))
A8: 46023 | B8: JU-2026-001 | C8: 1301 | D8: =IF(C8="","",IFERROR(INDEX(COA!$B$6:$B$35,MATCH(C8,COA!$A$6:$A$35,0)),"AKUN TIDAK ADA")) | E8: Saldo awal | F8: 80000000 | H8: =IF(B8="","",IF(ROUND(SUMIFS($F$6:$F$85,$B$6:$B$85,B8)-SUMIFS($G$6:$G$85,$B$6:$B$85,B8),0)=0,"OK","TIDAK SEIMBANG")) | I8: =IF(C8="","",IFERROR(INDEX(COA!$C$6:$C$35,MATCH(C8,COA!$A$6:$A$35,0)),"")) | J8: =IF(C8="","",IFERROR(INDEX(COA!$E$6:$E$35,MATCH(C8,COA!$A$6:$A$35,0)),""))
A9: 46023 | B9: JU-2026-001 | C9: 1501 | D9: =IF(C9="","",IFERROR(INDEX(COA!$B$6:$B$35,MATCH(C9,COA!$A$6:$A$35,0)),"AKUN TIDAK ADA")) | E9: Saldo awal | F9: 60000000 | H9: =IF(B9="","",IF(ROUND(SUMIFS($F$6:$F$85,$B$6:$B$85,B9)-SUMIFS($G$6:$G$85,$B$6:$B$85,B9),0)=0,"OK","TIDAK SEIMBANG")) | I9: =IF(C9="","",IFERROR(INDEX(COA!$C$6:$C$35,MATCH(C9,COA!$A$6:$A$35,0)),"")) | J9: =IF(C9="","",IFERROR(INDEX(COA!$E$6:$E$35,MATCH(C9,COA!$A$6:$A$35,0)),""))
A10: 46023 | B10: JU-2026-001 | C10: 2201 | D10: =IF(C10="","",IFERROR(INDEX(COA!$B$6:$B$35,MATCH(C10,COA!$A$6:$A$35,0)),"AKUN TIDAK ADA")) | E10: Saldo awal | G10: 100000000 | H10: =IF(B10="","",IF(ROUND(SUMIFS($F$6:$F$85,$B$6:$B$85,B10)-SUMIFS($G$6:$G$85,$B$6:$B$85,B10),0)=0,"OK","TIDAK SEIMBANG")) | I10: =IF(C10="","",IFERROR(INDEX(COA!$C$6:$C$35,MATCH(C10,COA!$A$6:$A$35,0)),"")) | J10: =IF(C10="","",IFERROR(INDEX(COA!$E$6:$E$35,MATCH(C10,COA!$A$6:$A$35,0)),""))
A11: 46023 | B11: JU-2026-001 | C11: 3101 | D11: =IF(C11="","",IFERROR(INDEX(COA!$B$6:$B$35,MATCH(C11,COA!$A$6:$A$35,0)),"AKUN TIDAK ADA")) | E11: Saldo awal | G11: 215000000 | H11: =IF(B11="","",IF(ROUND(SUMIFS($F$6:$F$85,$B$6:$B$85,B11)-SUMIFS($G$6:$G$85,$B$6:$B$85,B11),0)=0,"OK","TIDAK SEIMBANG")) | I11: =IF(C11="","",IFERROR(INDEX(COA!$C$6:$C$35,MATCH(C11,COA!$A$6:$A$35,0)),"")) | J11: =IF(C11="","",IFERROR(INDEX(COA!$E$6:$E$35,MATCH(C11,COA!$A$6:$A$35,0)),""))
A12: 46025 | B12: JU-2026-002 | C12: 1301 | D12: =IF(C12="","",IFERROR(INDEX(COA!$B$6:$B$35,MATCH(C12,COA!$A$6:$A$35,0)),"AKUN TIDAK ADA")) | E12: Pembelian persediaan kredit | F12: 87000000 | H12: =IF(B12="","",IF(ROUND(SUMIFS($F$6:$F$85,$B$6:$B$85,B12)-SUMIFS($G$6:$G$85,$B$6:$B$85,B12),0)=0,"OK","TIDAK SEIMBANG")) | I12: =IF(C12="","",IFERROR(INDEX(COA!$C$6:$C$35,MATCH(C12,COA!$A$6:$A$35,0)),"")) | J12: =IF(C12="","",IFERROR(INDEX(COA!$E$6:$E$35,MATCH(C12,COA!$A$6:$A$35,0)),""))
A13: 46025 | B13: JU-2026-002 | C13: 2101 | D13: =IF(C13="","",IFERROR(INDEX(COA!$B$6:$B$35,MATCH(C13,COA!$A$6:$A$35,0)),"AKUN TIDAK ADA")) | E13: Pembelian persediaan kredit | G13: 87000000 | H13: =IF(B13="","",IF(ROUND(SUMIFS($F$6:$F$85,$B$6:$B$85,B13)-SUMIFS($G$6:$G$85,$B$6:$B$85,B13),0)=0,"OK","TIDAK SEIMBANG")) | I13: =IF(C13="","",IFERROR(INDEX(COA!$C$6:$C$35,MATCH(C13,COA!$A$6:$A$35,0)),"")) | J13: =IF(C13="","",IFERROR(INDEX(COA!$E$6:$E$35,MATCH(C13,COA!$A$6:$A$35,0)),""))
A14: 46028 | B14: JU-2026-003 | C14: 1201 | D14: =IF(C14="","",IFERROR(INDEX(COA!$B$6:$B$35,MATCH(C14,COA!$A$6:$A$35,0)),"AKUN TIDAK ADA")) | E14: Penjualan kredit | F14: 128000000 | H14: =IF(B14="","",IF(ROUND(SUMIFS($F$6:$F$85,$B$6:$B$85,B14)-SUMIFS($G$6:$G$85,$B$6:$B$85,B14),0)=0,"OK","TIDAK SEIMBANG")) | I14: =IF(C14="","",IFERROR(INDEX(COA!$C$6:$C$35,MATCH(C14,COA!$A$6:$A$35,0)),"")) | J14: =IF(C14="","",IFERROR(INDEX(COA!$E$6:$E$35,MATCH(C14,COA!$A$6:$A$35,0)),""))
A15: 46028 | B15: JU-2026-003 | C15: 4101 | D15: =IF(C15="","",IFERROR(INDEX(COA!$B$6:$B$35,MATCH(C15,COA!$A$6:$A$35,0)),"AKUN TIDAK ADA")) | E15: Penjualan kredit | G15: 128000000 | H15: =IF(B15="","",IF(ROUND(SUMIFS($F$6:$F$85,$B$6:$B$85,B15)-SUMIFS($G$6:$G$85,$B$6:$B$85,B15),0)=0,"OK","TIDAK SEIMBANG")) | I15: =IF(C15="","",IFERROR(INDEX(COA!$C$6:$C$35,MATCH(C15,COA!$A$6:$A$35,0)),"")) | J15: =IF(C15="","",IFERROR(INDEX(COA!$E$6:$E$35,MATCH(C15,COA!$A$6:$A$35,0)),""))
A16: 46028 | B16: JU-2026-004 | C16: 5101 | D16: =IF(C16="","",IFERROR(INDEX(COA!$B$6:$B$35,MATCH(C16,COA!$A$6:$A$35,0)),"AKUN TIDAK ADA")) | E16: HPP penjualan | F16: 76800000 | H16: =IF(B16="","",IF(ROUND(SUMIFS($F$6:$F$85,$B$6:$B$85,B16)-SUMIFS($G$6:$G$85,$B$6:$B$85,B16),0)=0,"OK","TIDAK SEIMBANG")) | I16: =IF(C16="","",IFERROR(INDEX(COA!$C$6:$C$35,MATCH(C16,COA!$A$6:$A$35,0)),"")) | J16: =IF(C16="","",IFERROR(INDEX(COA!$E$6:$E$35,MATCH(C16,COA!$A$6:$A$35,0)),""))
A17: 46028 | B17: JU-2026-004 | C17: 1301 | D17: =IF(C17="","",IFERROR(INDEX(COA!$B$6:$B$35,MATCH(C17,COA!$A$6:$A$35,0)),"AKUN TIDAK ADA")) | E17: HPP penjualan | G17: 76800000 | H17: =IF(B17="","",IF(ROUND(SUMIFS($F$6:$F$85,$B$6:$B$85,B17)-SUMIFS($G$6:$G$85,$B$6:$B$85,B17),0)=0,"OK","TIDAK SEIMBANG")) | I17: =IF(C17="","",IFERROR(INDEX(COA!$C$6:$C$35,MATCH(C17,COA!$A$6:$A$35,0)),"")) | J17: =IF(C17="","",IFERROR(INDEX(COA!$E$6:$E$35,MATCH(C17,COA!$A$6:$A$35,0)),""))
A18: 46034 | B18: JU-2026-005 | C18: 1102 | D18: =IF(C18="","",IFERROR(INDEX(COA!$B$6:$B$35,MATCH(C18,COA!$A$6:$A$35,0)),"AKUN TIDAK ADA")) | E18: Penerimaan piutang | F18: 102400000 | H18: =IF(B18="","",IF(ROUND(SUMIFS($F$6:$F$85,$B$6:$B$85,B18)-SUMIFS($G$6:$G$85,$B$6:$B$85,B18),0)=0,"OK","TIDAK SEIMBANG")) | I18: =IF(C18="","",IFERROR(INDEX(COA!$C$6:$C$35,MATCH(C18,COA!$A$6:$A$35,0)),"")) | J18: =IF(C18="","",IFERROR(INDEX(COA!$E$6:$E$35,MATCH(C18,COA!$A$6:$A$35,0)),""))
A19: 46034 | B19: JU-2026-005 | C19: 1201 | D19: =IF(C19="","",IFERROR(INDEX(COA!$B$6:$B$35,MATCH(C19,COA!$A$6:$A$35,0)),"AKUN TIDAK ADA")) | E19: Penerimaan piutang | G19: 102400000 | H19: =IF(B19="","",IF(ROUND(SUMIFS($F$6:$F$85,$B$6:$B$85,B19)-SUMIFS($G$6:$G$85,$B$6:$B$85,B19),0)=0,"OK","TIDAK SEIMBANG")) | I19: =IF(C19="","",IFERROR(INDEX(COA!$C$6:$C$35,MATCH(C19,COA!$A$6:$A$35,0)),"")) | J19: =IF(C19="","",IFERROR(INDEX(COA!$E$6:$E$35,MATCH(C19,COA!$A$6:$A$35,0)),""))
A20: 46036 | B20: JU-2026-006 | C20: 2101 | D20: =IF(C20="","",IFERROR(INDEX(COA!$B$6:$B$35,MATCH(C20,COA!$A$6:$A$35,0)),"AKUN TIDAK ADA")) | E20: Pembayaran utang usaha | F20: 73950000 | H20: =IF(B20="","",IF(ROUND(SUMIFS($F$6:$F$85,$B$6:$B$85,B20)-SUMIFS($G$6:$G$85,$B$6:$B$85,B20),0)=0,"OK","TIDAK SEIMBANG")) | I20: =IF(C20="","",IFERROR(INDEX(COA!$C$6:$C$35,MATCH(C20,COA!$A$6:$A$35,0)),"")) | J20: =IF(C20="","",IFERROR(INDEX(COA!$E$6:$E$35,MATCH(C20,COA!$A$6:$A$35,0)),""))
A21: 46036 | B21: JU-2026-006 | C21: 1102 | D21: =IF(C21="","",IFERROR(INDEX(COA!$B$6:$B$35,MATCH(C21,COA!$A$6:$A$35,0)),"AKUN TIDAK ADA")) | E21: Pembayaran utang usaha | G21: 73950000 | H21: =IF(B21="","",IF(ROUND(SUMIFS($F$6:$F$85,$B$6:$B$85,B21)-SUMIFS($G$6:$G$85,$B$6:$B$85,B21),0)=0,"OK","TIDAK SEIMBANG")) | I21: =IF(C21="","",IFERROR(INDEX(COA!$C$6:$C$35,MATCH(C21,COA!$A$6:$A$35,0)),"")) | J21: =IF(C21="","",IFERROR(INDEX(COA!$E$6:$E$35,MATCH(C21,COA!$A$6:$A$35,0)),""))
A22: 46047 | B22: JU-2026-007 | C22: 6101 | D22: =IF(C22="","",IFERROR(INDEX(COA!$B$6:$B$35,MATCH(C22,COA!$A$6:$A$35,0)),"AKUN TIDAK ADA")) | E22: Gaji karyawan | F22: 18000000 | H22: =IF(B22="","",IF(ROUND(SUMIFS($F$6:$F$85,$B$6:$B$85,B22)-SUMIFS($G$6:$G$85,$B$6:$B$85,B22),0)=0,"OK","TIDAK SEIMBANG")) | I22: =IF(C22="","",IFERROR(INDEX(COA!$C$6:$C$35,MATCH(C22,COA!$A$6:$A$35,0)),"")) | J22: =IF(C22="","",IFERROR(INDEX(COA!$E$6:$E$35,MATCH(C22,COA!$A$6:$A$35,0)),""))
A23: 46047 | B23: JU-2026-007 | C23: 1102 | D23: =IF(C23="","",IFERROR(INDEX(COA!$B$6:$B$35,MATCH(C23,COA!$A$6:$A$35,0)),"AKUN TIDAK ADA")) | E23: Gaji karyawan | G23: 18000000 | H23: =IF(B23="","",IF(ROUND(SUMIFS($F$6:$F$85,$B$6:$B$85,B23)-SUMIFS($G$6:$G$85,$B$6:$B$85,B23),0)=0,"OK","TIDAK SEIMBANG")) | I23: =IF(C23="","",IFERROR(INDEX(COA!$C$6:$C$35,MATCH(C23,COA!$A$6:$A$35,0)),"")) | J23: =IF(C23="","",IFERROR(INDEX(COA!$E$6:$E$35,MATCH(C23,COA!$A$6:$A$35,0)),""))
A24: 46024 | B24: JU-2026-008 | C24: 6102 | D24: =IF(C24="","",IFERROR(INDEX(COA!$B$6:$B$35,MATCH(C24,COA!$A$6:$A$35,0)),"AKUN TIDAK ADA")) | E24: Sewa kantor | F24: 5000000 | H24: =IF(B24="","",IF(ROUND(SUMIFS($F$6:$F$85,$B$6:$B$85,B24)-SUMIFS($G$6:$G$85,$B$6:$B$85,B24),0)=0,"OK","TIDAK SEIMBANG")) | I24: =IF(C24="","",IFERROR(INDEX(COA!$C$6:$C$35,MATCH(C24,COA!$A$6:$A$35,0)),"")) | J24: =IF(C24="","",IFERROR(INDEX(COA!$E$6:$E$35,MATCH(C24,COA!$A$6:$A$35,0)),""))
A25: 46024 | B25: JU-2026-008 | C25: 1102 | D25: =IF(C25="","",IFERROR(INDEX(COA!$B$6:$B$35,MATCH(C25,COA!$A$6:$A$35,0)),"AKUN TIDAK ADA")) | E25: Sewa kantor | G25: 5000000 | H25: =IF(B25="","",IF(ROUND(SUMIFS($F$6:$F$85,$B$6:$B$85,B25)-SUMIFS($G$6:$G$85,$B$6:$B$85,B25),0)=0,"OK","TIDAK SEIMBANG")) | I25: =IF(C25="","",IFERROR(INDEX(COA!$C$6:$C$35,MATCH(C25,COA!$A$6:$A$35,0)),"")) | J25: =IF(C25="","",IFERROR(INDEX(COA!$E$6:$E$35,MATCH(C25,COA!$A$6:$A$35,0)),""))
A26: 46042 | B26: JU-2026-009 | C26: 6103 | D26: =IF(C26="","",IFERROR(INDEX(COA!$B$6:$B$35,MATCH(C26,COA!$A$6:$A$35,0)),"AKUN TIDAK ADA")) | E26: Listrik & air | F26: 1800000 | H26: =IF(B26="","",IF(ROUND(SUMIFS($F$6:$F$85,$B$6:$B$85,B26)-SUMIFS($G$6:$G$85,$B$6:$B$85,B26),0)=0,"OK","TIDAK SEIMBANG")) | I26: =IF(C26="","",IFERROR(INDEX(COA!$C$6:$C$35,MATCH(C26,COA!$A$6:$A$35,0)),"")) | J26: =IF(C26="","",IFERROR(INDEX(COA!$E$6:$E$35,MATCH(C26,COA!$A$6:$A$35,0)),""))
A27: 46042 | B27: JU-2026-009 | C27: 1101 | D27: =IF(C27="","",IFERROR(INDEX(COA!$B$6:$B$35,MATCH(C27,COA!$A$6:$A$35,0)),"AKUN TIDAK ADA")) | E27: Listrik & air | G27: 1800000 | H27: =IF(B27="","",IF(ROUND(SUMIFS($F$6:$F$85,$B$6:$B$85,B27)-SUMIFS($G$6:$G$85,$B$6:$B$85,B27),0)=0,"OK","TIDAK SEIMBANG")) | I27: =IF(C27="","",IFERROR(INDEX(COA!$C$6:$C$35,MATCH(C27,COA!$A$6:$A$35,0)),"")) | J27: =IF(C27="","",IFERROR(INDEX(COA!$E$6:$E$35,MATCH(C27,COA!$A$6:$A$35,0)),""))
A28: 46040 | B28: JU-2026-010 | C28: 6104 | D28: =IF(C28="","",IFERROR(INDEX(COA!$B$6:$B$35,MATCH(C28,COA!$A$6:$A$35,0)),"AKUN TIDAK ADA")) | E28: Biaya pemasaran | F28: 5600000 | H28: =IF(B28="","",IF(ROUND(SUMIFS($F$6:$F$85,$B$6:$B$85,B28)-SUMIFS($G$6:$G$85,$B$6:$B$85,B28),0)=0,"OK","TIDAK SEIMBANG")) | I28: =IF(C28="","",IFERROR(INDEX(COA!$C$6:$C$35,MATCH(C28,COA!$A$6:$A$35,0)),"")) | J28: =IF(C28="","",IFERROR(INDEX(COA!$E$6:$E$35,MATCH(C28,COA!$A$6:$A$35,0)),""))
A29: 46040 | B29: JU-2026-010 | C29: 1102 | D29: =IF(C29="","",IFERROR(INDEX(COA!$B$6:$B$35,MATCH(C29,COA!$A$6:$A$35,0)),"AKUN TIDAK ADA")) | E29: Biaya pemasaran | G29: 5600000 | H29: =IF(B29="","",IF(ROUND(SUMIFS($F$6:$F$85,$B$6:$B$85,B29)-SUMIFS($G$6:$G$85,$B$6:$B$85,B29),0)=0,"OK","TIDAK SEIMBANG")) | I29: =IF(C29="","",IFERROR(INDEX(COA!$C$6:$C$35,MATCH(C29,COA!$A$6:$A$35,0)),"")) | J29: =IF(C29="","",IFERROR(INDEX(COA!$E$6:$E$35,MATCH(C29,COA!$A$6:$A$35,0)),""))
A30: 46044 | B30: JU-2026-011 | C30: 6106 | D30: =IF(C30="","",IFERROR(INDEX(COA!$B$6:$B$35,MATCH(C30,COA!$A$6:$A$35,0)),"AKUN TIDAK ADA")) | E30: Administrasi & umum | F30: 1700000 | H30: =IF(B30="","",IF(ROUND(SUMIFS($F$6:$F$85,$B$6:$B$85,B30)-SUMIFS($G$6:$G$85,$B$6:$B$85,B30),0)=0,"OK","TIDAK SEIMBANG")) | I30: =IF(C30="","",IFERROR(INDEX(COA!$C$6:$C$35,MATCH(C30,COA!$A$6:$A$35,0)),"")) | J30: =IF(C30="","",IFERROR(INDEX(COA!$E$6:$E$35,MATCH(C30,COA!$A$6:$A$35,0)),""))
A31: 46044 | B31: JU-2026-011 | C31: 1101 | D31: =IF(C31="","",IFERROR(INDEX(COA!$B$6:$B$35,MATCH(C31,COA!$A$6:$A$35,0)),"AKUN TIDAK ADA")) | E31: Administrasi & umum | G31: 1700000 | H31: =IF(B31="","",IF(ROUND(SUMIFS($F$6:$F$85,$B$6:$B$85,B31)-SUMIFS($G$6:$G$85,$B$6:$B$85,B31),0)=0,"OK","TIDAK SEIMBANG")) | I31: =IF(C31="","",IFERROR(INDEX(COA!$C$6:$C$35,MATCH(C31,COA!$A$6:$A$35,0)),"")) | J31: =IF(C31="","",IFERROR(INDEX(COA!$E$6:$E$35,MATCH(C31,COA!$A$6:$A$35,0)),""))
A32: 46049 | B32: JU-2026-012 | C32: 7201 | D32: =IF(C32="","",IFERROR(INDEX(COA!$B$6:$B$35,MATCH(C32,COA!$A$6:$A$35,0)),"AKUN TIDAK ADA")) | E32: Cicilan bank (bunga) | F32: 900000 | H32: =IF(B32="","",IF(ROUND(SUMIFS($F$6:$F$85,$B$6:$B$85,B32)-SUMIFS($G$6:$G$85,$B$6:$B$85,B32),0)=0,"OK","TIDAK SEIMBANG")) | I32: =IF(C32="","",IFERROR(INDEX(COA!$C$6:$C$35,MATCH(C32,COA!$A$6:$A$35,0)),"")) | J32: =IF(C32="","",IFERROR(INDEX(COA!$E$6:$E$35,MATCH(C32,COA!$A$6:$A$35,0)),""))
A33: 46049 | B33: JU-2026-012 | C33: 1102 | D33: =IF(C33="","",IFERROR(INDEX(COA!$B$6:$B$35,MATCH(C33,COA!$A$6:$A$35,0)),"AKUN TIDAK ADA")) | E33: Cicilan bank (bunga) | G33: 900000 | H33: =IF(B33="","",IF(ROUND(SUMIFS($F$6:$F$85,$B$6:$B$85,B33)-SUMIFS($G$6:$G$85,$B$6:$B$85,B33),0)=0,"OK","TIDAK SEIMBANG")) | I33: =IF(C33="","",IFERROR(INDEX(COA!$C$6:$C$35,MATCH(C33,COA!$A$6:$A$35,0)),"")) | J33: =IF(C33="","",IFERROR(INDEX(COA!$E$6:$E$35,MATCH(C33,COA!$A$6:$A$35,0)),""))
A34: 46049 | B34: JU-2026-013 | C34: 2201 | D34: =IF(C34="","",IFERROR(INDEX(COA!$B$6:$B$35,MATCH(C34,COA!$A$6:$A$35,0)),"AKUN TIDAK ADA")) | E34: Cicilan bank (pokok) | F34: 1500000 | H34: =IF(B34="","",IF(ROUND(SUMIFS($F$6:$F$85,$B$6:$B$85,B34)-SUMIFS($G$6:$G$85,$B$6:$B$85,B34),0)=0,"OK","TIDAK SEIMBANG")) | I34: =IF(C34="","",IFERROR(INDEX(COA!$C$6:$C$35,MATCH(C34,COA!$A$6:$A$35,0)),"")) | J34: =IF(C34="","",IFERROR(INDEX(COA!$E$6:$E$35,MATCH(C34,COA!$A$6:$A$35,0)),""))
A35: 46049 | B35: JU-2026-013 | C35: 1102 | D35: =IF(C35="","",IFERROR(INDEX(COA!$B$6:$B$35,MATCH(C35,COA!$A$6:$A$35,0)),"AKUN TIDAK ADA")) | E35: Cicilan bank (pokok) | G35: 1500000 | H35: =IF(B35="","",IF(ROUND(SUMIFS($F$6:$F$85,$B$6:$B$85,B35)-SUMIFS($G$6:$G$85,$B$6:$B$85,B35),0)=0,"OK","TIDAK SEIMBANG")) | I35: =IF(C35="","",IFERROR(INDEX(COA!$C$6:$C$35,MATCH(C35,COA!$A$6:$A$35,0)),"")) | J35: =IF(C35="","",IFERROR(INDEX(COA!$E$6:$E$35,MATCH(C35,COA!$A$6:$A$35,0)),""))
A36: 46050 | B36: JU-2026-014 | C36: 6105 | D36: =IF(C36="","",IFERROR(INDEX(COA!$B$6:$B$35,MATCH(C36,COA!$A$6:$A$35,0)),"AKUN TIDAK ADA")) | E36: Penyusutan peralatan | F36: 1000000 | H36: =IF(B36="","",IF(ROUND(SUMIFS($F$6:$F$85,$B$6:$B$85,B36)-SUMIFS($G$6:$G$85,$B$6:$B$85,B36),0)=0,"OK","TIDAK SEIMBANG")) | I36: =IF(C36="","",IFERROR(INDEX(COA!$C$6:$C$35,MATCH(C36,COA!$A$6:$A$35,0)),"")) | J36: =IF(C36="","",IFERROR(INDEX(COA!$E$6:$E$35,MATCH(C36,COA!$A$6:$A$35,0)),""))
A37: 46050 | B37: JU-2026-014 | C37: 1502 | D37: =IF(C37="","",IFERROR(INDEX(COA!$B$6:$B$35,MATCH(C37,COA!$A$6:$A$35,0)),"AKUN TIDAK ADA")) | E37: Penyusutan peralatan | G37: 1000000 | H37: =IF(B37="","",IF(ROUND(SUMIFS($F$6:$F$85,$B$6:$B$85,B37)-SUMIFS($G$6:$G$85,$B$6:$B$85,B37),0)=0,"OK","TIDAK SEIMBANG")) | I37: =IF(C37="","",IFERROR(INDEX(COA!$C$6:$C$35,MATCH(C37,COA!$A$6:$A$35,0)),"")) | J37: =IF(C37="","",IFERROR(INDEX(COA!$E$6:$E$35,MATCH(C37,COA!$A$6:$A$35,0)),""))
A38: 46050 | B38: JU-2026-015 | C38: 1102 | D38: =IF(C38="","",IFERROR(INDEX(COA!$B$6:$B$35,MATCH(C38,COA!$A$6:$A$35,0)),"AKUN TIDAK ADA")) | E38: Bunga bank | F38: 200000 | H38: =IF(B38="","",IF(ROUND(SUMIFS($F$6:$F$85,$B$6:$B$85,B38)-SUMIFS($G$6:$G$85,$B$6:$B$85,B38),0)=0,"OK","TIDAK SEIMBANG")) | I38: =IF(C38="","",IFERROR(INDEX(COA!$C$6:$C$35,MATCH(C38,COA!$A$6:$A$35,0)),"")) | J38: =IF(C38="","",IFERROR(INDEX(COA!$E$6:$E$35,MATCH(C38,COA!$A$6:$A$35,0)),""))
A39: 46050 | B39: JU-2026-015 | C39: 7101 | D39: =IF(C39="","",IFERROR(INDEX(COA!$B$6:$B$35,MATCH(C39,COA!$A$6:$A$35,0)),"AKUN TIDAK ADA")) | E39: Bunga bank | G39: 200000 | H39: =IF(B39="","",IF(ROUND(SUMIFS($F$6:$F$85,$B$6:$B$85,B39)-SUMIFS($G$6:$G$85,$B$6:$B$85,B39),0)=0,"OK","TIDAK SEIMBANG")) | I39: =IF(C39="","",IFERROR(INDEX(COA!$C$6:$C$35,MATCH(C39,COA!$A$6:$A$35,0)),"")) | J39: =IF(C39="","",IFERROR(INDEX(COA!$E$6:$E$35,MATCH(C39,COA!$A$6:$A$35,0)),""))
A40: 46030 | B40: JU-2026-016 | C40: 1101 | D40: =IF(C40="","",IFERROR(INDEX(COA!$B$6:$B$35,MATCH(C40,COA!$A$6:$A$35,0)),"AKUN TIDAK ADA")) | E40: Penarikan kas dari bank | F40: 5000000 | H40: =IF(B40="","",IF(ROUND(SUMIFS($F$6:$F$85,$B$6:$B$85,B40)-SUMIFS($G$6:$G$85,$B$6:$B$85,B40),0)=0,"OK","TIDAK SEIMBANG")) | I40: =IF(C40="","",IFERROR(INDEX(COA!$C$6:$C$35,MATCH(C40,COA!$A$6:$A$35,0)),"")) | J40: =IF(C40="","",IFERROR(INDEX(COA!$E$6:$E$35,MATCH(C40,COA!$A$6:$A$35,0)),""))
...

Sheet NERACA_SALDO
A1: Neraca Saldo
A2: Kumulatif sampai akhir periode laporan
A3: VERSI DEMO: kapasitas & fitur dibatasi, data simulasi. Versi lengkap: WhatsApp 089623291732
C4: TOTAL | D4: =SUM(D6:D35) | E4: =SUM(E6:E35) | F4: =SUM(F6:F35) | G4: =SUM(G6:G35) | H4: =IF(ROUND(F4-G4,0)=0,"SEIMBANG","SELISIH")
A5: Kode | B5: Nama Akun | C5: Tipe | D5: Mutasi Debit | E5: Mutasi Kredit | F5: Saldo Debit | G5: Saldo Kredit
A6: =IF(COA!A6="","",COA!A6) | B6: =IF(A6="","",COA!B6) | C6: =IF(A6="","",COA!C6) | D6: =IF(A6="","",SUMIFS(JURNAL!$F$6:$F$85,JURNAL!$C$6:$C$85,A6,JURNAL!$A$6:$A$85,"<="&PARAMETER!$C$8)) | E6: =IF(A6="","",SUMIFS(JURNAL!$G$6:$G$85,JURNAL!$C$6:$C$85,A6,JURNAL!$A$6:$A$85,"<="&PARAMETER!$C$8)) | F6: =IF(A6="","",MAX(0,D6-E6)) | G6: =IF(A6="","",MAX(0,E6-D6))
A7: =IF(COA!A7="","",COA!A7) | B7: =IF(A7="","",COA!B7) | C7: =IF(A7="","",COA!C7) | D7: =IF(A7="","",SUMIFS(JURNAL!$F$6:$F$85,JURNAL!$C$6:$C$85,A7,JURNAL!$A$6:$A$85,"<="&PARAMETER!$C$8)) | E7: =IF(A7="","",SUMIFS(JURNAL!$G$6:$G$85,JURNAL!$C$6:$C$85,A7,JURNAL!$A$6:$A$85,"<="&PARAMETER!$C$8)) | F7: =IF(A7="","",MAX(0,D7-E7)) | G7: =IF(A7="","",MAX(0,E7-D7))
A8: =IF(COA!A8="","",COA!A8) | B8: =IF(A8="","",COA!B8) | C8: =IF(A8="","",COA!C8) | D8: =IF(A8="","",SUMIFS(JURNAL!$F$6:$F$85,JURNAL!$C$6:$C$85,A8,JURNAL!$A$6:$A$85,"<="&PARAMETER!$C$8)) | E8: =IF(A8="","",SUMIFS(JURNAL!$G$6:$G$85,JURNAL!$C$6:$C$85,A8,JURNAL!$A$6:$A$85,"<="&PARAMETER!$C$8)) | F8: =IF(A8="","",MAX(0,D8-E8)) | G8: =IF(A8="","",MAX(0,E8-D8))
A9: =IF(COA!A9="","",COA!A9) | B9: =IF(A9="","",COA!B9) | C9: =IF(A9="","",COA!C9) | D9: =IF(A9="","",SUMIFS(JURNAL!$F$6:$F$85,JURNAL!$C$6:$C$85,A9,JURNAL!$A$6:$A$85,"<="&PARAMETER!$C$8)) | E9: =IF(A9="","",SUMIFS(JURNAL!$G$6:$G$85,JURNAL!$C$6:$C$85,A9,JURNAL!$A$6:$A$85,"<="&PARAMETER!$C$8)) | F9: =IF(A9="","",MAX(0,D9-E9)) | G9: =IF(A9="","",MAX(0,E9-D9))
A10: =IF(COA!A10="","",COA!A10) | B10: =IF(A10="","",COA!B10) | C10: =IF(A10="","",COA!C10) | D10: =IF(A10="","",SUMIFS(JURNAL!$F$6:$F$85,JURNAL!$C$6:$C$85,A10,JURNAL!$A$6:$A$85,"<="&PARAMETER!$C$8)) | E10: =IF(A10="","",SUMIFS(JURNAL!$G$6:$G$85,JURNAL!$C$6:$C$85,A10,JURNAL!$A$6:$A$85,"<="&PARAMETER!$C$8)) | F10: =IF(A10="","",MAX(0,D10-E10)) | G10: =IF(A10="","",MAX(0,E10-D10))
A11: =IF(COA!A11="","",COA!A11) | B11: =IF(A11="","",COA!B11) | C11: =IF(A11="","",COA!C11) | D11: =IF(A11="","",SUMIFS(JURNAL!$F$6:$F$85,JURNAL!$C$6:$C$85,A11,JURNAL!$A$6:$A$85,"<="&PARAMETER!$C$8)) | E11: =IF(A11="","",SUMIFS(JURNAL!$G$6:$G$85,JURNAL!$C$6:$C$85,A11,JURNAL!$A$6:$A$85,"<="&PARAMETER!$C$8)) | F11: =IF(A11="","",MAX(0,D11-E11)) | G11: =IF(A11="","",MAX(0,E11-D11))
A12: =IF(COA!A12="","",COA!A12) | B12: =IF(A12="","",COA!B12) | C12: =IF(A12="","",COA!C12) | D12: =IF(A12="","",SUMIFS(JURNAL!$F$6:$F$85,JURNAL!$C$6:$C$85,A12,JURNAL!$A$6:$A$85,"<="&PARAMETER!$C$8)) | E12: =IF(A12="","",SUMIFS(JURNAL!$G$6:$G$85,JURNAL!$C$6:$C$85,A12,JURNAL!$A$6:$A$85,"<="&PARAMETER!$C$8)) | F12: =IF(A12="","",MAX(0,D12-E12)) | G12: =IF(A12="","",MAX(0,E12-D12))
A13: =IF(COA!A13="","",COA!A13) | B13: =IF(A13="","",COA!B13) | C13: =IF(A13="","",COA!C13) | D13: =IF(A13="","",SUMIFS(JURNAL!$F$6:$F$85,JURNAL!$C$6:$C$85,A13,JURNAL!$A$6:$A$85,"<="&PARAMETER!$C$8)) | E13: =IF(A13="","",SUMIFS(JURNAL!$G$6:$G$85,JURNAL!$C$6:$C$85,A13,JURNAL!$A$6:$A$85,"<="&PARAMETER!$C$8)) | F13: =IF(A13="","",MAX(0,D13-E13)) | G13: =IF(A13="","",MAX(0,E13-D13))
A14: =IF(COA!A14="","",COA!A14) | B14: =IF(A14="","",COA!B14) | C14: =IF(A14="","",COA!C14) | D14: =IF(A14="","",SUMIFS(JURNAL!$F$6:$F$85,JURNAL!$C$6:$C$85,A14,JURNAL!$A$6:$A$85,"<="&PARAMETER!$C$8)) | E14: =IF(A14="","",SUMIFS(JURNAL!$G$6:$G$85,JURNAL!$C$6:$C$85,A14,JURNAL!$A$6:$A$85,"<="&PARAMETER!$C$8)) | F14: =IF(A14="","",MAX(0,D14-E14)) | G14: =IF(A14="","",MAX(0,E14-D14))
A15: =IF(COA!A15="","",COA!A15) | B15: =IF(A15="","",COA!B15) | C15: =IF(A15="","",COA!C15) | D15: =IF(A15="","",SUMIFS(JURNAL!$F$6:$F$85,JURNAL!$C$6:$C$85,A15,JURNAL!$A$6:$A$85,"<="&PARAMETER!$C$8)) | E15: =IF(A15="","",SUMIFS(JURNAL!$G$6:$G$85,JURNAL!$C$6:$C$85,A15,JURNAL!$A$6:$A$85,"<="&PARAMETER!$C$8)) | F15: =IF(A15="","",MAX(0,D15-E15)) | G15: =IF(A15="","",MAX(0,E15-D15))
A16: =IF(COA!A16="","",COA!A16) | B16: =IF(A16="","",COA!B16) | C16: =IF(A16="","",COA!C16) | D16: =IF(A16="","",SUMIFS(JURNAL!$F$6:$F$85,JURNAL!$C$6:$C$85,A16,JURNAL!$A$6:$A$85,"<="&PARAMETER!$C$8)) | E16: =IF(A16="","",SUMIFS(JURNAL!$G$6:$G$85,JURNAL!$C$6:$C$85,A16,JURNAL!$A$6:$A$85,"<="&PARAMETER!$C$8)) | F16: =IF(A16="","",MAX(0,D16-E16)) | G16: =IF(A16="","",MAX(0,E16-D16))
A17: =IF(COA!A17="","",COA!A17) | B17: =IF(A17="","",COA!B17) | C17: =IF(A17="","",COA!C17) | D17: =IF(A17="","",SUMIFS(JURNAL!$F$6:$F$85,JURNAL!$C$6:$C$85,A17,JURNAL!$A$6:$A$85,"<="&PARAMETER!$C$8)) | E17: =IF(A17="","",SUMIFS(JURNAL!$G$6:$G$85,JURNAL!$C$6:$C$85,A17,JURNAL!$A$6:$A$85,"<="&PARAMETER!$C$8)) | F17: =IF(A17="","",MAX(0,D17-E17)) | G17: =IF(A17="","",MAX(0,E17-D17))
... A35: =IF(COA!A35="","",COA!A35) | B35: =IF(A35="","",COA!B35) | C35: =IF(A35="","",COA!C35) | D35: =IF(A35="","",SUMIFS(JURNAL!$F$6:$F$85,JURNAL!$C$6:$C$85,A35,JURNAL!$A$6:$A$85,"<="&PARAMETER!$C$8)) | E35: =IF(A35="","",SUMIFS(JURNAL!$G$6:$G$85,JURNAL!$C$6:$C$85,A35,JURNAL!$A$6:$A$85,"<="&PARAMETER!$C$8)) | F35: =IF(A35="","",MAX(0,D35-E35)) | G35: =IF(A35="","",MAX(0,E35-D35))

Sheet LABA_RUGI
A1: Laporan Laba Rugi
A2: =PARAMETER!C5&" | Periode "&TEXT(PARAMETER!C7,"dd mmm yyyy")&" s.d. "&TEXT(PARAMETER!C8,"dd mmm yyyy")&" | dalam Rupiah"
A3: VERSI DEMO: kapasitas & fitur dibatasi, data simulasi. Versi lengkap: WhatsApp 089623291732
A5: Uraian | B5: Kode | C5: Jumlah (Rp) | D5: % Pendapatan
A6: PENDAPATAN USAHA
A7: Penjualan | B7: 4101 | C7: =-(SUMIFS(JURNAL!$F$6:$F$85,JURNAL!$C$6:$C$85,4101,JURNAL!$A$6:$A$85,">="&PARAMETER!$C$7,JURNAL!$A$6:$A$85,"<="&PARAMETER!$C$8)-SUMIFS(JURNAL!$G$6:$G$85,JURNAL!$C$6:$C$85,4101,JURNAL!$A$6:$A$85,">="&PARAMETER!$C$7,JURNAL!$A$6:$A$85,"<="&PARAMETER!$C$8)) | D7: =IF($C$10=0,0,C7/$C$10)
A8: Retur & Potongan Penjualan | B8: 4102 | C8: =-(SUMIFS(JURNAL!$F$6:$F$85,JURNAL!$C$6:$C$85,4102,JURNAL!$A$6:$A$85,">="&PARAMETER!$C$7,JURNAL!$A$6:$A$85,"<="&PARAMETER!$C$8)-SUMIFS(JURNAL!$G$6:$G$85,JURNAL!$C$6:$C$85,4102,JURNAL!$A$6:$A$85,">="&PARAMETER!$C$7,JURNAL!$A$6:$A$85,"<="&PARAMETER!$C$8)) | D8: =IF($C$10=0,0,C8/$C$10)
A9: Pendapatan usaha lainnya | C9: =-(SUMIFS(JURNAL!$F$6:$F$85,JURNAL!$J$6:$J$85,"Pendapatan Usaha",JURNAL!$A$6:$A$85,">="&PARAMETER!$C$7,JURNAL!$A$6:$A$85,"<="&PARAMETER!$C$8)-SUMIFS(JURNAL!$G$6:$G$85,JURNAL!$J$6:$J$85,"Pendapatan Usaha",JURNAL!$A$6:$A$85,">="&PARAMETER!$C$7,JURNAL!$A$6:$A$85,"<="&PARAMETER!$C$8))-C7-C8 | D9: =IF($C$10=0,0,C9/$C$10)
A10: PENDAPATAN USAHA NETO | C10: =SUM(C7:C9) | D10: =IF($C$10=0,0,C10/$C$10)
A11: HARGA POKOK PENJUALAN
A12: Harga Pokok Penjualan | B12: 5101 | C12: =(SUMIFS(JURNAL!$F$6:$F$85,JURNAL!$C$6:$C$85,5101,JURNAL!$A$6:$A$85,">="&PARAMETER!$C$7,JURNAL!$A$6:$A$85,"<="&PARAMETER!$C$8)-SUMIFS(JURNAL!$G$6:$G$85,JURNAL!$C$6:$C$85,5101,JURNAL!$A$6:$A$85,">="&PARAMETER!$C$7,JURNAL!$A$6:$A$85,"<="&PARAMETER!$C$8)) | D12: =IF($C$10=0,0,C12/$C$10)
A13: HPP lainnya | C13: =(SUMIFS(JURNAL!$F$6:$F$85,JURNAL!$J$6:$J$85,"HPP",JURNAL!$A$6:$A$85,">="&PARAMETER!$C$7,JURNAL!$A$6:$A$85,"<="&PARAMETER!$C$8)-SUMIFS(JURNAL!$G$6:$G$85,JURNAL!$J$6:$J$85,"HPP",JURNAL!$A$6:$A$85,">="&PARAMETER!$C$7,JURNAL!$A$6:$A$85,"<="&PARAMETER!$C$8))-C12 | D13: =IF($C$10=0,0,C13/$C$10)
A14: TOTAL HPP | C14: =SUM(C12:C13) | D14: =IF($C$10=0,0,C14/$C$10)
A15: LABA KOTOR | C15: =C10-C14 | D15: =IF($C$10=0,0,C15/$C$10)
A16: Margin laba kotor | C16: =IF(C10=0,0,C15/C10)
A17: BEBAN OPERASIONAL
A18: Beban Gaji | B18: 6101 | C18: =(SUMIFS(JURNAL!$F$6:$F$85,JURNAL!$C$6:$C$85,6101,JURNAL!$A$6:$A$85,">="&PARAMETER!$C$7,JURNAL!$A$6:$A$85,"<="&PARAMETER!$C$8)-SUMIFS(JURNAL!$G$6:$G$85,JURNAL!$C$6:$C$85,6101,JURNAL!$A$6:$A$85,">="&PARAMETER!$C$7,JURNAL!$A$6:$A$85,"<="&PARAMETER!$C$8)) | D18: =IF($C$10=0,0,C18/$C$10)
A19: Beban Sewa | B19: 6102 | C19: =(SUMIFS(JURNAL!$F$6:$F$85,JURNAL!$C$6:$C$85,6102,JURNAL!$A$6:$A$85,">="&PARAMETER!$C$7,JURNAL!$A$6:$A$85,"<="&PARAMETER!$C$8)-SUMIFS(JURNAL!$G$6:$G$85,JURNAL!$C$6:$C$85,6102,JURNAL!$A$6:$A$85,">="&PARAMETER!$C$7,JURNAL!$A$6:$A$85,"<="&PARAMETER!$C$8)) | D19: =IF($C$10=0,0,C19/$C$10)
A20: Beban Listrik & Air | B20: 6103 | C20: =(SUMIFS(JURNAL!$F$6:$F$85,JURNAL!$C$6:$C$85,6103,JURNAL!$A$6:$A$85,">="&PARAMETER!$C$7,JURNAL!$A$6:$A$85,"<="&PARAMETER!$C$8)-SUMIFS(JURNAL!$G$6:$G$85,JURNAL!$C$6:$C$85,6103,JURNAL!$A$6:$A$85,">="&PARAMETER!$C$7,JURNAL!$A$6:$A$85,"<="&PARAMETER!$C$8)) | D20: =IF($C$10=0,0,C20/$C$10)
A21: Beban Pemasaran | B21: 6104 | C21: =(SUMIFS(JURNAL!$F$6:$F$85,JURNAL!$C$6:$C$85,6104,JURNAL!$A$6:$A$85,">="&PARAMETER!$C$7,JURNAL!$A$6:$A$85,"<="&PARAMETER!$C$8)-SUMIFS(JURNAL!$G$6:$G$85,JURNAL!$C$6:$C$85,6104,JURNAL!$A$6:$A$85,">="&PARAMETER!$C$7,JURNAL!$A$6:$A$85,"<="&PARAMETER!$C$8)) | D21: =IF($C$10=0,0,C21/$C$10)
A22: Beban Penyusutan | B22: 6105 | C22: =(SUMIFS(JURNAL!$F$6:$F$85,JURNAL!$C$6:$C$85,6105,JURNAL!$A$6:$A$85,">="&PARAMETER!$C$7,JURNAL!$A$6:$A$85,"<="&PARAMETER!$C$8)-SUMIFS(JURNAL!$G$6:$G$85,JURNAL!$C$6:$C$85,6105,JURNAL!$A$6:$A$85,">="&PARAMETER!$C$7,JURNAL!$A$6:$A$85,"<="&PARAMETER!$C$8)) | D22: =IF($C$10=0,0,C22/$C$10)
A23: Beban Administrasi & Umum | B23: 6106 | C23: =(SUMIFS(JURNAL!$F$6:$F$85,JURNAL!$C$6:$C$85,6106,JURNAL!$A$6:$A$85,">="&PARAMETER!$C$7,JURNAL!$A$6:$A$85,"<="&PARAMETER!$C$8)-SUMIFS(JURNAL!$G$6:$G$85,JURNAL!$C$6:$C$85,6106,JURNAL!$A$6:$A$85,">="&PARAMETER!$C$7,JURNAL!$A$6:$A$85,"<="&PARAMETER!$C$8)) | D23: =IF($C$10=0,0,C23/$C$10)
A24: Beban operasional lainnya | C24: =(SUMIFS(JURNAL!$F$6:$F$85,JURNAL!$J$6:$J$85,"Beban Operasional",JURNAL!$A$6:$A$85,">="&PARAMETER!$C$7,JURNAL!$A$6:$A$85,"<="&PARAMETER!$C$8)-SUMIFS(JURNAL!$G$6:$G$85,JURNAL!$J$6:$J$85,"Beban Operasional",JURNAL!$A$6:$A$85,">="&PARAMETER!$C$7,JURNAL!$A$6:$A$85,"<="&PARAMETER!$C$8))-SUM(C18:C23) | D24: =IF($C$10=0,0,C24/$C$10)
A25: TOTAL BEBAN OPERASIONAL | C25: =SUM(C18:C24) | D25: =IF($C$10=0,0,C25/$C$10)
A26: LABA USAHA | C26: =C15-C25 | D26: =IF($C$10=0,0,C26/$C$10)
A27: PENDAPATAN / (BEBAN) LAIN
A28: Pendapatan Bunga | B28: 7101 | C28: =-(SUMIFS(JURNAL!$F$6:$F$85,JURNAL!$C$6:$C$85,7101,JURNAL!$A$6:$A$85,">="&PARAMETER!$C$7,JURNAL!$A$6:$A$85,"<="&PARAMETER!$C$8)-SUMIFS(JURNAL!$G$6:$G$85,JURNAL!$C$6:$C$85,7101,JURNAL!$A$6:$A$85,">="&PARAMETER!$C$7,JURNAL!$A$6:$A$85,"<="&PARAMETER!$C$8)) | D28: =IF($C$10=0,0,C28/$C$10)
A29: Beban Bunga | B29: 7201 | C29: =(SUMIFS(JURNAL!$F$6:$F$85,JURNAL!$C$6:$C$85,7201,JURNAL!$A$6:$A$85,">="&PARAMETER!$C$7,JURNAL!$A$6:$A$85,"<="&PARAMETER!$C$8)-SUMIFS(JURNAL!$G$6:$G$85,JURNAL!$C$6:$C$85,7201,JURNAL!$A$6:$A$85,">="&PARAMETER!$C$7,JURNAL!$A$6:$A$85,"<="&PARAMETER!$C$8)) | D29: =IF($C$10=0,0,C29/$C$10)
A30: Pendapatan/(beban) lain lainnya | C30: =-(SUMIFS(JURNAL!$F$6:$F$85,JURNAL!$J$6:$J$85,"Pendapatan/Beban Lain",JURNAL!$A$6:$A$85,">="&PARAMETER!$C$7,JURNAL!$A$6:$A$85,"<="&PARAMETER!$C$8)-SUMIFS(JURNAL!$G$6:$G$85,JURNAL!$J$6:$J$85,"Pendapatan/Beban Lain",JURNAL!$A$6:$A$85,">="&PARAMETER!$C$7,JURNAL!$A$6:$A$85,"<="&PARAMETER!$C$8))-(C28-C29) | D30: =IF($C$10=0,0,C30/$C$10)
A31: TOTAL LAIN-LAIN (NETO) | C31: =C28-C29+C30 | D31: =IF($C$10=0,0,C31/$C$10)
A32: LABA SEBELUM PAJAK | C32: =C26+C31 | D32: =IF($C$10=0,0,C32/$C$10)
A33: Beban pajak penghasilan (estimasi) | C33: =MAX(0,C32)*PARAMETER!$C$9 | D33: =IF($C$10=0,0,C33/$C$10)
A34: LABA BERSIH | C34: =C32-C33 | D34: =IF($C$10=0,0,C34/$C$10)
A35: Margin laba bersih | C35: =IF(C10=0,0,C34/C10)

Sheet NERACA
A1: Laporan Posisi Keuangan (Neraca)
A2: =PARAMETER!C5&" | Per "&TEXT(PARAMETER!C8,"dd mmm yyyy")&" | dalam Rupiah"
A3: VERSI DEMO: kapasitas & fitur dibatasi, data simulasi. Versi lengkap: WhatsApp 089623291732
A5: Uraian | B5: Kode | C5: Saldo (Rp)
A6: ASET LANCAR
A7: Kas | B7: 1101 | C7: =(SUMIFS(JURNAL!$F$6:$F$85,JURNAL!$C$6:$C$85,1101,JURNAL!$A$6:$A$85,"<="&PARAMETER!$C$8)-SUMIFS(JURNAL!$G$6:$G$85,JURNAL!$C$6:$C$85,1101,JURNAL!$A$6:$A$85,"<="&PARAMETER!$C$8))
A8: Bank | B8: 1102 | C8: =(SUMIFS(JURNAL!$F$6:$F$85,JURNAL!$C$6:$C$85,1102,JURNAL!$A$6:$A$85,"<="&PARAMETER!$C$8)-SUMIFS(JURNAL!$G$6:$G$85,JURNAL!$C$6:$C$85,1102,JURNAL!$A$6:$A$85,"<="&PARAMETER!$C$8))
A9: Piutang Usaha | B9: 1201 | C9: =(SUMIFS(JURNAL!$F$6:$F$85,JURNAL!$C$6:$C$85,1201,JURNAL!$A$6:$A$85,"<="&PARAMETER!$C$8)-SUMIFS(JURNAL!$G$6:$G$85,JURNAL!$C$6:$C$85,1201,JURNAL!$A$6:$A$85,"<="&PARAMETER!$C$8))
A10: Persediaan Barang Dagang | B10: 1301 | C10: =(SUMIFS(JURNAL!$F$6:$F$85,JURNAL!$C$6:$C$85,1301,JURNAL!$A$6:$A$85,"<="&PARAMETER!$C$8)-SUMIFS(JURNAL!$G$6:$G$85,JURNAL!$C$6:$C$85,1301,JURNAL!$A$6:$A$85,"<="&PARAMETER!$C$8))
A11: Beban Dibayar Dimuka | B11: 1401 | C11: =(SUMIFS(JURNAL!$F$6:$F$85,JURNAL!$C$6:$C$85,1401,JURNAL!$A$6:$A$85,"<="&PARAMETER!$C$8)-SUMIFS(JURNAL!$G$6:$G$85,JURNAL!$C$6:$C$85,1401,JURNAL!$A$6:$A$85,"<="&PARAMETER!$C$8))
A12: Aset lancar lainnya | C12: =(SUMIFS(JURNAL!$F$6:$F$85,JURNAL!$J$6:$J$85,"Aset Lancar",JURNAL!$A$6:$A$85,"<="&PARAMETER!$C$8)-SUMIFS(JURNAL!$G$6:$G$85,JURNAL!$J$6:$J$85,"Aset Lancar",JURNAL!$A$6:$A$85,"<="&PARAMETER!$C$8))-SUM(C7:C11)
A13: TOTAL ASET LANCAR | C13: =SUM(C7:C12)
A14: ASET TETAP
A15: Peralatan Kantor | B15: 1501 | C15: =(SUMIFS(JURNAL!$F$6:$F$85,JURNAL!$C$6:$C$85,1501,JURNAL!$A$6:$A$85,"<="&PARAMETER!$C$8)-SUMIFS(JURNAL!$G$6:$G$85,JURNAL!$C$6:$C$85,1501,JURNAL!$A$6:$A$85,"<="&PARAMETER!$C$8))
A16: Akumulasi Penyusutan Peralatan | B16: 1502 | C16: =(SUMIFS(JURNAL!$F$6:$F$85,JURNAL!$C$6:$C$85,1502,JURNAL!$A$6:$A$85,"<="&PARAMETER!$C$8)-SUMIFS(JURNAL!$G$6:$G$85,JURNAL!$C$6:$C$85,1502,JURNAL!$A$6:$A$85,"<="&PARAMETER!$C$8))
A17: Aset tetap lainnya | C17: =(SUMIFS(JURNAL!$F$6:$F$85,JURNAL!$J$6:$J$85,"Aset Tetap",JURNAL!$A$6:$A$85,"<="&PARAMETER!$C$8)-SUMIFS(JURNAL!$G$6:$G$85,JURNAL!$J$6:$J$85,"Aset Tetap",JURNAL!$A$6:$A$85,"<="&PARAMETER!$C$8))-C15-C16
A18: TOTAL ASET TETAP (NETO) | C18: =SUM(C15:C17)
A19: TOTAL ASET | C19: =C13+C18
A21: KEWAJIBAN LANCAR
A22: Utang Usaha | B22: 2101 | C22: =-(SUMIFS(JURNAL!$F$6:$F$85,JURNAL!$C$6:$C$85,2101,JURNAL!$A$6:$A$85,"<="&PARAMETER!$C$8)-SUMIFS(JURNAL!$G$6:$G$85,JURNAL!$C$6:$C$85,2101,JURNAL!$A$6:$A$85,"<="&PARAMETER!$C$8))
A23: Utang Gaji | B23: 2102 | C23: =-(SUMIFS(JURNAL!$F$6:$F$85,JURNAL!$C$6:$C$85,2102,JURNAL!$A$6:$A$85,"<="&PARAMETER!$C$8)-SUMIFS(JURNAL!$G$6:$G$85,JURNAL!$C$6:$C$85,2102,JURNAL!$A$6:$A$85,"<="&PARAMETER!$C$8))
A24: Utang Pajak | B24: 2103 | C24: =-(SUMIFS(JURNAL!$F$6:$F$85,JURNAL!$C$6:$C$85,2103,JURNAL!$A$6:$A$85,"<="&PARAMETER!$C$8)-SUMIFS(JURNAL!$G$6:$G$85,JURNAL!$C$6:$C$85,2103,JURNAL!$A$6:$A$85,"<="&PARAMETER!$C$8))
A25: Estimasi utang pajak penghasilan | C25: =C44
A26: Kewajiban lancar lainnya | C26: =-(SUMIFS(JURNAL!$F$6:$F$85,JURNAL!$J$6:$J$85,"Kewajiban Lancar",JURNAL!$A$6:$A$85,"<="&PARAMETER!$C$8)-SUMIFS(JURNAL!$G$6:$G$85,JURNAL!$J$6:$J$85,"Kewajiban Lancar",JURNAL!$A$6:$A$85,"<="&PARAMETER!$C$8))-SUM(C22:C24)
A27: TOTAL KEWAJIBAN LANCAR | C27: =SUM(C22:C26)
A28: KEWAJIBAN JANGKA PANJANG
A29: Utang Bank Jangka Panjang | B29: 2201 | C29: =-(SUMIFS(JURNAL!$F$6:$F$85,JURNAL!$C$6:$C$85,2201,JURNAL!$A$6:$A$85,"<="&PARAMETER!$C$8)-SUMIFS(JURNAL!$G$6:$G$85,JURNAL!$C$6:$C$85,2201,JURNAL!$A$6:$A$85,"<="&PARAMETER!$C$8))
A30: Kewajiban jangka panjang lainnya | C30: =-(SUMIFS(JURNAL!$F$6:$F$85,JURNAL!$J$6:$J$85,"Kewajiban Jangka Panjang",JURNAL!$A$6:$A$85,"<="&PARAMETER!$C$8)-SUMIFS(JURNAL!$G$6:$G$85,JURNAL!$J$6:$J$85,"Kewajiban Jangka Panjang",JURNAL!$A$6:$A$85,"<="&PARAMETER!$C$8))-C29
A31: TOTAL KEWAJIBAN JANGKA PANJANG | C31: =SUM(C29:C30)
A32: TOTAL KEWAJIBAN | C32: =C27+C31
A34: EKUITAS
A35: Modal Disetor | B35: 3101 | C35: =-(SUMIFS(JURNAL!$F$6:$F$85,JURNAL!$C$6:$C$85,3101,JURNAL!$A$6:$A$85,"<="&PARAMETER!$C$8)-SUMIFS(JURNAL!$G$6:$G$85,JURNAL!$C$6:$C$85,3101,JURNAL!$A$6:$A$85,"<="&PARAMETER!$C$8))
A36: Laba Ditahan | B36: 3201 | C36: =-(SUMIFS(JURNAL!$F$6:$F$85,JURNAL!$C$6:$C$85,3201,JURNAL!$A$6:$A$85,"<="&PARAMETER!$C$8)-SUMIFS(JURNAL!$G$6:$G$85,JURNAL!$C$6:$C$85,3201,JURNAL!$A$6:$A$85,"<="&PARAMETER!$C$8))
A37: Ekuitas lainnya | C37: =-(SUMIFS(JURNAL!$F$6:$F$85,JURNAL!$J$6:$J$85,"Ekuitas",JURNAL!$A$6:$A$85,"<="&PARAMETER!$C$8)-SUMIFS(JURNAL!$G$6:$G$85,JURNAL!$J$6:$J$85,"Ekuitas",JURNAL!$A$6:$A$85,"<="&PARAMETER!$C$8))-C35-C36
A38: Laba berjalan (setelah pajak) | C38: =C43-C44
A39: TOTAL EKUITAS | C39: =SUM(C35:C38)
A40: TOTAL KEWAJIBAN + EKUITAS | C40: =C32+C39
A41: Cek keseimbangan | C41: =IF(ROUND(C19-C40,0)=0,"SEIMBANG","SELISIH "&TEXT(C19-C40,"#,##0"))
A42: PERHITUNGAN BANTU
A43: Laba sebelum pajak (awal tahun buku s.d. akhir periode) | C43: =(SUMIFS(JURNAL!$G$6:$G$85,JURNAL!$I$6:$I$85,"Pendapatan",JURNAL!$A$6:$A$85,">="&PARAMETER!$C$6,JURNAL!$A$6:$A$85,"<="&PARAMETER!$C$8)-SUMIFS(JURNAL!$F$6:$F$85,JURNAL!$I$6:$I$85,"Pendapatan",JURNAL!$A$6:$A$85,">="&PARAMETER!$C$6,JURNAL!$A$6:$A$85,"<="&PARAMETER!$C$8))-(SUMIFS(JURNAL!$F$6:$F$85,JURNAL!$I$6:$I$85,"Beban",JURNAL!$A$6:$A$85,">="&PARAMETER!$C$6,JURNAL!$A$6:$A$85,"<="&PARAMETER!$C$8)-SUMIFS(JURNAL!$G$6:$G$85,JURNAL!$I$6:$I$85,"Beban",JURNAL!$A$6:$A$85,">="&PARAMETER!$C$6,JURNAL!$A$6:$A$85,"<="&PARAMETER!$C$8))
...

Sheet FULL-DASHBOARD
B2: Fitur Versi Lengkap
B3: DASHBOARD
B5: Ringkasan KPI, rasio keuangan, grafik pendapatan vs beban bulanan, dan komposisi beban.
B7: • Sheet ini hanya tersedia di versi lengkap, lengkap dengan rumus dan grafik yang bekerja dari data Anda.
B8: • Kapasitas data versi lengkap jauh lebih besar dibanding demo.
B9: • Pesan versi lengkap lewat WhatsApp 089623291732.
