Workbook

Sheet PETUNJUK
B1: Mantam Product
B2: Aging Piutang & Hutang
B3: Pantau umur piutang dan utang, temukan faktur yang lewat jatuh tempo, dan siapkan pesan penagihan dalam sekali buka.
B5: Lisensi | C5: VERSI DEMO. Kapasitas dan fitur dibatasi. Pesan versi lengkap: WhatsApp 089623291732
B7: Cara memakai
B8: Langkah 1 | C8: Isi tanggal laporan dan batas kelompok umur di PARAMETER.
B9: Langkah 2 | C9: Daftarkan pelanggan (dan pemasok) di MASTER.
B10: Langkah 3 | C10: Catat faktur di PIUTANG: nomor, pihak, tanggal, termin, nilai, dibayar.
B11: Langkah 4 | C11: Baca matriks aging di AGING_PIUTANG.
B13: Isi berkas
B14: PARAMETER | C14: Tanggal laporan dan batas kelompok umur (30/60/90 hari, dapat diubah).
B15: MASTER | C15: Daftar pelanggan yang tampil pada laporan aging.
B16: PIUTANG | C16: Daftar faktur piutang (kapasitas 60). Sisa, hari lewat tempo, dan kelompok umur otomatis.
B17: AGING_PIUTANG | C17: Matriks pelanggan × kelompok umur lengkap dengan total, persentase, dan grafik.
B19: Legenda warna
B20: Teks biru | C20: Sel input: boleh Anda ubah (tidak terkunci).
B21: Sel kuning | C21: Parameter kunci: periksa terlebih dulu.
B22: Teks hitam | C22: Rumus otomatis (terkunci; Review > Unprotect Sheet tanpa kata sandi bila perlu).
B24: Catatan
C25: • Seluruh data adalah simulasi buatan, bukan data perusahaan nyata.
C26: • Hasil perhitungan adalah alat bantu; verifikasi dengan akuntan/konsultan sebelum dipakai untuk keputusan atau pelaporan resmi.
C27: • Nilai dibayar mencakup pembayaran sebagian. Faktur lunas otomatis keluar dari aging.

Sheet PARAMETER
A1: Parameter
A2: Isi sel kuning.
A3: VERSI DEMO: kapasitas & fitur dibatasi, data simulasi. Versi lengkap: WhatsApp 089623291732
B5: Tanggal laporan | C5: 46326 | D5: Umur dihitung terhadap tanggal ini
B6: Batas kelompok 1 (hari) | C6: 30
B7: Batas kelompok 2 (hari) | C7: 60
B8: Batas kelompok 3 (hari) | C8: 90 | D8: Lewat batas ini = kelompok terakhir
B10: Label kelompok umur (otomatis)
B11: Belum jatuh tempo | C11: ="Belum JT"
B12: Kelompok 1 | C12: ="1-"&C6&" hari"
B13: Kelompok 2 | C13: =(C6+1)&"-"&C7&" hari"
B14: Kelompok 3 | C14: =(C7+1)&"-"&C8&" hari"
B15: Kelompok 4 | C15: ="Lewat "&C8&" hari"

Sheet MASTER
A1: Master Pihak
A2: Nama harus sama persis dengan yang dipakai pada daftar faktur
A3: VERSI DEMO: kapasitas & fitur dibatasi, data simulasi. Versi lengkap: WhatsApp 089623291732
A5: Pelanggan
A6: PT Contoh Alfa
A7: CV Contoh Beta
A8: UD Contoh Gamma
A9: PT Contoh Delta
A10: CV Contoh Epsilon
A11: UD Contoh Zeta
A12: PT Contoh Eta
A13: CV Contoh Theta

Sheet PIUTANG
A1: Daftar Faktur Pelanggan
A2: Kapasitas 60 faktur. Isi sel berwarna biru.
A3: VERSI DEMO: kapasitas & fitur dibatasi, data simulasi. Versi lengkap: WhatsApp 089623291732
A5: No. Faktur | B5: Pelanggan | C5: Tgl Faktur | D5: Termin (hari) | E5: Jatuh Tempo | F5: Nilai (Rp) | G5: Dibayar (Rp) | H5: Sisa (Rp) | I5: Hari Lewat Tempo | J5: Kelompok Umur
A6: INV-2026-0013 | B6: UD Contoh Zeta | C6: 46224 | D6: 14 | E6: =IF(A6="","",C6+D6) | F6: 18000000 | G6: 7200000 | H6: =IF(A6="","",F6-G6) | I6: =IF(A6="","",PARAMETER!$C$5-E6) | J6: =IF(A6="","",IF(H6<=0,"Lunas",IF(I6<=0,PARAMETER!$C$11,IF(I6<=PARAMETER!$C$6,PARAMETER!$C$12,IF(I6<=PARAMETER!$C$7,PARAMETER!$C$13,IF(I6<=PARAMETER!$C$8,PARAMETER!$C$14,PARAMETER!$C$15))))))
A7: INV-2026-0016 | B7: PT Contoh Eta | C7: 46225 | D7: 45 | E7: =IF(A7="","",C7+D7) | F7: 95000000 | H7: =IF(A7="","",F7-G7) | I7: =IF(A7="","",PARAMETER!$C$5-E7) | J7: =IF(A7="","",IF(H7<=0,"Lunas",IF(I7<=0,PARAMETER!$C$11,IF(I7<=PARAMETER!$C$6,PARAMETER!$C$12,IF(I7<=PARAMETER!$C$7,PARAMETER!$C$13,IF(I7<=PARAMETER!$C$8,PARAMETER!$C$14,PARAMETER!$C$15))))))
A8: INV-2026-0039 | B8: UD Contoh Gamma | C8: 46227 | D8: 30 | E8: =IF(A8="","",C8+D8) | F8: 70000000 | H8: =IF(A8="","",F8-G8) | I8: =IF(A8="","",PARAMETER!$C$5-E8) | J8: =IF(A8="","",IF(H8<=0,"Lunas",IF(I8<=0,PARAMETER!$C$11,IF(I8<=PARAMETER!$C$6,PARAMETER!$C$12,IF(I8<=PARAMETER!$C$7,PARAMETER!$C$13,IF(I8<=PARAMETER!$C$8,PARAMETER!$C$14,PARAMETER!$C$15))))))
A9: INV-2026-0037 | B9: CV Contoh Beta | C9: 46229 | D9: 45 | E9: =IF(A9="","",C9+D9) | F9: 43000000 | G9: 30100000 | H9: =IF(A9="","",F9-G9) | I9: =IF(A9="","",PARAMETER!$C$5-E9) | J9: =IF(A9="","",IF(H9<=0,"Lunas",IF(I9<=0,PARAMETER!$C$11,IF(I9<=PARAMETER!$C$6,PARAMETER!$C$12,IF(I9<=PARAMETER!$C$7,PARAMETER!$C$13,IF(I9<=PARAMETER!$C$8,PARAMETER!$C$14,PARAMETER!$C$15))))))
A10: INV-2026-0015 | B10: CV Contoh Beta | C10: 46230 | D10: 45 | E10: =IF(A10="","",C10+D10) | F10: 29000000 | G10: 29000000 | H10: =IF(A10="","",F10-G10) | I10: =IF(A10="","",PARAMETER!$C$5-E10) | J10: =IF(A10="","",IF(H10<=0,"Lunas",IF(I10<=0,PARAMETER!$C$11,IF(I10<=PARAMETER!$C$6,PARAMETER!$C$12,IF(I10<=PARAMETER!$C$7,PARAMETER!$C$13,IF(I10<=PARAMETER!$C$8,PARAMETER!$C$14,PARAMETER!$C$15))))))
A11: INV-2026-0007 | B11: CV Contoh Beta | C11: 46233 | D11: 30 | E11: =IF(A11="","",C11+D11) | F11: 148000000 | H11: =IF(A11="","",F11-G11) | I11: =IF(A11="","",PARAMETER!$C$5-E11) | J11: =IF(A11="","",IF(H11<=0,"Lunas",IF(I11<=0,PARAMETER!$C$11,IF(I11<=PARAMETER!$C$6,PARAMETER!$C$12,IF(I11<=PARAMETER!$C$7,PARAMETER!$C$13,IF(I11<=PARAMETER!$C$8,PARAMETER!$C$14,PARAMETER!$C$15))))))
A12: INV-2026-0032 | B12: UD Contoh Zeta | C12: 46233 | D12: 30 | E12: =IF(A12="","",C12+D12) | F12: 31000000 | G12: 31000000 | H12: =IF(A12="","",F12-G12) | I12: =IF(A12="","",PARAMETER!$C$5-E12) | J12: =IF(A12="","",IF(H12<=0,"Lunas",IF(I12<=0,PARAMETER!$C$11,IF(I12<=PARAMETER!$C$6,PARAMETER!$C$12,IF(I12<=PARAMETER!$C$7,PARAMETER!$C$13,IF(I12<=PARAMETER!$C$8,PARAMETER!$C$14,PARAMETER!$C$15))))))
A13: INV-2026-0036 | B13: PT Contoh Alfa | C13: 46234 | D13: 30 | E13: =IF(A13="","",C13+D13) | F13: 25000000 | G13: 25000000 | H13: =IF(A13="","",F13-G13) | I13: =IF(A13="","",PARAMETER!$C$5-E13) | J13: =IF(A13="","",IF(H13<=0,"Lunas",IF(I13<=0,PARAMETER!$C$11,IF(I13<=PARAMETER!$C$6,PARAMETER!$C$12,IF(I13<=PARAMETER!$C$7,PARAMETER!$C$13,IF(I13<=PARAMETER!$C$8,PARAMETER!$C$14,PARAMETER!$C$15))))))
A14: INV-2026-0008 | B14: CV Contoh Beta | C14: 46235 | D14: 30 | E14: =IF(A14="","",C14+D14) | F14: 89000000 | H14: =IF(A14="","",F14-G14) | I14: =IF(A14="","",PARAMETER!$C$5-E14) | J14: =IF(A14="","",IF(H14<=0,"Lunas",IF(I14<=0,PARAMETER!$C$11,IF(I14<=PARAMETER!$C$6,PARAMETER!$C$12,IF(I14<=PARAMETER!$C$7,PARAMETER!$C$13,IF(I14<=PARAMETER!$C$8,PARAMETER!$C$14,PARAMETER!$C$15))))))
A15: INV-2026-0027 | B15: PT Contoh Eta | C15: 46236 | D15: 45 | E15: =IF(A15="","",C15+D15) | F15: 77000000 | G15: 38500000 | H15: =IF(A15="","",F15-G15) | I15: =IF(A15="","",PARAMETER!$C$5-E15) | J15: =IF(A15="","",IF(H15<=0,"Lunas",IF(I15<=0,PARAMETER!$C$11,IF(I15<=PARAMETER!$C$6,PARAMETER!$C$12,IF(I15<=PARAMETER!$C$7,PARAMETER!$C$13,IF(I15<=PARAMETER!$C$8,PARAMETER!$C$14,PARAMETER!$C$15))))))
A16: INV-2026-0019 | B16: UD Contoh Gamma | C16: 46237 | D16: 45 | E16: =IF(A16="","",C16+D16) | F16: 126000000 | G16: 126000000 | H16: =IF(A16="","",F16-G16) | I16: =IF(A16="","",PARAMETER!$C$5-E16) | J16: =IF(A16="","",IF(H16<=0,"Lunas",IF(I16<=0,PARAMETER!$C$11,IF(I16<=PARAMETER!$C$6,PARAMETER!$C$12,IF(I16<=PARAMETER!$C$7,PARAMETER!$C$13,IF(I16<=PARAMETER!$C$8,PARAMETER!$C$14,PARAMETER!$C$15))))))
A17: INV-2026-0003 | B17: CV Contoh Theta | C17: 46241 | D17: 14 | E17: =IF(A17="","",C17+D17) | F17: 76000000 | G17: 76000000 | H17: =IF(A17="","",F17-G17) | I17: =IF(A17="","",PARAMETER!$C$5-E17) | J17: =IF(A17="","",IF(H17<=0,"Lunas",IF(I17<=0,PARAMETER!$C$11,IF(I17<=PARAMETER!$C$6,PARAMETER!$C$12,IF(I17<=PARAMETER!$C$7,PARAMETER!$C$13,IF(I17<=PARAMETER!$C$8,PARAMETER!$C$14,PARAMETER!$C$15))))))
A18: INV-2026-0021 | B18: PT Contoh Delta | C18: 46243 | D18: 30 | E18: =IF(A18="","",C18+D18) | F18: 43000000 | G18: 43000000 | H18: =IF(A18="","",F18-G18) | I18: =IF(A18="","",PARAMETER!$C$5-E18) | J18: =IF(A18="","",IF(H18<=0,"Lunas",IF(I18<=0,PARAMETER!$C$11,IF(I18<=PARAMETER!$C$6,PARAMETER!$C$12,IF(I18<=PARAMETER!$C$7,PARAMETER!$C$13,IF(I18<=PARAMETER!$C$8,PARAMETER!$C$14,PARAMETER!$C$15))))))
A19: INV-2026-0004 | B19: PT Contoh Eta | C19: 46245 | D19: 30 | E19: =IF(A19="","",C19+D19) | F19: 134000000 | H19: =IF(A19="","",F19-G19) | I19: =IF(A19="","",PARAMETER!$C$5-E19) | J19: =IF(A19="","",IF(H19<=0,"Lunas",IF(I19<=0,PARAMETER!$C$11,IF(I19<=PARAMETER!$C$6,PARAMETER!$C$12,IF(I19<=PARAMETER!$C$7,PARAMETER!$C$13,IF(I19<=PARAMETER!$C$8,PARAMETER!$C$14,PARAMETER!$C$15))))))
A20: INV-2026-0005 | B20: CV Contoh Epsilon | C20: 46246 | D20: 30 | E20: =IF(A20="","",C20+D20) | F20: 87000000 | G20: 87000000 | H20: =IF(A20="","",F20-G20) | I20: =IF(A20="","",PARAMETER!$C$5-E20) | J20: =IF(A20="","",IF(H20<=0,"Lunas",IF(I20<=0,PARAMETER!$C$11,IF(I20<=PARAMETER!$C$6,PARAMETER!$C$12,IF(I20<=PARAMETER!$C$7,PARAMETER!$C$13,IF(I20<=PARAMETER!$C$8,PARAMETER!$C$14,PARAMETER!$C$15))))))
A21: INV-2026-0024 | B21: PT Contoh Alfa | C21: 46247 | D21: 14 | E21: =IF(A21="","",C21+D21) | F21: 129000000 | G21: 129000000 | H21: =IF(A21="","",F21-G21) | I21: =IF(A21="","",PARAMETER!$C$5-E21) | J21: =IF(A21="","",IF(H21<=0,"Lunas",IF(I21<=0,PARAMETER!$C$11,IF(I21<=PARAMETER!$C$6,PARAMETER!$C$12,IF(I21<=PARAMETER!$C$7,PARAMETER!$C$13,IF(I21<=PARAMETER!$C$8,PARAMETER!$C$14,PARAMETER!$C$15))))))
A22: INV-2026-0028 | B22: CV Contoh Beta | C22: 46247 | D22: 45 | E22: =IF(A22="","",C22+D22) | F22: 69000000 | G22: 69000000 | H22: =IF(A22="","",F22-G22) | I22: =IF(A22="","",PARAMETER!$C$5-E22) | J22: =IF(A22="","",IF(H22<=0,"Lunas",IF(I22<=0,PARAMETER!$C$11,IF(I22<=PARAMETER!$C$6,PARAMETER!$C$12,IF(I22<=PARAMETER!$C$7,PARAMETER!$C$13,IF(I22<=PARAMETER!$C$8,PARAMETER!$C$14,PARAMETER!$C$15))))))
A23: INV-2026-0012 | B23: PT Contoh Eta | C23: 46251 | D23: 45 | E23: =IF(A23="","",C23+D23) | F23: 108000000 | H23: =IF(A23="","",F23-G23) | I23: =IF(A23="","",PARAMETER!$C$5-E23) | J23: =IF(A23="","",IF(H23<=0,"Lunas",IF(I23<=0,PARAMETER!$C$11,IF(I23<=PARAMETER!$C$6,PARAMETER!$C$12,IF(I23<=PARAMETER!$C$7,PARAMETER!$C$13,IF(I23<=PARAMETER!$C$8,PARAMETER!$C$14,PARAMETER!$C$15))))))
A24: INV-2026-0020 | B24: CV Contoh Beta | C24: 46253 | D24: 30 | E24: =IF(A24="","",C24+D24) | F24: 58000000 | H24: =IF(A24="","",F24-G24) | I24: =IF(A24="","",PARAMETER!$C$5-E24) | J24: =IF(A24="","",IF(H24<=0,"Lunas",IF(I24<=0,PARAMETER!$C$11,IF(I24<=PARAMETER!$C$6,PARAMETER!$C$12,IF(I24<=PARAMETER!$C$7,PARAMETER!$C$13,IF(I24<=PARAMETER!$C$8,PARAMETER!$C$14,PARAMETER!$C$15))))))
A25: INV-2026-0001 | B25: CV Contoh Beta | C25: 46255 | D25: 30 | E25: =IF(A25="","",C25+D25) | F25: 55000000 | G25: 55000000 | H25: =IF(A25="","",F25-G25) | I25: =IF(A25="","",PARAMETER!$C$5-E25) | J25: =IF(A25="","",IF(H25<=0,"Lunas",IF(I25<=0,PARAMETER!$C$11,IF(I25<=PARAMETER!$C$6,PARAMETER!$C$12,IF(I25<=PARAMETER!$C$7,PARAMETER!$C$13,IF(I25<=PARAMETER!$C$8,PARAMETER!$C$14,PARAMETER!$C$15))))))
A26: INV-2026-0031 | B26: CV Contoh Epsilon | C26: 46255 | D26: 45 | E26: =IF(A26="","",C26+D26) | F26: 148000000 | H26: =IF(A26="","",F26-G26) | I26: =IF(A26="","",PARAMETER!$C$5-E26) | J26: =IF(A26="","",IF(H26<=0,"Lunas",IF(I26<=0,PARAMETER!$C$11,IF(I26<=PARAMETER!$C$6,PARAMETER!$C$12,IF(I26<=PARAMETER!$C$7,PARAMETER!$C$13,IF(I26<=PARAMETER!$C$8,PARAMETER!$C$14,PARAMETER!$C$15))))))
A27: INV-2026-0010 | B27: UD Contoh Zeta | C27: 46257 | D27: 45 | E27: =IF(A27="","",C27+D27) | F27: 146000000 | H27: =IF(A27="","",F27-G27) | I27: =IF(A27="","",PARAMETER!$C$5-E27) | J27: =IF(A27="","",IF(H27<=0,"Lunas",IF(I27<=0,PARAMETER!$C$11,IF(I27<=PARAMETER!$C$6,PARAMETER!$C$12,IF(I27<=PARAMETER!$C$7,PARAMETER!$C$13,IF(I27<=PARAMETER!$C$8,PARAMETER!$C$14,PARAMETER!$C$15))))))
A28: INV-2026-0035 | B28: PT Contoh Eta | C28: 46257 | D28: 30 | E28: =IF(A28="","",C28+D28) | F28: 92000000 | G28: 92000000 | H28: =IF(A28="","",F28-G28) | I28: =IF(A28="","",PARAMETER!$C$5-E28) | J28: =IF(A28="","",IF(H28<=0,"Lunas",IF(I28<=0,PARAMETER!$C$11,IF(I28<=PARAMETER!$C$6,PARAMETER!$C$12,IF(I28<=PARAMETER!$C$7,PARAMETER!$C$13,IF(I28<=PARAMETER!$C$8,PARAMETER!$C$14,PARAMETER!$C$15))))))
A29: INV-2026-0002 | B29: PT Contoh Delta | C29: 46260 | D29: 45 | E29: =IF(A29="","",C29+D29) | F29: 147000000 | H29: =IF(A29="","",F29-G29) | I29: =IF(A29="","",PARAMETER!$C$5-E29) | J29: =IF(A29="","",IF(H29<=0,"Lunas",IF(I29<=0,PARAMETER!$C$11,IF(I29<=PARAMETER!$C$6,PARAMETER!$C$12,IF(I29<=PARAMETER!$C$7,PARAMETER!$C$13,IF(I29<=PARAMETER!$C$8,PARAMETER!$C$14,PARAMETER!$C$15))))))
A30: INV-2026-0030 | B30: PT Contoh Eta | C30: 46270 | D30: 45 | E30: =IF(A30="","",C30+D30) | F30: 139000000 | G30: 139000000 | H30: =IF(A30="","",F30-G30) | I30: =IF(A30="","",PARAMETER!$C$5-E30) | J30: =IF(A30="","",IF(H30<=0,"Lunas",IF(I30<=0,PARAMETER!$C$11,IF(I30<=PARAMETER!$C$6,PARAMETER!$C$12,IF(I30<=PARAMETER!$C$7,PARAMETER!$C$13,IF(I30<=PARAMETER!$C$8,PARAMETER!$C$14,PARAMETER!$C$15))))))
A31: INV-2026-0038 | B31: UD Contoh Gamma | C31: 46278 | D31: 14 | E31: =IF(A31="","",C31+D31) | F31: 33000000 | G31: 33000000 | H31: =IF(A31="","",F31-G31) | I31: =IF(A31="","",PARAMETER!$C$5-E31) | J31: =IF(A31="","",IF(H31<=0,"Lunas",IF(I31<=0,PARAMETER!$C$11,IF(I31<=PARAMETER!$C$6,PARAMETER!$C$12,IF(I31<=PARAMETER!$C$7,PARAMETER!$C$13,IF(I31<=PARAMETER!$C$8,PARAMETER!$C$14,PARAMETER!$C$15))))))
A32: INV-2026-0023 | B32: CV Contoh Theta | C32: 46283 | D32: 45 | E32: =IF(A32="","",C32+D32) | F32: 80000000 | G32: 40000000 | H32: =IF(A32="","",F32-G32) | I32: =IF(A32="","",PARAMETER!$C$5-E32) | J32: =IF(A32="","",IF(H32<=0,"Lunas",IF(I32<=0,PARAMETER!$C$11,IF(I32<=PARAMETER!$C$6,PARAMETER!$C$12,IF(I32<=PARAMETER!$C$7,PARAMETER!$C$13,IF(I32<=PARAMETER!$C$8,PARAMETER!$C$14,PARAMETER!$C$15))))))
A33: INV-2026-0026 | B33: UD Contoh Gamma | C33: 46288 | D33: 30 | E33: =IF(A33="","",C33+D33) | F33: 26000000 | H33: =IF(A33="","",F33-G33) | I33: =IF(A33="","",PARAMETER!$C$5-E33) | J33: =IF(A33="","",IF(H33<=0,"Lunas",IF(I33<=0,PARAMETER!$C$11,IF(I33<=PARAMETER!$C$6,PARAMETER!$C$12,IF(I33<=PARAMETER!$C$7,PARAMETER!$C$13,IF(I33<=PARAMETER!$C$8,PARAMETER!$C$14,PARAMETER!$C$15))))))
A34: INV-2026-0011 | B34: PT Contoh Delta | C34: 46290 | D34: 14 | E34: =IF(A34="","",C34+D34) | F34: 108000000 | H34: =IF(A34="","",F34-G34) | I34: =IF(A34="","",PARAMETER!$C$5-E34) | J34: =IF(A34="","",IF(H34<=0,"Lunas",IF(I34<=0,PARAMETER!$C$11,IF(I34<=PARAMETER!$C$6,PARAMETER!$C$12,IF(I34<=PARAMETER!$C$7,PARAMETER!$C$13,IF(I34<=PARAMETER!$C$8,PARAMETER!$C$14,PARAMETER!$C$15))))))
A35: INV-2026-0029 | B35: CV Contoh Epsilon | C35: 46290 | D35: 30 | E35: =IF(A35="","",C35+D35) | F35: 85000000 | H35: =IF(A35="","",F35-G35) | I35: =IF(A35="","",PARAMETER!$C$5-E35) | J35: =IF(A35="","",IF(H35<=0,"Lunas",IF(I35<=0,PARAMETER!$C$11,IF(I35<=PARAMETER!$C$6,PARAMETER!$C$12,IF(I35<=PARAMETER!$C$7,PARAMETER!$C$13,IF(I35<=PARAMETER!$C$8,PARAMETER!$C$14,PARAMETER!$C$15))))))
A36: INV-2026-0034 | B36: UD Contoh Gamma | C36: 46290 | D36: 14 | E36: =IF(A36="","",C36+D36) | F36: 35000000 | H36: =IF(A36="","",F36-G36) | I36: =IF(A36="","",PARAMETER!$C$5-E36) | J36: =IF(A36="","",IF(H36<=0,"Lunas",IF(I36<=0,PARAMETER!$C$11,IF(I36<=PARAMETER!$C$6,PARAMETER!$C$12,IF(I36<=PARAMETER!$C$7,PARAMETER!$C$13,IF(I36<=PARAMETER!$C$8,PARAMETER!$C$14,PARAMETER!$C$15))))))
A37: INV-2026-0006 | B37: CV Contoh Beta | C37: 46291 | D37: 45 | E37: =IF(A37="","",C37+D37) | F37: 57000000 | G37: 57000000 | H37: =IF(A37="","",F37-G37) | I37: =IF(A37="","",PARAMETER!$C$5-E37) | J37: =IF(A37="","",IF(H37<=0,"Lunas",IF(I37<=0,PARAMETER!$C$11,IF(I37<=PARAMETER!$C$6,PARAMETER!$C$12,IF(I37<=PARAMETER!$C$7,PARAMETER!$C$13,IF(I37<=PARAMETER!$C$8,PARAMETER!$C$14,PARAMETER!$C$15))))))
A38: INV-2026-0040 | B38: PT Contoh Eta | C38: 46292 | D38: 14 | E38: =IF(A38="","",C38+D38) | F38: 22000000 | G38: 22000000 | H38: =IF(A38="","",F38-G38) | I38: =IF(A38="","",PARAMETER!$C$5-E38) | J38: =IF(A38="","",IF(H38<=0,"Lunas",IF(I38<=0,PARAMETER!$C$11,IF(I38<=PARAMETER!$C$6,PARAMETER!$C$12,IF(I38<=PARAMETER!$C$7,PARAMETER!$C$13,IF(I38<=PARAMETER!$C$8,PARAMETER!$C$14,PARAMETER!$C$15))))))
A39: INV-2026-0009 | B39: CV Contoh Beta | C39: 46296 | D39: 45 | E39: =IF(A39="","",C39+D39) | F39: 25000000 | H39: =IF(A39="","",F39-G39) | I39: =IF(A39="","",PARAMETER!$C$5-E39) | J39: =IF(A39="","",IF(H39<=0,"Lunas",IF(I39<=0,PARAMETER!$C$11,IF(I39<=PARAMETER!$C$6,PARAMETER!$C$12,IF(I39<=PARAMETER!$C$7,PARAMETER!$C$13,IF(I39<=PARAMETER!$C$8,PARAMETER!$C$14,PARAMETER!$C$15))))))
A40: INV-2026-0017 | B40: UD Contoh Gamma | C40: 46296 | D40: 14 | E40: =IF(A40="","",C40+D40) | F40: 20000000 | H40: =IF(A40="","",F40-G40) | I40: =IF(A40="","",PARAMETER!$C$5-E40) | J40: =IF(A40="","",IF(H40<=0,"Lunas",IF(I40<=0,PARAMETER!$C$11,IF(I40<=PARAMETER!$C$6,PARAMETER!$C$12,IF(I40<=PARAMETER!$C$7,PARAMETER!$C$13,IF(I40<=PARAMETER!$C$8,PARAMETER!$C$14,PARAMETER!$C$15))))))
A41: INV-2026-0022 | B41: CV Contoh Beta | C41: 46308 | D41: 45 | E41: =IF(A41="","",C41+D41) | F41: 111000000 | G41: 55500000 | H41: =IF(A41="","",F41-G41) | I41: =IF(A41="","",PARAMETER!$C$5-E41) | J41: =IF(A41="","",IF(H41<=0,"Lunas",IF(I41<=0,PARAMETER!$C$11,IF(I41<=PARAMETER!$C$6,PARAMETER!$C$12,IF(I41<=PARAMETER!$C$7,PARAMETER!$C$13,IF(I41<=PARAMETER!$C$8,PARAMETER!$C$14,PARAMETER!$C$15))))))
...

Sheet AGING_PIUTANG
A1: Aging Pelanggan
A2: Saldo per kelompok umur (hari lewat jatuh tempo)
A3: VERSI DEMO: kapasitas & fitur dibatasi, data simulasi. Versi lengkap: WhatsApp 089623291732
A5: Pelanggan | B5: =PARAMETER!C11 | C5: =PARAMETER!C12 | D5: =PARAMETER!C13 | E5: =PARAMETER!C14 | F5: =PARAMETER!C15 | G5: Total (Rp) | H5: % Lewat Tempo | I5: Kunci Peringkat
A6: =IF(MASTER!A6="","",MASTER!A6) | B6: =IF($A6="","",SUMIFS(PIUTANG!$H$6:$H$65,PIUTANG!$B$6:$B$65,$A6,PIUTANG!$J$6:$J$65,B$5)) | C6: =IF($A6="","",SUMIFS(PIUTANG!$H$6:$H$65,PIUTANG!$B$6:$B$65,$A6,PIUTANG!$J$6:$J$65,C$5)) | D6: =IF($A6="","",SUMIFS(PIUTANG!$H$6:$H$65,PIUTANG!$B$6:$B$65,$A6,PIUTANG!$J$6:$J$65,D$5)) | E6: =IF($A6="","",SUMIFS(PIUTANG!$H$6:$H$65,PIUTANG!$B$6:$B$65,$A6,PIUTANG!$J$6:$J$65,E$5)) | F6: =IF($A6="","",SUMIFS(PIUTANG!$H$6:$H$65,PIUTANG!$B$6:$B$65,$A6,PIUTANG!$J$6:$J$65,F$5)) | G6: =IF(A6="","",SUM(B6:F6)) | H6: =IF(A6="","",IF(G6=0,0,SUM(C6:F6)/G6)) | I6: =IF(A6="",-1,G6+ROW()/1000000000)
A7: =IF(MASTER!A7="","",MASTER!A7) | B7: =IF($A7="","",SUMIFS(PIUTANG!$H$6:$H$65,PIUTANG!$B$6:$B$65,$A7,PIUTANG!$J$6:$J$65,B$5)) | C7: =IF($A7="","",SUMIFS(PIUTANG!$H$6:$H$65,PIUTANG!$B$6:$B$65,$A7,PIUTANG!$J$6:$J$65,C$5)) | D7: =IF($A7="","",SUMIFS(PIUTANG!$H$6:$H$65,PIUTANG!$B$6:$B$65,$A7,PIUTANG!$J$6:$J$65,D$5)) | E7: =IF($A7="","",SUMIFS(PIUTANG!$H$6:$H$65,PIUTANG!$B$6:$B$65,$A7,PIUTANG!$J$6:$J$65,E$5)) | F7: =IF($A7="","",SUMIFS(PIUTANG!$H$6:$H$65,PIUTANG!$B$6:$B$65,$A7,PIUTANG!$J$6:$J$65,F$5)) | G7: =IF(A7="","",SUM(B7:F7)) | H7: =IF(A7="","",IF(G7=0,0,SUM(C7:F7)/G7)) | I7: =IF(A7="",-1,G7+ROW()/1000000000)
A8: =IF(MASTER!A8="","",MASTER!A8) | B8: =IF($A8="","",SUMIFS(PIUTANG!$H$6:$H$65,PIUTANG!$B$6:$B$65,$A8,PIUTANG!$J$6:$J$65,B$5)) | C8: =IF($A8="","",SUMIFS(PIUTANG!$H$6:$H$65,PIUTANG!$B$6:$B$65,$A8,PIUTANG!$J$6:$J$65,C$5)) | D8: =IF($A8="","",SUMIFS(PIUTANG!$H$6:$H$65,PIUTANG!$B$6:$B$65,$A8,PIUTANG!$J$6:$J$65,D$5)) | E8: =IF($A8="","",SUMIFS(PIUTANG!$H$6:$H$65,PIUTANG!$B$6:$B$65,$A8,PIUTANG!$J$6:$J$65,E$5)) | F8: =IF($A8="","",SUMIFS(PIUTANG!$H$6:$H$65,PIUTANG!$B$6:$B$65,$A8,PIUTANG!$J$6:$J$65,F$5)) | G8: =IF(A8="","",SUM(B8:F8)) | H8: =IF(A8="","",IF(G8=0,0,SUM(C8:F8)/G8)) | I8: =IF(A8="",-1,G8+ROW()/1000000000)
A9: =IF(MASTER!A9="","",MASTER!A9) | B9: =IF($A9="","",SUMIFS(PIUTANG!$H$6:$H$65,PIUTANG!$B$6:$B$65,$A9,PIUTANG!$J$6:$J$65,B$5)) | C9: =IF($A9="","",SUMIFS(PIUTANG!$H$6:$H$65,PIUTANG!$B$6:$B$65,$A9,PIUTANG!$J$6:$J$65,C$5)) | D9: =IF($A9="","",SUMIFS(PIUTANG!$H$6:$H$65,PIUTANG!$B$6:$B$65,$A9,PIUTANG!$J$6:$J$65,D$5)) | E9: =IF($A9="","",SUMIFS(PIUTANG!$H$6:$H$65,PIUTANG!$B$6:$B$65,$A9,PIUTANG!$J$6:$J$65,E$5)) | F9: =IF($A9="","",SUMIFS(PIUTANG!$H$6:$H$65,PIUTANG!$B$6:$B$65,$A9,PIUTANG!$J$6:$J$65,F$5)) | G9: =IF(A9="","",SUM(B9:F9)) | H9: =IF(A9="","",IF(G9=0,0,SUM(C9:F9)/G9)) | I9: =IF(A9="",-1,G9+ROW()/1000000000)
A10: =IF(MASTER!A10="","",MASTER!A10) | B10: =IF($A10="","",SUMIFS(PIUTANG!$H$6:$H$65,PIUTANG!$B$6:$B$65,$A10,PIUTANG!$J$6:$J$65,B$5)) | C10: =IF($A10="","",SUMIFS(PIUTANG!$H$6:$H$65,PIUTANG!$B$6:$B$65,$A10,PIUTANG!$J$6:$J$65,C$5)) | D10: =IF($A10="","",SUMIFS(PIUTANG!$H$6:$H$65,PIUTANG!$B$6:$B$65,$A10,PIUTANG!$J$6:$J$65,D$5)) | E10: =IF($A10="","",SUMIFS(PIUTANG!$H$6:$H$65,PIUTANG!$B$6:$B$65,$A10,PIUTANG!$J$6:$J$65,E$5)) | F10: =IF($A10="","",SUMIFS(PIUTANG!$H$6:$H$65,PIUTANG!$B$6:$B$65,$A10,PIUTANG!$J$6:$J$65,F$5)) | G10: =IF(A10="","",SUM(B10:F10)) | H10: =IF(A10="","",IF(G10=0,0,SUM(C10:F10)/G10)) | I10: =IF(A10="",-1,G10+ROW()/1000000000)
A11: =IF(MASTER!A11="","",MASTER!A11) | B11: =IF($A11="","",SUMIFS(PIUTANG!$H$6:$H$65,PIUTANG!$B$6:$B$65,$A11,PIUTANG!$J$6:$J$65,B$5)) | C11: =IF($A11="","",SUMIFS(PIUTANG!$H$6:$H$65,PIUTANG!$B$6:$B$65,$A11,PIUTANG!$J$6:$J$65,C$5)) | D11: =IF($A11="","",SUMIFS(PIUTANG!$H$6:$H$65,PIUTANG!$B$6:$B$65,$A11,PIUTANG!$J$6:$J$65,D$5)) | E11: =IF($A11="","",SUMIFS(PIUTANG!$H$6:$H$65,PIUTANG!$B$6:$B$65,$A11,PIUTANG!$J$6:$J$65,E$5)) | F11: =IF($A11="","",SUMIFS(PIUTANG!$H$6:$H$65,PIUTANG!$B$6:$B$65,$A11,PIUTANG!$J$6:$J$65,F$5)) | G11: =IF(A11="","",SUM(B11:F11)) | H11: =IF(A11="","",IF(G11=0,0,SUM(C11:F11)/G11)) | I11: =IF(A11="",-1,G11+ROW()/1000000000)
A12: =IF(MASTER!A12="","",MASTER!A12) | B12: =IF($A12="","",SUMIFS(PIUTANG!$H$6:$H$65,PIUTANG!$B$6:$B$65,$A12,PIUTANG!$J$6:$J$65,B$5)) | C12: =IF($A12="","",SUMIFS(PIUTANG!$H$6:$H$65,PIUTANG!$B$6:$B$65,$A12,PIUTANG!$J$6:$J$65,C$5)) | D12: =IF($A12="","",SUMIFS(PIUTANG!$H$6:$H$65,PIUTANG!$B$6:$B$65,$A12,PIUTANG!$J$6:$J$65,D$5)) | E12: =IF($A12="","",SUMIFS(PIUTANG!$H$6:$H$65,PIUTANG!$B$6:$B$65,$A12,PIUTANG!$J$6:$J$65,E$5)) | F12: =IF($A12="","",SUMIFS(PIUTANG!$H$6:$H$65,PIUTANG!$B$6:$B$65,$A12,PIUTANG!$J$6:$J$65,F$5)) | G12: =IF(A12="","",SUM(B12:F12)) | H12: =IF(A12="","",IF(G12=0,0,SUM(C12:F12)/G12)) | I12: =IF(A12="",-1,G12+ROW()/1000000000)
A13: =IF(MASTER!A13="","",MASTER!A13) | B13: =IF($A13="","",SUMIFS(PIUTANG!$H$6:$H$65,PIUTANG!$B$6:$B$65,$A13,PIUTANG!$J$6:$J$65,B$5)) | C13: =IF($A13="","",SUMIFS(PIUTANG!$H$6:$H$65,PIUTANG!$B$6:$B$65,$A13,PIUTANG!$J$6:$J$65,C$5)) | D13: =IF($A13="","",SUMIFS(PIUTANG!$H$6:$H$65,PIUTANG!$B$6:$B$65,$A13,PIUTANG!$J$6:$J$65,D$5)) | E13: =IF($A13="","",SUMIFS(PIUTANG!$H$6:$H$65,PIUTANG!$B$6:$B$65,$A13,PIUTANG!$J$6:$J$65,E$5)) | F13: =IF($A13="","",SUMIFS(PIUTANG!$H$6:$H$65,PIUTANG!$B$6:$B$65,$A13,PIUTANG!$J$6:$J$65,F$5)) | G13: =IF(A13="","",SUM(B13:F13)) | H13: =IF(A13="","",IF(G13=0,0,SUM(C13:F13)/G13)) | I13: =IF(A13="",-1,G13+ROW()/1000000000)
A14: TOTAL | B14: =SUM(B6:B13) | C14: =SUM(C6:C13) | D14: =SUM(D6:D13) | E14: =SUM(E6:E13) | F14: =SUM(F6:F13) | G14: =SUM(G6:G13) | H14: =IF(G14=0,0,SUM(C14:F14)/G14)
A15: % dari total | B15: =IF($G$14=0,0,B14/$G$14) | C15: =IF($G$14=0,0,C14/$G$14) | D15: =IF($G$14=0,0,D14/$G$14) | E15: =IF($G$14=0,0,E14/$G$14) | F15: =IF($G$14=0,0,F14/$G$14)

Sheet FULL-HUTANG
B2: Fitur Versi Lengkap
B3: HUTANG
B5: Daftar tagihan pemasok (utang usaha).
B7: • Sheet ini hanya tersedia di versi lengkap, lengkap dengan rumus dan grafik yang bekerja dari data Anda.
B8: • Kapasitas data versi lengkap jauh lebih besar dibanding demo.
B9: • Pesan versi lengkap lewat WhatsApp 089623291732.

Sheet FULL-AGING_HUTANG
B2: Fitur Versi Lengkap
B3: AGING HUTANG
B5: Aging utang usaha per pemasok.
B7: • Sheet ini hanya tersedia di versi lengkap, lengkap dengan rumus dan grafik yang bekerja dari data Anda.
B8: • Kapasitas data versi lengkap jauh lebih besar dibanding demo.
B9: • Pesan versi lengkap lewat WhatsApp 089623291732.

Sheet FULL-DASHBOARD
B2: Fitur Versi Lengkap
B3: DASHBOARD
B5: Ringkasan piutang vs utang, persentase lewat tempo, dan 5 debitur terbesar.
B7: • Sheet ini hanya tersedia di versi lengkap, lengkap dengan rumus dan grafik yang bekerja dari data Anda.
B8: • Kapasitas data versi lengkap jauh lebih besar dibanding demo.
B9: • Pesan versi lengkap lewat WhatsApp 089623291732.
