Workbook

Sheet PETUNJUK
B1: Mantam Product
B2: Budget vs Aktual
B3: Bandingkan anggaran dengan realisasi per departemen dan akun, lengkap dengan status otomatis dan proyeksi setahun.
B5: Lisensi | C5: VERSI DEMO. Kapasitas dan fitur dibatasi. Pesan versi lengkap: WhatsApp 089623291732
B7: Cara memakai
B8: Langkah 1 | C8: Isi daftar departemen dan akun di MASTER.
B9: Langkah 2 | C9: Masukkan anggaran dan realisasi per bulan di DATA (satu baris = departemen × akun × bulan). Realisasi bulan yang belum berjalan dikosongkan.
B10: Langkah 3 | C10: Pilih departemen, bulan s/d, dan toleransi di PARAMETER.
B11: Langkah 4 | C11: Baca VARIANS: selisih positif berarti hemat, negatif berarti melebihi anggaran.
B13: Isi berkas
B14: PARAMETER | C14: Pilih departemen (atau Semua), bulan s/d, dan toleransi varians.
B15: MASTER | C15: Daftar departemen dan akun beban.
B16: DATA | C16: Tabel anggaran dan realisasi per departemen × akun × bulan (kapasitas 150 baris).
B17: VARIANS | C17: Budget vs aktual YTD per akun, selisih, persentase, status (Over Budget / On Track / Hemat), dan grafik.
B19: Legenda warna
B20: Teks biru | C20: Sel input: boleh Anda ubah (tidak terkunci).
B21: Sel kuning | C21: Parameter kunci: periksa terlebih dulu.
B22: Teks hitam | C22: Rumus otomatis (terkunci; Review > Unprotect Sheet tanpa kata sandi bila perlu).
B24: Catatan
C25: • Seluruh data adalah simulasi buatan, bukan data perusahaan nyata.
C26: • Hasil perhitungan adalah alat bantu; verifikasi dengan akuntan/konsultan sebelum dipakai untuk keputusan atau pelaporan resmi.
C27: • Proyeksi setahun = realisasi YTD + anggaran sisa bulan (metode sederhana).

Sheet PARAMETER
A1: Parameter
A2: Isi sel kuning.
A3: VERSI DEMO: kapasitas & fitur dibatasi, data simulasi. Versi lengkap: WhatsApp 089623291732
B5: Departemen | C5: Semua | D5: Pilih 'Semua' untuk seluruh departemen
B6: Bulan s/d (1-12) | C6: 4 | D6: Hanya sampai bulan yang sudah ada realisasinya
B7: Toleransi varians | C7: 0.05 | D7: Di atas batas ini dianggap Over Budget / Hemat

Sheet MASTER
A1: Master
A2: Nama harus sama persis dengan yang dipakai di DATA
A3: VERSI DEMO: kapasitas & fitur dibatasi, data simulasi. Versi lengkap: WhatsApp 089623291732
A5: Departemen | C5: Akun beban | J5: Semua
A6: Operasional | C6: Gaji & Tunjangan | J6: =IF(A6="","",A6)
A7: Pemasaran | C7: Perjalanan Dinas | J7: =IF(A7="","",A7)
A8: Keuangan | C8: Pemasaran & Iklan | J8: =IF(A8="","",A8)
C9: Utilitas | J9: =IF(A9="","",A9)
C10: Perlengkapan | J10: =IF(A10="","",A10)
C11: Pelatihan | J11: =IF(A11="","",A11)
J12: =IF(A12="","",A12)
J13: =IF(A13="","",A13)

Sheet DATA
A1: Data Anggaran & Realisasi
A2: Kapasitas 150 baris
A3: VERSI DEMO: kapasitas & fitur dibatasi, data simulasi. Versi lengkap: WhatsApp 089623291732
A5: Departemen | B5: Akun | C5: Bulan (1-12) | D5: Anggaran (Rp) | E5: Realisasi (Rp)
A6: Operasional | B6: Gaji & Tunjangan | C6: 1 | D6: 16660000 | E6: 15960000
A7: Operasional | B7: Gaji & Tunjangan | C7: 2 | D7: 17340000 | E7: 18210000
A8: Operasional | B8: Gaji & Tunjangan | C8: 3 | D8: 18020000 | E8: 17330000
A9: Operasional | B9: Gaji & Tunjangan | C9: 4 | D9: 15980000 | E9: 15290000
A10: Operasional | B10: Gaji & Tunjangan | C10: 5 | D10: 16660000
A11: Operasional | B11: Gaji & Tunjangan | C11: 6 | D11: 17340000
A12: Operasional | B12: Perjalanan Dinas | C12: 1 | D12: 29400000 | E12: 31450000
A13: Operasional | B13: Perjalanan Dinas | C13: 2 | D13: 30600000 | E13: 35980000
A14: Operasional | B14: Perjalanan Dinas | C14: 3 | D14: 31800000 | E14: 27610000
A15: Operasional | B15: Perjalanan Dinas | C15: 4 | D15: 28200000 | E15: 30530000
A16: Operasional | B16: Perjalanan Dinas | C16: 5 | D16: 29400000
A17: Operasional | B17: Perjalanan Dinas | C17: 6 | D17: 30600000
A18: Operasional | B18: Pemasaran & Iklan | C18: 1 | D18: 15680000 | E18: 18500000
A19: Operasional | B19: Pemasaran & Iklan | C19: 2 | D19: 16320000 | E19: 19440000
A20: Operasional | B20: Pemasaran & Iklan | C20: 3 | D20: 16960000 | E20: 21390000
A21: Operasional | B21: Pemasaran & Iklan | C21: 4 | D21: 15040000 | E21: 12860000
A22: Operasional | B22: Pemasaran & Iklan | C22: 5 | D22: 15680000
A23: Operasional | B23: Pemasaran & Iklan | C23: 6 | D23: 16320000
A24: Operasional | B24: Utilitas | C24: 1 | D24: 40180000 | E24: 41280000
A25: Operasional | B25: Utilitas | C25: 2 | D25: 41820000 | E25: 46510000
A26: Operasional | B26: Utilitas | C26: 3 | D26: 43460000 | E26: 39160000
A27: Operasional | B27: Utilitas | C27: 4 | D27: 38540000 | E27: 46620000
A28: Operasional | B28: Utilitas | C28: 5 | D28: 40180000
A29: Operasional | B29: Utilitas | C29: 6 | D29: 41820000
A30: Operasional | B30: Perlengkapan | C30: 1 | D30: 37240000 | E30: 43900000
A31: Operasional | B31: Perlengkapan | C31: 2 | D31: 38760000 | E31: 34810000
A32: Operasional | B32: Perlengkapan | C32: 3 | D32: 40280000 | E32: 36180000
A33: Operasional | B33: Perlengkapan | C33: 4 | D33: 35720000 | E33: 32680000
A34: Operasional | B34: Perlengkapan | C34: 5 | D34: 37240000
A35: Operasional | B35: Perlengkapan | C35: 6 | D35: 38760000
A36: Operasional | B36: Pelatihan | C36: 1 | D36: 38220000 | E36: 45580000
A37: Operasional | B37: Pelatihan | C37: 2 | D37: 39780000 | E37: 39060000
A38: Operasional | B38: Pelatihan | C38: 3 | D38: 41340000 | E38: 43550000
A39: Operasional | B39: Pelatihan | C39: 4 | D39: 36660000 | E39: 38920000
A40: Operasional | B40: Pelatihan | C40: 5 | D40: 38220000
A41: Operasional | B41: Pelatihan | C41: 6 | D41: 39780000
...

Sheet VARIANS
A1: Analisis Varians
A2: ="Departemen: "&PARAMETER!C5&" | Januari s/d bulan ke-"&PARAMETER!C6&" | Toleransi "&TEXT(PARAMETER!C7,"0%")
A3: VERSI DEMO: kapasitas & fitur dibatasi, data simulasi. Versi lengkap: WhatsApp 089623291732
A5: Akun | B5: Anggaran YTD (Rp) | C5: Realisasi YTD (Rp) | D5: Selisih (Rp) | E5: Selisih (%) | F5: Status
A6: =IF(MASTER!C6="","",MASTER!C6) | B6: =IF($A6="","",SUMIFS(DATA!$D$6:$D$155,DATA!$A$6:$A$155,IF(PARAMETER!$C$5="Semua","*",PARAMETER!$C$5),DATA!$B$6:$B$155,$A6,DATA!$C$6:$C$155,"<="&PARAMETER!$C$6)) | C6: =IF($A6="","",SUMIFS(DATA!$E$6:$E$155,DATA!$A$6:$A$155,IF(PARAMETER!$C$5="Semua","*",PARAMETER!$C$5),DATA!$B$6:$B$155,$A6,DATA!$C$6:$C$155,"<="&PARAMETER!$C$6)) | D6: =IF($A6="","",B6-C6) | E6: =IF($A6="","",IF(B6=0,0,D6/B6)) | F6: =IF($A6="","",IF(B6=0,"-",IF(C6>B6*(1+PARAMETER!$C$7),"Over Budget",IF(C6<B6*(1-PARAMETER!$C$7),"Hemat","On Track"))))
A7: =IF(MASTER!C7="","",MASTER!C7) | B7: =IF($A7="","",SUMIFS(DATA!$D$6:$D$155,DATA!$A$6:$A$155,IF(PARAMETER!$C$5="Semua","*",PARAMETER!$C$5),DATA!$B$6:$B$155,$A7,DATA!$C$6:$C$155,"<="&PARAMETER!$C$6)) | C7: =IF($A7="","",SUMIFS(DATA!$E$6:$E$155,DATA!$A$6:$A$155,IF(PARAMETER!$C$5="Semua","*",PARAMETER!$C$5),DATA!$B$6:$B$155,$A7,DATA!$C$6:$C$155,"<="&PARAMETER!$C$6)) | D7: =IF($A7="","",B7-C7) | E7: =IF($A7="","",IF(B7=0,0,D7/B7)) | F7: =IF($A7="","",IF(B7=0,"-",IF(C7>B7*(1+PARAMETER!$C$7),"Over Budget",IF(C7<B7*(1-PARAMETER!$C$7),"Hemat","On Track"))))
A8: =IF(MASTER!C8="","",MASTER!C8) | B8: =IF($A8="","",SUMIFS(DATA!$D$6:$D$155,DATA!$A$6:$A$155,IF(PARAMETER!$C$5="Semua","*",PARAMETER!$C$5),DATA!$B$6:$B$155,$A8,DATA!$C$6:$C$155,"<="&PARAMETER!$C$6)) | C8: =IF($A8="","",SUMIFS(DATA!$E$6:$E$155,DATA!$A$6:$A$155,IF(PARAMETER!$C$5="Semua","*",PARAMETER!$C$5),DATA!$B$6:$B$155,$A8,DATA!$C$6:$C$155,"<="&PARAMETER!$C$6)) | D8: =IF($A8="","",B8-C8) | E8: =IF($A8="","",IF(B8=0,0,D8/B8)) | F8: =IF($A8="","",IF(B8=0,"-",IF(C8>B8*(1+PARAMETER!$C$7),"Over Budget",IF(C8<B8*(1-PARAMETER!$C$7),"Hemat","On Track"))))
A9: =IF(MASTER!C9="","",MASTER!C9) | B9: =IF($A9="","",SUMIFS(DATA!$D$6:$D$155,DATA!$A$6:$A$155,IF(PARAMETER!$C$5="Semua","*",PARAMETER!$C$5),DATA!$B$6:$B$155,$A9,DATA!$C$6:$C$155,"<="&PARAMETER!$C$6)) | C9: =IF($A9="","",SUMIFS(DATA!$E$6:$E$155,DATA!$A$6:$A$155,IF(PARAMETER!$C$5="Semua","*",PARAMETER!$C$5),DATA!$B$6:$B$155,$A9,DATA!$C$6:$C$155,"<="&PARAMETER!$C$6)) | D9: =IF($A9="","",B9-C9) | E9: =IF($A9="","",IF(B9=0,0,D9/B9)) | F9: =IF($A9="","",IF(B9=0,"-",IF(C9>B9*(1+PARAMETER!$C$7),"Over Budget",IF(C9<B9*(1-PARAMETER!$C$7),"Hemat","On Track"))))
A10: =IF(MASTER!C10="","",MASTER!C10) | B10: =IF($A10="","",SUMIFS(DATA!$D$6:$D$155,DATA!$A$6:$A$155,IF(PARAMETER!$C$5="Semua","*",PARAMETER!$C$5),DATA!$B$6:$B$155,$A10,DATA!$C$6:$C$155,"<="&PARAMETER!$C$6)) | C10: =IF($A10="","",SUMIFS(DATA!$E$6:$E$155,DATA!$A$6:$A$155,IF(PARAMETER!$C$5="Semua","*",PARAMETER!$C$5),DATA!$B$6:$B$155,$A10,DATA!$C$6:$C$155,"<="&PARAMETER!$C$6)) | D10: =IF($A10="","",B10-C10) | E10: =IF($A10="","",IF(B10=0,0,D10/B10)) | F10: =IF($A10="","",IF(B10=0,"-",IF(C10>B10*(1+PARAMETER!$C$7),"Over Budget",IF(C10<B10*(1-PARAMETER!$C$7),"Hemat","On Track"))))
A11: =IF(MASTER!C11="","",MASTER!C11) | B11: =IF($A11="","",SUMIFS(DATA!$D$6:$D$155,DATA!$A$6:$A$155,IF(PARAMETER!$C$5="Semua","*",PARAMETER!$C$5),DATA!$B$6:$B$155,$A11,DATA!$C$6:$C$155,"<="&PARAMETER!$C$6)) | C11: =IF($A11="","",SUMIFS(DATA!$E$6:$E$155,DATA!$A$6:$A$155,IF(PARAMETER!$C$5="Semua","*",PARAMETER!$C$5),DATA!$B$6:$B$155,$A11,DATA!$C$6:$C$155,"<="&PARAMETER!$C$6)) | D11: =IF($A11="","",B11-C11) | E11: =IF($A11="","",IF(B11=0,0,D11/B11)) | F11: =IF($A11="","",IF(B11=0,"-",IF(C11>B11*(1+PARAMETER!$C$7),"Over Budget",IF(C11<B11*(1-PARAMETER!$C$7),"Hemat","On Track"))))
A12: =IF(MASTER!C12="","",MASTER!C12) | B12: =IF($A12="","",SUMIFS(DATA!$D$6:$D$155,DATA!$A$6:$A$155,IF(PARAMETER!$C$5="Semua","*",PARAMETER!$C$5),DATA!$B$6:$B$155,$A12,DATA!$C$6:$C$155,"<="&PARAMETER!$C$6)) | C12: =IF($A12="","",SUMIFS(DATA!$E$6:$E$155,DATA!$A$6:$A$155,IF(PARAMETER!$C$5="Semua","*",PARAMETER!$C$5),DATA!$B$6:$B$155,$A12,DATA!$C$6:$C$155,"<="&PARAMETER!$C$6)) | D12: =IF($A12="","",B12-C12) | E12: =IF($A12="","",IF(B12=0,0,D12/B12)) | F12: =IF($A12="","",IF(B12=0,"-",IF(C12>B12*(1+PARAMETER!$C$7),"Over Budget",IF(C12<B12*(1-PARAMETER!$C$7),"Hemat","On Track"))))
A13: =IF(MASTER!C13="","",MASTER!C13) | B13: =IF($A13="","",SUMIFS(DATA!$D$6:$D$155,DATA!$A$6:$A$155,IF(PARAMETER!$C$5="Semua","*",PARAMETER!$C$5),DATA!$B$6:$B$155,$A13,DATA!$C$6:$C$155,"<="&PARAMETER!$C$6)) | C13: =IF($A13="","",SUMIFS(DATA!$E$6:$E$155,DATA!$A$6:$A$155,IF(PARAMETER!$C$5="Semua","*",PARAMETER!$C$5),DATA!$B$6:$B$155,$A13,DATA!$C$6:$C$155,"<="&PARAMETER!$C$6)) | D13: =IF($A13="","",B13-C13) | E13: =IF($A13="","",IF(B13=0,0,D13/B13)) | F13: =IF($A13="","",IF(B13=0,"-",IF(C13>B13*(1+PARAMETER!$C$7),"Over Budget",IF(C13<B13*(1-PARAMETER!$C$7),"Hemat","On Track"))))
A14: =IF(MASTER!C14="","",MASTER!C14) | B14: =IF($A14="","",SUMIFS(DATA!$D$6:$D$155,DATA!$A$6:$A$155,IF(PARAMETER!$C$5="Semua","*",PARAMETER!$C$5),DATA!$B$6:$B$155,$A14,DATA!$C$6:$C$155,"<="&PARAMETER!$C$6)) | C14: =IF($A14="","",SUMIFS(DATA!$E$6:$E$155,DATA!$A$6:$A$155,IF(PARAMETER!$C$5="Semua","*",PARAMETER!$C$5),DATA!$B$6:$B$155,$A14,DATA!$C$6:$C$155,"<="&PARAMETER!$C$6)) | D14: =IF($A14="","",B14-C14) | E14: =IF($A14="","",IF(B14=0,0,D14/B14)) | F14: =IF($A14="","",IF(B14=0,"-",IF(C14>B14*(1+PARAMETER!$C$7),"Over Budget",IF(C14<B14*(1-PARAMETER!$C$7),"Hemat","On Track"))))
A15: =IF(MASTER!C15="","",MASTER!C15) | B15: =IF($A15="","",SUMIFS(DATA!$D$6:$D$155,DATA!$A$6:$A$155,IF(PARAMETER!$C$5="Semua","*",PARAMETER!$C$5),DATA!$B$6:$B$155,$A15,DATA!$C$6:$C$155,"<="&PARAMETER!$C$6)) | C15: =IF($A15="","",SUMIFS(DATA!$E$6:$E$155,DATA!$A$6:$A$155,IF(PARAMETER!$C$5="Semua","*",PARAMETER!$C$5),DATA!$B$6:$B$155,$A15,DATA!$C$6:$C$155,"<="&PARAMETER!$C$6)) | D15: =IF($A15="","",B15-C15) | E15: =IF($A15="","",IF(B15=0,0,D15/B15)) | F15: =IF($A15="","",IF(B15=0,"-",IF(C15>B15*(1+PARAMETER!$C$7),"Over Budget",IF(C15<B15*(1-PARAMETER!$C$7),"Hemat","On Track"))))
A16: =IF(MASTER!C16="","",MASTER!C16) | B16: =IF($A16="","",SUMIFS(DATA!$D$6:$D$155,DATA!$A$6:$A$155,IF(PARAMETER!$C$5="Semua","*",PARAMETER!$C$5),DATA!$B$6:$B$155,$A16,DATA!$C$6:$C$155,"<="&PARAMETER!$C$6)) | C16: =IF($A16="","",SUMIFS(DATA!$E$6:$E$155,DATA!$A$6:$A$155,IF(PARAMETER!$C$5="Semua","*",PARAMETER!$C$5),DATA!$B$6:$B$155,$A16,DATA!$C$6:$C$155,"<="&PARAMETER!$C$6)) | D16: =IF($A16="","",B16-C16) | E16: =IF($A16="","",IF(B16=0,0,D16/B16)) | F16: =IF($A16="","",IF(B16=0,"-",IF(C16>B16*(1+PARAMETER!$C$7),"Over Budget",IF(C16<B16*(1-PARAMETER!$C$7),"Hemat","On Track"))))
A17: =IF(MASTER!C17="","",MASTER!C17) | B17: =IF($A17="","",SUMIFS(DATA!$D$6:$D$155,DATA!$A$6:$A$155,IF(PARAMETER!$C$5="Semua","*",PARAMETER!$C$5),DATA!$B$6:$B$155,$A17,DATA!$C$6:$C$155,"<="&PARAMETER!$C$6)) | C17: =IF($A17="","",SUMIFS(DATA!$E$6:$E$155,DATA!$A$6:$A$155,IF(PARAMETER!$C$5="Semua","*",PARAMETER!$C$5),DATA!$B$6:$B$155,$A17,DATA!$C$6:$C$155,"<="&PARAMETER!$C$6)) | D17: =IF($A17="","",B17-C17) | E17: =IF($A17="","",IF(B17=0,0,D17/B17)) | F17: =IF($A17="","",IF(B17=0,"-",IF(C17>B17*(1+PARAMETER!$C$7),"Over Budget",IF(C17<B17*(1-PARAMETER!$C$7),"Hemat","On Track"))))
A18: TOTAL | B18: =SUM(B6:B17) | C18: =SUM(C6:C17) | D18: =SUM(D6:D17) | E18: =IF(B18=0,0,D18/B18)
