Workbook

Sheet PETUNJUK
B1: Mantam Product
B2: HRMS Enterprise (Demo)
B3: Sistem SDM lengkap dalam Excel: master karyawan, absensi, cuti, payroll dengan BPJS dan PPh 21 TER, slip gaji, rekrutmen, kinerja, pelatihan, dan dashboard.
B5: Lisensi | C5: VERSI DEMO. Kapasitas dan fitur dibatasi. Pesan versi lengkap: WhatsApp 089623291732
B7: Cara memakai
B8: Langkah 1 | C8: Buka PARAMETER: isi nama perusahaan, bulan dan tahun payroll, hari kerja, tarif BPJS, dan daftar pilihan (sel kuning/biru).
B9: Langkah 2 | C9: Isi master karyawan di KARYAWAN (satu baris per orang). Gaji, PTKP, dan status menentukan perhitungan payroll.
B10: Langkah 3 | C10: Tiap bulan isi ABSENSI (hari hadir, sakit, izin, cuti, alpa, jam lembur, bonus). Baris mengikuti urutan KARYAWAN.
B11: Langkah 4 | C11: Buka PAYROLL untuk melihat gaji bersih dan total biaya perusahaan.
B13: Isi berkas
B14: PARAMETER | C14: Pusat kustomisasi: identitas perusahaan, periode, tunjangan, tarif BPJS, PTKP, tarif progresif Pasal 17, daftar pilihan, band gaji.
B15: TARIF_TER | C15: Tabel tarif efektif rata-rata (TER) kategori A, B, C untuk PPh 21 bulanan; dapat Anda perbarui bila aturan berubah.
B16: KARYAWAN | C16: Master karyawan (kapasitas 15): identitas, jabatan, grade, status, PTKP, gaji, 2 kolom kustom; usia, masa kerja, kategori TER, dan posisi terhadap band gaji otomatis.
B17: ABSENSI | C17: Rekap kehadiran bulanan per karyawan: hadir, sakit, izin, cuti, alpa, jam lembur, bonus, potongan lain, dengan pengecekan jumlah hari.
B18: PAYROLL | C18: Penggajian otomatis: tunjangan, lembur, potongan alpa, BPJS perusahaan dan karyawan, PPh 21 (TER), gaji bersih, dan total biaya perusahaan.
B19: RINGKASAN | C19: Headcount dan biaya payroll per departemen.
B21: Legenda warna
B22: Teks biru | C22: Sel input: boleh Anda ubah (tidak terkunci).
B23: Sel kuning | C23: Parameter kunci: periksa terlebih dulu.
B24: Teks hitam | C24: Rumus otomatis (terkunci; Review > Unprotect Sheet tanpa kata sandi bila perlu).
B26: Catatan
C27: • Seluruh data adalah simulasi buatan, bukan data perusahaan nyata.
C28: • Hasil perhitungan adalah alat bantu; verifikasi dengan akuntan/konsultan sebelum dipakai untuk keputusan atau pelaporan resmi.
C29: • Tarif BPJS, PTKP, dan tabel TER di berkas ini adalah nilai acuan dan DAPAT BERUBAH. Verifikasi dengan peraturan resmi (PP 58/2023, PMK 168/2023, ketentuan BPJS terbaru) sebelum dipakai untuk penggajian nyata.
C30: • Tabel TER disalin dari sumber sekunder; cocokkan dengan lampiran resmi PMK 168/2023. Batas upah dan tarif BPJS Kesehatan perlu diverifikasi karena sering diperbarui.
C31: • PPh 21 Januari–November memakai TER; Desember (masa pajak terakhir) memakai tarif progresif Pasal 17 dengan estimasi setahun dari penghasilan bulan terpilih (penyederhanaan). Laporan pajak resmi tetap harus melalui konsultan/aplikasi pajak.
C32: • Kustomisasi: ganti nama tunjangan, tarif, daftar departemen/status, band gaji, bobot KPI, tabel rating, dan 2 kolom kustom di PARAMETER tanpa mengubah rumus. Perlu modul khusus? Hubungi WhatsApp 089623291732 (layanan Custom Pro).
C33: • Data karyawan bersifat pribadi; simpan berkas ini dengan aman dan bagikan sesuai kebijakan privasi perusahaan Anda.

Sheet PARAMETER
A1: Parameter & Kustomisasi
A2: Sel kuning = parameter kunci; sel biru = daftar yang bisa Anda ganti.
A3: VERSI DEMO: kapasitas & fitur dibatasi, data simulasi. Versi lengkap: WhatsApp 089623291732
B5: Nama perusahaan | C5: PT Nusantara Karya Mandiri (contoh)
B6: Bulan payroll (1-12) | C6: 10 | F6: Bulan 12 memakai perhitungan PPh 21 progresif tahunan.
B7: Tahun payroll | C7: 2026
B8: Hari kerja pada bulan payroll | C8: 22
B9: Pembagi upah per jam (jam/bulan) | C9: 173
B10: Pengali lembur rata-rata | C10: 1.75 | F10: Contoh 1,75; sesuaikan aturan lembur perusahaan.
B11: Tunjangan Transport (per hari hadir) | C11: 25000
B12: Tunjangan Makan (per hari hadir) | C12: 30000
B13: Tanggal laporan | C13: 46326
B14: Jatah cuti tahunan (hari) | C14: 12
B15: Biaya jabatan (% penghasilan) | C15: 0.05
B16: Biaya jabatan maksimum per tahun (Rp) | C16: 6000000
B17: Nama kolom kustom 1 (tanggal) | C17: Tgl Akhir Kontrak
B18: Nama kolom kustom 2 (teks) | C18: Catatan HR
B20: TARIF BPJS (acuan, verifikasi dengan aturan terbaru)
B21: Komponen | C21: Perusahaan | D21: Karyawan | E21: Batas upah (Rp)
B22: JHT (Jaminan Hari Tua) | C22: 0.037 | D22: 0.02 | E22: 9999999999
B23: JP (Jaminan Pensiun) | C23: 0.02 | D23: 0.01 | E23: 10547400
B24: JKK (Kecelakaan Kerja) | C24: 0.0024 | D24: 0 | E24: 9999999999
B25: JKM (Kematian) | C25: 0.003 | D25: 0 | E25: 9999999999
B26: BPJS Kesehatan | C26: 0.04 | D26: 0.01 | E26: 12000000
B27: Batas 9.999.999.999 = tanpa batas. JKK mengikuti kelas risiko usaha (default contoh 0,24%). JKP ditanggung pemerintah/rekomposisi JKK, tidak dimodelkan.
B29: PTKP & KATEGORI TER | F29: TARIF PROGRESIF PASAL 17
B30: Status | C30: PTKP setahun (Rp) | D30: Kategori TER | F30: Batas bawah PKP (Rp) | G30: Tarif | H30: Selisih tarif
B31: TK/0 | C31: 54000000 | D31: A | F31: 0 | G31: 0.05 | H31: =G31
B32: TK/1 | C32: 58500000 | D32: A | F32: 60000000 | G32: 0.15 | H32: =G32-G31
B33: TK/2 | C33: 63000000 | D33: B | F33: 250000000 | G33: 0.25 | H33: =G33-G32
B34: TK/3 | C34: 67500000 | D34: B | F34: 500000000 | G34: 0.3 | H34: =G34-G33
B35: K/0 | C35: 58500000 | D35: A | F35: 5000000000 | G35: 0.35 | H35: =G35-G34
B36: K/1 | C36: 63000000 | D36: B
B37: K/2 | C37: 67500000 | D37: B
B38: K/3 | C38: 72000000 | D38: C
B40: DAFTAR PILIHAN (ganti sesuai perusahaan Anda)
B41: Departemen | C41: Status kerja | D41: Lokasi | E41: Tahap rekrutmen | F41: Sumber kandidat | G41: Jenis cuti | H41: Status cuti | I41: Kategori pelatihan
B42: Operasional | C42: Tetap | D42: Jakarta | E42: Lamaran | F42: LinkedIn | G42: Tahunan | H42: Disetujui | I42: Teknis
B43: Keuangan | C43: Kontrak | D43: Bandung | E43: Screening | F43: Jobstreet | G43: Sakit | H43: Menunggu | I43: Kepemimpinan
B44: Pemasaran | C44: Probation | D44: Surabaya | E44: Interview HR | F44: Referral | G44: Melahirkan | H44: Ditolak | I44: Soft Skill
...

Sheet TARIF_TER
A1: Tarif Efektif Rata-rata (TER) PPh 21
A2: Batas bawah penghasilan bruto bulanan (Rp) dan tarif. Verifikasi dengan lampiran resmi PMK 168/2023.
A3: VERSI DEMO: kapasitas & fitur dibatasi, data simulasi. Versi lengkap: WhatsApp 089623291732
B5: KATEGORI A | E5: KATEGORI B | H5: KATEGORI C
B6: Dari (Rp) | C6: Tarif | E6: Dari (Rp) | F6: Tarif | H6: Dari (Rp) | I6: Tarif
B7: 0 | C7: 0 | E7: 0 | F7: 0 | H7: 0 | I7: 0
B8: 5400001 | C8: 0.0025 | E8: 6200001 | F8: 0.0025 | H8: 6600001 | I8: 0.0025
B9: 5650001 | C9: 0.005 | E9: 6500001 | F9: 0.005 | H9: 6950001 | I9: 0.005
B10: 5950001 | C10: 0.0075 | E10: 6850001 | F10: 0.0075 | H10: 7350001 | I10: 0.0075
B11: 6300001 | C11: 0.01 | E11: 7300001 | F11: 0.01 | H11: 7800001 | I11: 0.01
B12: 6750001 | C12: 0.0125 | E12: 9200001 | F12: 0.015 | H12: 8850001 | I12: 0.0125
B13: 7500001 | C13: 0.015 | E13: 10750001 | F13: 0.02 | H13: 9800001 | I13: 0.015
B14: 8550001 | C14: 0.0175 | E14: 11250001 | F14: 0.025 | H14: 10950001 | I14: 0.0175
B15: 9650001 | C15: 0.02 | E15: 11600001 | F15: 0.03 | H15: 11200001 | I15: 0.02
B16: 10050001 | C16: 0.0225 | E16: 12600001 | F16: 0.04 | H16: 12050001 | I16: 0.03
B17: 10350001 | C17: 0.025 | E17: 13600001 | F17: 0.05 | H17: 12950001 | I17: 0.04
B18: 10700001 | C18: 0.03 | E18: 14950001 | F18: 0.06 | H18: 14150001 | I18: 0.05
... B46: 454000001 | C46: 0.3 | E46: 1405000001 | F46: 0.34 | H46: 965000001 | I46: 0.33
B47: 550000001 | C47: 0.31 | H47: 1419000001 | I47: 0.34
B48: 695000001 | C48: 0.32
B49: 910000001 | C49: 0.33
B50: 1400000001 | C50: 0.34

Sheet KARYAWAN
A1: Master Karyawan
A2: Kapasitas 15 baris. Satu baris per karyawan; ID harus unik.
A3: VERSI DEMO: kapasitas & fitur dibatasi, data simulasi. Versi lengkap: WhatsApp 089623291732
A5: ID | B5: Nama | C5: Gender (L/P) | D5: Tgl Lahir | E5: Departemen | F5: Jabatan | G5: Grade | H5: Status Kerja | I5: Tgl Masuk | J5: Status PTKP | K5: Gaji Pokok (Rp) | L5: Tunjangan Tetap (Rp) | M5: Atasan | N5: Lokasi | O5: Tgl Keluar | P5: =PARAMETER!C17 | Q5: =PARAMETER!C18 | R5: Usia (thn) | S5: Masa Kerja (thn) | T5: Kategori TER | U5: Aktif (1/0) | V5: Posisi vs Band Gaji
A6: K-001 | B6: Dian Pratama | C6: P | D6: 33464 | E6: Teknologi | F6: Direktur | G6: G6 | H6: Tetap | I6: 44440 | J6: TK/1 | K6: 49500000 | L6: 5100000 | M6: - | N6: Bandung | R6: =IF(OR($A6="",D6=""),"",INT((PARAMETER!$C$13-D6)/365.25)) | S6: =IF(OR($A6="",I6=""),"",ROUND((IF(O6="",PARAMETER!$C$13,MIN(O6,PARAMETER!$C$13))-I6)/365.25,1)) | T6: =IF($A6="","",IFERROR(INDEX(PARAMETER!$D$31:$D$38,MATCH(J6,PARAMETER!$B$31:$B$38,0)),"?")) | U6: =IF($A6="","",IF(H6="Resign",0,1))
A7: K-002 | B7: Nadia Utami | C7: P | D7: 35009 | E7: SDM | F7: Senior Staf | G7: G3 | H7: Tetap | I7: 42809 | J7: K/1 | K7: 12250000 | L7: 1400000 | M7: - | N7: Bandung | R7: =IF(OR($A7="",D7=""),"",INT((PARAMETER!$C$13-D7)/365.25)) | S7: =IF(OR($A7="",I7=""),"",ROUND((IF(O7="",PARAMETER!$C$13,MIN(O7,PARAMETER!$C$13))-I7)/365.25,1)) | T7: =IF($A7="","",IFERROR(INDEX(PARAMETER!$D$31:$D$38,MATCH(J7,PARAMETER!$B$31:$B$38,0)),"?")) | U7: =IF($A7="","",IF(H7="Resign",0,1))
A8: K-003 | B8: Farah Kusuma | C8: P | D8: 34893 | E8: Teknologi | F8: Manajer | G8: G4 | H8: Tetap | I8: 45533 | J8: TK/0 | K8: 20350000 | L8: 3400000 | M8: Dian Pratama | N8: Bandung | R8: =IF(OR($A8="",D8=""),"",INT((PARAMETER!$C$13-D8)/365.25)) | S8: =IF(OR($A8="",I8=""),"",ROUND((IF(O8="",PARAMETER!$C$13,MIN(O8,PARAMETER!$C$13))-I8)/365.25,1)) | T8: =IF($A8="","",IFERROR(INDEX(PARAMETER!$D$31:$D$38,MATCH(J8,PARAMETER!$B$31:$B$38,0)),"?")) | U8: =IF($A8="","",IF(H8="Resign",0,1))
A9: K-004 | B9: Dimas Nugroho | C9: L | D9: 34388 | E9: SDM | F9: Staf Junior | G9: G1 | H9: Kontrak | I9: 42976 | J9: K/2 | K9: 5550000 | L9: 950000 | M9: Nadia Utami | N9: Jakarta | P9: 46593 | R9: =IF(OR($A9="",D9=""),"",INT((PARAMETER!$C$13-D9)/365.25)) | S9: =IF(OR($A9="",I9=""),"",ROUND((IF(O9="",PARAMETER!$C$13,MIN(O9,PARAMETER!$C$13))-I9)/365.25,1)) | T9: =IF($A9="","",IFERROR(INDEX(PARAMETER!$D$31:$D$38,MATCH(J9,PARAMETER!$B$31:$B$38,0)),"?")) | U9: =IF($A9="","",IF(H9="Resign",0,1))
A10: K-005 | B10: Dimas Pratama | C10: L | D10: 37706 | E10: Teknologi | F10: Staf | G10: G2 | H10: Tetap | I10: 45737 | J10: K/1 | K10: 7100000 | L10: 650000 | M10: Dian Pratama | N10: Jakarta | R10: =IF(OR($A10="",D10=""),"",INT((PARAMETER!$C$13-D10)/365.25)) | S10: =IF(OR($A10="",I10=""),"",ROUND((IF(O10="",PARAMETER!$C$13,MIN(O10,PARAMETER!$C$13))-I10)/365.25,1)) | T10: =IF($A10="","",IFERROR(INDEX(PARAMETER!$D$31:$D$38,MATCH(J10,PARAMETER!$B$31:$B$38,0)),"?")) | U10: =IF($A10="","",IF(H10="Resign",0,1))
A11: K-006 | B11: Nadia Pratama | C11: P | D11: 34958 | E11: SDM | F11: Staf | G11: G2 | H11: Tetap | I11: 45357 | J11: K/0 | K11: 7150000 | L11: 1050000 | M11: Nadia Utami | N11: Jakarta | R11: =IF(OR($A11="",D11=""),"",INT((PARAMETER!$C$13-D11)/365.25)) | S11: =IF(OR($A11="",I11=""),"",ROUND((IF(O11="",PARAMETER!$C$13,MIN(O11,PARAMETER!$C$13))-I11)/365.25,1)) | T11: =IF($A11="","",IFERROR(INDEX(PARAMETER!$D$31:$D$38,MATCH(J11,PARAMETER!$B$31:$B$38,0)),"?")) | U11: =IF($A11="","",IF(H11="Resign",0,1))
A12: K-007 | B12: Wahyu Hidayat | C12: L | D12: 36960 | E12: SDM | F12: Senior Staf | G12: G3 | H12: Tetap | I12: 45926 | J12: K/1 | K12: 10700000 | L12: 1400000 | M12: - | N12: Bandung | R12: =IF(OR($A12="",D12=""),"",INT((PARAMETER!$C$13-D12)/365.25)) | S12: =IF(OR($A12="",I12=""),"",ROUND((IF(O12="",PARAMETER!$C$13,MIN(O12,PARAMETER!$C$13))-I12)/365.25,1)) | T12: =IF($A12="","",IFERROR(INDEX(PARAMETER!$D$31:$D$38,MATCH(J12,PARAMETER!$B$31:$B$38,0)),"?")) | U12: =IF($A12="","",IF(H12="Resign",0,1))
A13: K-008 | B13: Fajar Firmansyah | C13: L | D13: 36169 | E13: Teknologi | F13: Senior Manajer | G13: G5 | H13: Resign | I13: 45691 | J13: TK/0 | K13: 27750000 | L13: 4200000 | M13: Dian Pratama | N13: Bandung | O13: 46211 | R13: =IF(OR($A13="",D13=""),"",INT((PARAMETER!$C$13-D13)/365.25)) | S13: =IF(OR($A13="",I13=""),"",ROUND((IF(O13="",PARAMETER!$C$13,MIN(O13,PARAMETER!$C$13))-I13)/365.25,1)) | T13: =IF($A13="","",IFERROR(INDEX(PARAMETER!$D$31:$D$38,MATCH(J13,PARAMETER!$B$31:$B$38,0)),"?")) | U13: =IF($A13="","",IF(H13="Resign",0,1))
A14: K-009 | B14: Vero Lestari | C14: P | D14: 30535 | E14: Teknologi | F14: Senior Staf | G14: G3 | H14: Tetap | I14: 42337 | J14: TK/2 | K14: 10100000 | L14: 850000 | M14: Dian Pratama | N14: Bandung | R14: =IF(OR($A14="",D14=""),"",INT((PARAMETER!$C$13-D14)/365.25)) | S14: =IF(OR($A14="",I14=""),"",ROUND((IF(O14="",PARAMETER!$C$13,MIN(O14,PARAMETER!$C$13))-I14)/365.25,1)) | T14: =IF($A14="","",IFERROR(INDEX(PARAMETER!$D$31:$D$38,MATCH(J14,PARAMETER!$B$31:$B$38,0)),"?")) | U14: =IF($A14="","",IF(H14="Resign",0,1))
A15: K-010 | B15: Tegar Santoso | C15: L | D15: 33029 | E15: Operasional | F15: Staf | G15: G2 | H15: Tetap | I15: 45006 | J15: TK/2 | K15: 9250000 | L15: 1600000 | M15: - | N15: Jakarta | R15: =IF(OR($A15="",D15=""),"",INT((PARAMETER!$C$13-D15)/365.25)) | S15: =IF(OR($A15="",I15=""),"",ROUND((IF(O15="",PARAMETER!$C$13,MIN(O15,PARAMETER!$C$13))-I15)/365.25,1)) | T15: =IF($A15="","",IFERROR(INDEX(PARAMETER!$D$31:$D$38,MATCH(J15,PARAMETER!$B$31:$B$38,0)),"?")) | U15: =IF($A15="","",IF(H15="Resign",0,1))
A16: K-011 | B16: Tegar Pratama | C16: L | D16: 35062 | E16: Keuangan | F16: Staf | G16: G2 | H16: Tetap | I16: 44002 | J16: TK/0 | K16: 8050000 | L16: 800000 | M16: - | N16: Bandung | R16: =IF(OR($A16="",D16=""),"",INT((PARAMETER!$C$13-D16)/365.25)) | S16: =IF(OR($A16="",I16=""),"",ROUND((IF(O16="",PARAMETER!$C$13,MIN(O16,PARAMETER!$C$13))-I16)/365.25,1)) | T16: =IF($A16="","",IFERROR(INDEX(PARAMETER!$D$31:$D$38,MATCH(J16,PARAMETER!$B$31:$B$38,0)),"?")) | U16: =IF($A16="","",IF(H16="Resign",0,1))
A17: K-012 | B17: Eko Maulana | C17: L | D17: 33281 | E17: Teknologi | F17: Senior Staf | G17: G3 | H17: Tetap | I17: 43884 | J17: K/0 | K17: 10200000 | L17: 900000 | M17: Dian Pratama | N17: Jakarta | R17: =IF(OR($A17="",D17=""),"",INT((PARAMETER!$C$13-D17)/365.25)) | S17: =IF(OR($A17="",I17=""),"",ROUND((IF(O17="",PARAMETER!$C$13,MIN(O17,PARAMETER!$C$13))-I17)/365.25,1)) | T17: =IF($A17="","",IFERROR(INDEX(PARAMETER!$D$31:$D$38,MATCH(J17,PARAMETER!$B$31:$B$38,0)),"?")) | U17: =IF($A17="","",IF(H17="Resign",0,1))
R18: =IF(OR($A18="",D18=""),"",INT((PARAMETER!$C$13-D18)/365.25)) | S18: =IF(OR($A18="",I18=""),"",ROUND((IF(O18="",PARAMETER!$C$13,MIN(O18,PARAMETER!$C$13))-I18)/365.25,1)) | T18: =IF($A18="","",IFERROR(INDEX(PARAMETER!$D$31:$D$38,MATCH(J18,PARAMETER!$B$31:$B$38,0)),"?")) | U18: =IF($A18="","",IF(H18="Resign",0,1))
R19: =IF(OR($A19="",D19=""),"",INT((PARAMETER!$C$13-D19)/365.25)) | S19: =IF(OR($A19="",I19=""),"",ROUND((IF(O19="",PARAMETER!$C$13,MIN(O19,PARAMETER!$C$13))-I19)/365.25,1)) | T19: =IF($A19="","",IFERROR(INDEX(PARAMETER!$D$31:$D$38,MATCH(J19,PARAMETER!$B$31:$B$38,0)),"?")) | U19: =IF($A19="","",IF(H19="Resign",0,1))
R20: =IF(OR($A20="",D20=""),"",INT((PARAMETER!$C$13-D20)/365.25)) | S20: =IF(OR($A20="",I20=""),"",ROUND((IF(O20="",PARAMETER!$C$13,MIN(O20,PARAMETER!$C$13))-I20)/365.25,1)) | T20: =IF($A20="","",IFERROR(INDEX(PARAMETER!$D$31:$D$38,MATCH(J20,PARAMETER!$B$31:$B$38,0)),"?")) | U20: =IF($A20="","",IF(H20="Resign",0,1))

Sheet ABSENSI
A1: Absensi Bulanan
A2: ="Periode "&CHOOSE(PARAMETER!$C$6,"Januari","Februari","Maret","April","Mei","Juni","Juli","Agustus","September","Oktober","November","Desember")&" "&PARAMETER!$C$7&" · hari kerja "&PARAMETER!$C$8
A3: VERSI DEMO: kapasitas & fitur dibatasi, data simulasi. Versi lengkap: WhatsApp 089623291732
A5: ID | B5: Nama | C5: Departemen | D5: Hadir | E5: Sakit | F5: Izin | G5: Cuti | H5: Alpa | I5: Jam Lembur | J5: Bonus / Insentif (Rp) | K5: Potongan Lain (Rp) | L5: Catatan | M5: Cek Hari
A6: =IF(KARYAWAN!A6="","",KARYAWAN!A6) | B6: =IF(KARYAWAN!A6="","",KARYAWAN!B6) | C6: =IF(KARYAWAN!A6="","",KARYAWAN!E6) | D6: 19 | E6: 0 | F6: 1 | G6: 2 | H6: 0 | I6: 0 | J6: 0 | K6: 500000 | M6: =IF(A6="","",IF(KARYAWAN!U6=0,"Resign",IF(SUM(D6:H6)=PARAMETER!$C$8,"OK","Cek hari")))
A7: =IF(KARYAWAN!A7="","",KARYAWAN!A7) | B7: =IF(KARYAWAN!A7="","",KARYAWAN!B7) | C7: =IF(KARYAWAN!A7="","",KARYAWAN!E7) | D7: 22 | E7: 0 | F7: 0 | G7: 0 | H7: 0 | I7: 0 | J7: 0 | K7: 0 | M7: =IF(A7="","",IF(KARYAWAN!U7=0,"Resign",IF(SUM(D7:H7)=PARAMETER!$C$8,"OK","Cek hari")))
A8: =IF(KARYAWAN!A8="","",KARYAWAN!A8) | B8: =IF(KARYAWAN!A8="","",KARYAWAN!B8) | C8: =IF(KARYAWAN!A8="","",KARYAWAN!E8) | D8: 22 | E8: 0 | F8: 0 | G8: 0 | H8: 0 | I8: 0 | J8: 0 | K8: 0 | M8: =IF(A8="","",IF(KARYAWAN!U8=0,"Resign",IF(SUM(D8:H8)=PARAMETER!$C$8,"OK","Cek hari")))
A9: =IF(KARYAWAN!A9="","",KARYAWAN!A9) | B9: =IF(KARYAWAN!A9="","",KARYAWAN!B9) | C9: =IF(KARYAWAN!A9="","",KARYAWAN!E9) | D9: 22 | E9: 0 | F9: 0 | G9: 0 | H9: 0 | I9: 12 | J9: 0 | K9: 0 | M9: =IF(A9="","",IF(KARYAWAN!U9=0,"Resign",IF(SUM(D9:H9)=PARAMETER!$C$8,"OK","Cek hari")))
A10: =IF(KARYAWAN!A10="","",KARYAWAN!A10) | B10: =IF(KARYAWAN!A10="","",KARYAWAN!B10) | C10: =IF(KARYAWAN!A10="","",KARYAWAN!E10) | D10: 22 | E10: 0 | F10: 0 | G10: 0 | H10: 0 | I10: 0 | J10: 0 | K10: 0 | M10: =IF(A10="","",IF(KARYAWAN!U10=0,"Resign",IF(SUM(D10:H10)=PARAMETER!$C$8,"OK","Cek hari")))
A11: =IF(KARYAWAN!A11="","",KARYAWAN!A11) | B11: =IF(KARYAWAN!A11="","",KARYAWAN!B11) | C11: =IF(KARYAWAN!A11="","",KARYAWAN!E11) | D11: 18 | E11: 0 | F11: 0 | G11: 3 | H11: 1 | I11: 0 | J11: 0 | K11: 0 | M11: =IF(A11="","",IF(KARYAWAN!U11=0,"Resign",IF(SUM(D11:H11)=PARAMETER!$C$8,"OK","Cek hari")))
A12: =IF(KARYAWAN!A12="","",KARYAWAN!A12) | B12: =IF(KARYAWAN!A12="","",KARYAWAN!B12) | C12: =IF(KARYAWAN!A12="","",KARYAWAN!E12) | D12: 21 | E12: 0 | F12: 1 | G12: 0 | H12: 0 | I12: 0 | J12: 0 | K12: 0 | M12: =IF(A12="","",IF(KARYAWAN!U12=0,"Resign",IF(SUM(D12:H12)=PARAMETER!$C$8,"OK","Cek hari")))
A13: =IF(KARYAWAN!A13="","",KARYAWAN!A13) | B13: =IF(KARYAWAN!A13="","",KARYAWAN!B13) | C13: =IF(KARYAWAN!A13="","",KARYAWAN!E13) | D13: 0 | E13: 0 | F13: 0 | G13: 0 | H13: 0 | I13: 0 | J13: 0 | K13: 0 | M13: =IF(A13="","",IF(KARYAWAN!U13=0,"Resign",IF(SUM(D13:H13)=PARAMETER!$C$8,"OK","Cek hari")))
A14: =IF(KARYAWAN!A14="","",KARYAWAN!A14) | B14: =IF(KARYAWAN!A14="","",KARYAWAN!B14) | C14: =IF(KARYAWAN!A14="","",KARYAWAN!E14) | D14: 20 | E14: 0 | F14: 0 | G14: 2 | H14: 0 | I14: 0 | J14: 0 | K14: 250000 | M14: =IF(A14="","",IF(KARYAWAN!U14=0,"Resign",IF(SUM(D14:H14)=PARAMETER!$C$8,"OK","Cek hari")))
A15: =IF(KARYAWAN!A15="","",KARYAWAN!A15) | B15: =IF(KARYAWAN!A15="","",KARYAWAN!B15) | C15: =IF(KARYAWAN!A15="","",KARYAWAN!E15) | D15: 22 | E15: 0 | F15: 0 | G15: 0 | H15: 0 | I15: 4 | J15: 0 | K15: 0 | M15: =IF(A15="","",IF(KARYAWAN!U15=0,"Resign",IF(SUM(D15:H15)=PARAMETER!$C$8,"OK","Cek hari")))
A16: =IF(KARYAWAN!A16="","",KARYAWAN!A16) | B16: =IF(KARYAWAN!A16="","",KARYAWAN!B16) | C16: =IF(KARYAWAN!A16="","",KARYAWAN!E16) | D16: 19 | E16: 0 | F16: 1 | G16: 2 | H16: 0 | I16: 12 | J16: 0 | K16: 0 | M16: =IF(A16="","",IF(KARYAWAN!U16=0,"Resign",IF(SUM(D16:H16)=PARAMETER!$C$8,"OK","Cek hari")))
A17: =IF(KARYAWAN!A17="","",KARYAWAN!A17) | B17: =IF(KARYAWAN!A17="","",KARYAWAN!B17) | C17: =IF(KARYAWAN!A17="","",KARYAWAN!E17) | D17: 16 | E17: 2 | F17: 1 | G17: 3 | H17: 0 | I17: 8 | J17: 0 | K17: 0 | M17: =IF(A17="","",IF(KARYAWAN!U17=0,"Resign",IF(SUM(D17:H17)=PARAMETER!$C$8,"OK","Cek hari")))
A18: =IF(KARYAWAN!A18="","",KARYAWAN!A18) | B18: =IF(KARYAWAN!A18="","",KARYAWAN!B18) | C18: =IF(KARYAWAN!A18="","",KARYAWAN!E18) | M18: =IF(A18="","",IF(KARYAWAN!U18=0,"Resign",IF(SUM(D18:H18)=PARAMETER!$C$8,"OK","Cek hari")))
A19: =IF(KARYAWAN!A19="","",KARYAWAN!A19) | B19: =IF(KARYAWAN!A19="","",KARYAWAN!B19) | C19: =IF(KARYAWAN!A19="","",KARYAWAN!E19) | M19: =IF(A19="","",IF(KARYAWAN!U19=0,"Resign",IF(SUM(D19:H19)=PARAMETER!$C$8,"OK","Cek hari")))
A20: =IF(KARYAWAN!A20="","",KARYAWAN!A20) | B20: =IF(KARYAWAN!A20="","",KARYAWAN!B20) | C20: =IF(KARYAWAN!A20="","",KARYAWAN!E20) | M20: =IF(A20="","",IF(KARYAWAN!U20=0,"Resign",IF(SUM(D20:H20)=PARAMETER!$C$8,"OK","Cek hari")))

Sheet PAYROLL
A1: Payroll
A2: ="Periode "&CHOOSE(PARAMETER!$C$6,"Januari","Februari","Maret","April","Mei","Juni","Juli","Agustus","September","Oktober","November","Desember")&" "&PARAMETER!$C$7&IF(PARAMETER!$C$6=12," · PPh 21 progresif (masa pajak terakhir)"," · PPh 21 metode TER")
A3: VERSI DEMO: kapasitas & fitur dibatasi, data simulasi. Versi lengkap: WhatsApp 089623291732
A4: TOTAL | F4: =SUM(F6:F20) | G4: =SUM(G6:G20) | H4: =SUM(H6:H20) | I4: =SUM(I6:I20) | J4: =SUM(J6:J20) | K4: =SUM(K6:K20) | L4: =SUM(L6:L20) | M4: =SUM(M6:M20) | ... V4: =SUM(V6:V20) | X4: =SUM(X6:X20)
A5: ID | B5: Nama | C5: Departemen | D5: Status PTKP | E5: Kat. TER | F5: Gaji Pokok | G5: Tunjangan Tetap | H5: =PARAMETER!B11 | I5: =PARAMETER!B12 | J5: Lembur | K5: Bonus / Insentif | L5: Potongan Alpa | M5: Premi Perusahaan Kena Pajak (JKK+JKM+Kes) | N5: Penghasilan Bruto (dasar PPh) | O5: PPh 21 | P5: JHT Karyawan | Q5: JP Karyawan | R5: BPJS Kes. Karyawan | S5: Potongan Lain | T5: GAJI BERSIH (THP) | U5: BPJS Perusahaan (total) | V5: TOTAL BIAYA PERUSAHAAN | W5: Tarif TER | X5: PPh 21 metode TER
A6: =IF(KARYAWAN!A6="","",KARYAWAN!A6) | B6: =IF($A6="","",KARYAWAN!B6) | C6: =IF($A6="","",KARYAWAN!E6) | D6: =IF($A6="","",KARYAWAN!J6) | E6: =IF($A6="","",KARYAWAN!T6) | F6: =IF($A6="","",KARYAWAN!$U6*KARYAWAN!K6) | G6: =IF($A6="","",KARYAWAN!$U6*KARYAWAN!L6) | H6: =IF($A6="","",KARYAWAN!$U6*ABSENSI!D6*PARAMETER!$C$11) | I6: =IF($A6="","",KARYAWAN!$U6*ABSENSI!D6*PARAMETER!$C$12) | J6: =IF($A6="","",ROUND(KARYAWAN!$U6*ABSENSI!I6*(F6+G6)/PARAMETER!$C$9*PARAMETER!$C$10,0)) | K6: =IF($A6="","",KARYAWAN!$U6*ABSENSI!J6) | L6: =IF($A6="","",ROUND(KARYAWAN!$U6*ABSENSI!H6*F6/PARAMETER!$C$8,0)) | M6: =IF($A6="","",ROUND(MIN((F6+G6),PARAMETER!$E$24)*PARAMETER!$C$24+MIN((F6+G6),PARAMETER!$E$25)*PARAMETER!$C$25+MIN((F6+G6),PARAMETER!$E$26)*PARAMETER!$C$26,0)) | N6: =IF($A6="","",F6+G6+H6+I6+J6+K6-L6+M6) | O6: =IF($A6="","",X6) | P6: =IF($A6="","",ROUND(MIN((F6+G6),PARAMETER!$E$22)*PARAMETER!$D$22,0)) | Q6: =IF($A6="","",ROUND(MIN((F6+G6),PARAMETER!$E$23)*PARAMETER!$D$23,0)) | R6: =IF($A6="","",ROUND(MIN((F6+G6),PARAMETER!$E$26)*PARAMETER!$D$26,0)) | S6: =IF($A6="","",KARYAWAN!$U6*ABSENSI!K6) | T6: =IF($A6="","",F6+G6+H6+I6+J6+K6-L6-O6-P6-Q6-R6-S6) | U6: =IF($A6="","",M6+ROUND(MIN((F6+G6),PARAMETER!$E$22)*PARAMETER!$C$22,0)+ROUND(MIN((F6+G6),PARAMETER!$E$23)*PARAMETER!$C$23,0)) | V6: =IF($A6="","",F6+G6+H6+I6+J6+K6-L6+U6) | W6: =IF($A6="","",IF(E6="A",INDEX(TARIF_TER!$C$7:$C$50,MATCH(N6,TARIF_TER!$B$7:$B$50,1)),IF(E6="B",INDEX(TARIF_TER!$F$7:$F$46,MATCH(N6,TARIF_TER!$E$7:$E$46,1)),INDEX(TARIF_TER!$I$7:$I$47,MATCH(N6,TARIF_TER!$H$7:$H$47,1))))) | X6: =IF($A6="","",ROUND(N6*W6,0))
A7: =IF(KARYAWAN!A7="","",KARYAWAN!A7) | B7: =IF($A7="","",KARYAWAN!B7) | C7: =IF($A7="","",KARYAWAN!E7) | D7: =IF($A7="","",KARYAWAN!J7) | E7: =IF($A7="","",KARYAWAN!T7) | F7: =IF($A7="","",KARYAWAN!$U7*KARYAWAN!K7) | G7: =IF($A7="","",KARYAWAN!$U7*KARYAWAN!L7) | H7: =IF($A7="","",KARYAWAN!$U7*ABSENSI!D7*PARAMETER!$C$11) | I7: =IF($A7="","",KARYAWAN!$U7*ABSENSI!D7*PARAMETER!$C$12) | J7: =IF($A7="","",ROUND(KARYAWAN!$U7*ABSENSI!I7*(F7+G7)/PARAMETER!$C$9*PARAMETER!$C$10,0)) | K7: =IF($A7="","",KARYAWAN!$U7*ABSENSI!J7) | L7: =IF($A7="","",ROUND(KARYAWAN!$U7*ABSENSI!H7*F7/PARAMETER!$C$8,0)) | M7: =IF($A7="","",ROUND(MIN((F7+G7),PARAMETER!$E$24)*PARAMETER!$C$24+MIN((F7+G7),PARAMETER!$E$25)*PARAMETER!$C$25+MIN((F7+G7),PARAMETER!$E$26)*PARAMETER!$C$26,0)) | N7: =IF($A7="","",F7+G7+H7+I7+J7+K7-L7+M7) | O7: =IF($A7="","",X7) | P7: =IF($A7="","",ROUND(MIN((F7+G7),PARAMETER!$E$22)*PARAMETER!$D$22,0)) | Q7: =IF($A7="","",ROUND(MIN((F7+G7),PARAMETER!$E$23)*PARAMETER!$D$23,0)) | R7: =IF($A7="","",ROUND(MIN((F7+G7),PARAMETER!$E$26)*PARAMETER!$D$26,0)) | S7: =IF($A7="","",KARYAWAN!$U7*ABSENSI!K7) | T7: =IF($A7="","",F7+G7+H7+I7+J7+K7-L7-O7-P7-Q7-R7-S7) | U7: =IF($A7="","",M7+ROUND(MIN((F7+G7),PARAMETER!$E$22)*PARAMETER!$C$22,0)+ROUND(MIN((F7+G7),PARAMETER!$E$23)*PARAMETER!$C$23,0)) | V7: =IF($A7="","",F7+G7+H7+I7+J7+K7-L7+U7) | W7: =IF($A7="","",IF(E7="A",INDEX(TARIF_TER!$C$7:$C$50,MATCH(N7,TARIF_TER!$B$7:$B$50,1)),IF(E7="B",INDEX(TARIF_TER!$F$7:$F$46,MATCH(N7,TARIF_TER!$E$7:$E$46,1)),INDEX(TARIF_TER!$I$7:$I$47,MATCH(N7,TARIF_TER!$H$7:$H$47,1))))) | X7: =IF($A7="","",ROUND(N7*W7,0))
A8: =IF(KARYAWAN!A8="","",KARYAWAN!A8) | B8: =IF($A8="","",KARYAWAN!B8) | C8: =IF($A8="","",KARYAWAN!E8) | D8: =IF($A8="","",KARYAWAN!J8) | E8: =IF($A8="","",KARYAWAN!T8) | F8: =IF($A8="","",KARYAWAN!$U8*KARYAWAN!K8) | G8: =IF($A8="","",KARYAWAN!$U8*KARYAWAN!L8) | H8: =IF($A8="","",KARYAWAN!$U8*ABSENSI!D8*PARAMETER!$C$11) | I8: =IF($A8="","",KARYAWAN!$U8*ABSENSI!D8*PARAMETER!$C$12) | J8: =IF($A8="","",ROUND(KARYAWAN!$U8*ABSENSI!I8*(F8+G8)/PARAMETER!$C$9*PARAMETER!$C$10,0)) | K8: =IF($A8="","",KARYAWAN!$U8*ABSENSI!J8) | L8: =IF($A8="","",ROUND(KARYAWAN!$U8*ABSENSI!H8*F8/PARAMETER!$C$8,0)) | M8: =IF($A8="","",ROUND(MIN((F8+G8),PARAMETER!$E$24)*PARAMETER!$C$24+MIN((F8+G8),PARAMETER!$E$25)*PARAMETER!$C$25+MIN((F8+G8),PARAMETER!$E$26)*PARAMETER!$C$26,0)) | N8: =IF($A8="","",F8+G8+H8+I8+J8+K8-L8+M8) | O8: =IF($A8="","",X8) | P8: =IF($A8="","",ROUND(MIN((F8+G8),PARAMETER!$E$22)*PARAMETER!$D$22,0)) | Q8: =IF($A8="","",ROUND(MIN((F8+G8),PARAMETER!$E$23)*PARAMETER!$D$23,0)) | R8: =IF($A8="","",ROUND(MIN((F8+G8),PARAMETER!$E$26)*PARAMETER!$D$26,0)) | S8: =IF($A8="","",KARYAWAN!$U8*ABSENSI!K8) | T8: =IF($A8="","",F8+G8+H8+I8+J8+K8-L8-O8-P8-Q8-R8-S8) | U8: =IF($A8="","",M8+ROUND(MIN((F8+G8),PARAMETER!$E$22)*PARAMETER!$C$22,0)+ROUND(MIN((F8+G8),PARAMETER!$E$23)*PARAMETER!$C$23,0)) | V8: =IF($A8="","",F8+G8+H8+I8+J8+K8-L8+U8) | W8: =IF($A8="","",IF(E8="A",INDEX(TARIF_TER!$C$7:$C$50,MATCH(N8,TARIF_TER!$B$7:$B$50,1)),IF(E8="B",INDEX(TARIF_TER!$F$7:$F$46,MATCH(N8,TARIF_TER!$E$7:$E$46,1)),INDEX(TARIF_TER!$I$7:$I$47,MATCH(N8,TARIF_TER!$H$7:$H$47,1))))) | X8: =IF($A8="","",ROUND(N8*W8,0))
A9: =IF(KARYAWAN!A9="","",KARYAWAN!A9) | B9: =IF($A9="","",KARYAWAN!B9) | C9: =IF($A9="","",KARYAWAN!E9) | D9: =IF($A9="","",KARYAWAN!J9) | E9: =IF($A9="","",KARYAWAN!T9) | F9: =IF($A9="","",KARYAWAN!$U9*KARYAWAN!K9) | G9: =IF($A9="","",KARYAWAN!$U9*KARYAWAN!L9) | H9: =IF($A9="","",KARYAWAN!$U9*ABSENSI!D9*PARAMETER!$C$11) | I9: =IF($A9="","",KARYAWAN!$U9*ABSENSI!D9*PARAMETER!$C$12) | J9: =IF($A9="","",ROUND(KARYAWAN!$U9*ABSENSI!I9*(F9+G9)/PARAMETER!$C$9*PARAMETER!$C$10,0)) | K9: =IF($A9="","",KARYAWAN!$U9*ABSENSI!J9) | L9: =IF($A9="","",ROUND(KARYAWAN!$U9*ABSENSI!H9*F9/PARAMETER!$C$8,0)) | M9: =IF($A9="","",ROUND(MIN((F9+G9),PARAMETER!$E$24)*PARAMETER!$C$24+MIN((F9+G9),PARAMETER!$E$25)*PARAMETER!$C$25+MIN((F9+G9),PARAMETER!$E$26)*PARAMETER!$C$26,0)) | N9: =IF($A9="","",F9+G9+H9+I9+J9+K9-L9+M9) | O9: =IF($A9="","",X9) | P9: =IF($A9="","",ROUND(MIN((F9+G9),PARAMETER!$E$22)*PARAMETER!$D$22,0)) | Q9: =IF($A9="","",ROUND(MIN((F9+G9),PARAMETER!$E$23)*PARAMETER!$D$23,0)) | R9: =IF($A9="","",ROUND(MIN((F9+G9),PARAMETER!$E$26)*PARAMETER!$D$26,0)) | S9: =IF($A9="","",KARYAWAN!$U9*ABSENSI!K9) | T9: =IF($A9="","",F9+G9+H9+I9+J9+K9-L9-O9-P9-Q9-R9-S9) | U9: =IF($A9="","",M9+ROUND(MIN((F9+G9),PARAMETER!$E$22)*PARAMETER!$C$22,0)+ROUND(MIN((F9+G9),PARAMETER!$E$23)*PARAMETER!$C$23,0)) | V9: =IF($A9="","",F9+G9+H9+I9+J9+K9-L9+U9) | W9: =IF($A9="","",IF(E9="A",INDEX(TARIF_TER!$C$7:$C$50,MATCH(N9,TARIF_TER!$B$7:$B$50,1)),IF(E9="B",INDEX(TARIF_TER!$F$7:$F$46,MATCH(N9,TARIF_TER!$E$7:$E$46,1)),INDEX(TARIF_TER!$I$7:$I$47,MATCH(N9,TARIF_TER!$H$7:$H$47,1))))) | X9: =IF($A9="","",ROUND(N9*W9,0))
A10: =IF(KARYAWAN!A10="","",KARYAWAN!A10) | B10: =IF($A10="","",KARYAWAN!B10) | C10: =IF($A10="","",KARYAWAN!E10) | D10: =IF($A10="","",KARYAWAN!J10) | E10: =IF($A10="","",KARYAWAN!T10) | F10: =IF($A10="","",KARYAWAN!$U10*KARYAWAN!K10) | G10: =IF($A10="","",KARYAWAN!$U10*KARYAWAN!L10) | H10: =IF($A10="","",KARYAWAN!$U10*ABSENSI!D10*PARAMETER!$C$11) | I10: =IF($A10="","",KARYAWAN!$U10*ABSENSI!D10*PARAMETER!$C$12) | J10: =IF($A10="","",ROUND(KARYAWAN!$U10*ABSENSI!I10*(F10+G10)/PARAMETER!$C$9*PARAMETER!$C$10,0)) | K10: =IF($A10="","",KARYAWAN!$U10*ABSENSI!J10) | L10: =IF($A10="","",ROUND(KARYAWAN!$U10*ABSENSI!H10*F10/PARAMETER!$C$8,0)) | M10: =IF($A10="","",ROUND(MIN((F10+G10),PARAMETER!$E$24)*PARAMETER!$C$24+MIN((F10+G10),PARAMETER!$E$25)*PARAMETER!$C$25+MIN((F10+G10),PARAMETER!$E$26)*PARAMETER!$C$26,0)) | N10: =IF($A10="","",F10+G10+H10+I10+J10+K10-L10+M10) | O10: =IF($A10="","",X10) | P10: =IF($A10="","",ROUND(MIN((F10+G10),PARAMETER!$E$22)*PARAMETER!$D$22,0)) | Q10: =IF($A10="","",ROUND(MIN((F10+G10),PARAMETER!$E$23)*PARAMETER!$D$23,0)) | R10: =IF($A10="","",ROUND(MIN((F10+G10),PARAMETER!$E$26)*PARAMETER!$D$26,0)) | S10: =IF($A10="","",KARYAWAN!$U10*ABSENSI!K10) | T10: =IF($A10="","",F10+G10+H10+I10+J10+K10-L10-O10-P10-Q10-R10-S10) | U10: =IF($A10="","",M10+ROUND(MIN((F10+G10),PARAMETER!$E$22)*PARAMETER!$C$22,0)+ROUND(MIN((F10+G10),PARAMETER!$E$23)*PARAMETER!$C$23,0)) | V10: =IF($A10="","",F10+G10+H10+I10+J10+K10-L10+U10) | W10: =IF($A10="","",IF(E10="A",INDEX(TARIF_TER!$C$7:$C$50,MATCH(N10,TARIF_TER!$B$7:$B$50,1)),IF(E10="B",INDEX(TARIF_TER!$F$7:$F$46,MATCH(N10,TARIF_TER!$E$7:$E$46,1)),INDEX(TARIF_TER!$I$7:$I$47,MATCH(N10,TARIF_TER!$H$7:$H$47,1))))) | X10: =IF($A10="","",ROUND(N10*W10,0))
A11: =IF(KARYAWAN!A11="","",KARYAWAN!A11) | B11: =IF($A11="","",KARYAWAN!B11) | C11: =IF($A11="","",KARYAWAN!E11) | D11: =IF($A11="","",KARYAWAN!J11) | E11: =IF($A11="","",KARYAWAN!T11) | F11: =IF($A11="","",KARYAWAN!$U11*KARYAWAN!K11) | G11: =IF($A11="","",KARYAWAN!$U11*KARYAWAN!L11) | H11: =IF($A11="","",KARYAWAN!$U11*ABSENSI!D11*PARAMETER!$C$11) | I11: =IF($A11="","",KARYAWAN!$U11*ABSENSI!D11*PARAMETER!$C$12) | J11: =IF($A11="","",ROUND(KARYAWAN!$U11*ABSENSI!I11*(F11+G11)/PARAMETER!$C$9*PARAMETER!$C$10,0)) | K11: =IF($A11="","",KARYAWAN!$U11*ABSENSI!J11) | L11: =IF($A11="","",ROUND(KARYAWAN!$U11*ABSENSI!H11*F11/PARAMETER!$C$8,0)) | M11: =IF($A11="","",ROUND(MIN((F11+G11),PARAMETER!$E$24)*PARAMETER!$C$24+MIN((F11+G11),PARAMETER!$E$25)*PARAMETER!$C$25+MIN((F11+G11),PARAMETER!$E$26)*PARAMETER!$C$26,0)) | N11: =IF($A11="","",F11+G11+H11+I11+J11+K11-L11+M11) | O11: =IF($A11="","",X11) | P11: =IF($A11="","",ROUND(MIN((F11+G11),PARAMETER!$E$22)*PARAMETER!$D$22,0)) | Q11: =IF($A11="","",ROUND(MIN((F11+G11),PARAMETER!$E$23)*PARAMETER!$D$23,0)) | R11: =IF($A11="","",ROUND(MIN((F11+G11),PARAMETER!$E$26)*PARAMETER!$D$26,0)) | S11: =IF($A11="","",KARYAWAN!$U11*ABSENSI!K11) | T11: =IF($A11="","",F11+G11+H11+I11+J11+K11-L11-O11-P11-Q11-R11-S11) | U11: =IF($A11="","",M11+ROUND(MIN((F11+G11),PARAMETER!$E$22)*PARAMETER!$C$22,0)+ROUND(MIN((F11+G11),PARAMETER!$E$23)*PARAMETER!$C$23,0)) | V11: =IF($A11="","",F11+G11+H11+I11+J11+K11-L11+U11) | W11: =IF($A11="","",IF(E11="A",INDEX(TARIF_TER!$C$7:$C$50,MATCH(N11,TARIF_TER!$B$7:$B$50,1)),IF(E11="B",INDEX(TARIF_TER!$F$7:$F$46,MATCH(N11,TARIF_TER!$E$7:$E$46,1)),INDEX(TARIF_TER!$I$7:$I$47,MATCH(N11,TARIF_TER!$H$7:$H$47,1))))) | X11: =IF($A11="","",ROUND(N11*W11,0))
A12: =IF(KARYAWAN!A12="","",KARYAWAN!A12) | B12: =IF($A12="","",KARYAWAN!B12) | C12: =IF($A12="","",KARYAWAN!E12) | D12: =IF($A12="","",KARYAWAN!J12) | E12: =IF($A12="","",KARYAWAN!T12) | F12: =IF($A12="","",KARYAWAN!$U12*KARYAWAN!K12) | G12: =IF($A12="","",KARYAWAN!$U12*KARYAWAN!L12) | H12: =IF($A12="","",KARYAWAN!$U12*ABSENSI!D12*PARAMETER!$C$11) | I12: =IF($A12="","",KARYAWAN!$U12*ABSENSI!D12*PARAMETER!$C$12) | J12: =IF($A12="","",ROUND(KARYAWAN!$U12*ABSENSI!I12*(F12+G12)/PARAMETER!$C$9*PARAMETER!$C$10,0)) | K12: =IF($A12="","",KARYAWAN!$U12*ABSENSI!J12) | L12: =IF($A12="","",ROUND(KARYAWAN!$U12*ABSENSI!H12*F12/PARAMETER!$C$8,0)) | M12: =IF($A12="","",ROUND(MIN((F12+G12),PARAMETER!$E$24)*PARAMETER!$C$24+MIN((F12+G12),PARAMETER!$E$25)*PARAMETER!$C$25+MIN((F12+G12),PARAMETER!$E$26)*PARAMETER!$C$26,0)) | N12: =IF($A12="","",F12+G12+H12+I12+J12+K12-L12+M12) | O12: =IF($A12="","",X12) | P12: =IF($A12="","",ROUND(MIN((F12+G12),PARAMETER!$E$22)*PARAMETER!$D$22,0)) | Q12: =IF($A12="","",ROUND(MIN((F12+G12),PARAMETER!$E$23)*PARAMETER!$D$23,0)) | R12: =IF($A12="","",ROUND(MIN((F12+G12),PARAMETER!$E$26)*PARAMETER!$D$26,0)) | S12: =IF($A12="","",KARYAWAN!$U12*ABSENSI!K12) | T12: =IF($A12="","",F12+G12+H12+I12+J12+K12-L12-O12-P12-Q12-R12-S12) | U12: =IF($A12="","",M12+ROUND(MIN((F12+G12),PARAMETER!$E$22)*PARAMETER!$C$22,0)+ROUND(MIN((F12+G12),PARAMETER!$E$23)*PARAMETER!$C$23,0)) | V12: =IF($A12="","",F12+G12+H12+I12+J12+K12-L12+U12) | W12: =IF($A12="","",IF(E12="A",INDEX(TARIF_TER!$C$7:$C$50,MATCH(N12,TARIF_TER!$B$7:$B$50,1)),IF(E12="B",INDEX(TARIF_TER!$F$7:$F$46,MATCH(N12,TARIF_TER!$E$7:$E$46,1)),INDEX(TARIF_TER!$I$7:$I$47,MATCH(N12,TARIF_TER!$H$7:$H$47,1))))) | X12: =IF($A12="","",ROUND(N12*W12,0))
A13: =IF(KARYAWAN!A13="","",KARYAWAN!A13) | B13: =IF($A13="","",KARYAWAN!B13) | C13: =IF($A13="","",KARYAWAN!E13) | D13: =IF($A13="","",KARYAWAN!J13) | E13: =IF($A13="","",KARYAWAN!T13) | F13: =IF($A13="","",KARYAWAN!$U13*KARYAWAN!K13) | G13: =IF($A13="","",KARYAWAN!$U13*KARYAWAN!L13) | H13: =IF($A13="","",KARYAWAN!$U13*ABSENSI!D13*PARAMETER!$C$11) | I13: =IF($A13="","",KARYAWAN!$U13*ABSENSI!D13*PARAMETER!$C$12) | J13: =IF($A13="","",ROUND(KARYAWAN!$U13*ABSENSI!I13*(F13+G13)/PARAMETER!$C$9*PARAMETER!$C$10,0)) | K13: =IF($A13="","",KARYAWAN!$U13*ABSENSI!J13) | L13: =IF($A13="","",ROUND(KARYAWAN!$U13*ABSENSI!H13*F13/PARAMETER!$C$8,0)) | M13: =IF($A13="","",ROUND(MIN((F13+G13),PARAMETER!$E$24)*PARAMETER!$C$24+MIN((F13+G13),PARAMETER!$E$25)*PARAMETER!$C$25+MIN((F13+G13),PARAMETER!$E$26)*PARAMETER!$C$26,0)) | N13: =IF($A13="","",F13+G13+H13+I13+J13+K13-L13+M13) | O13: =IF($A13="","",X13) | P13: =IF($A13="","",ROUND(MIN((F13+G13),PARAMETER!$E$22)*PARAMETER!$D$22,0)) | Q13: =IF($A13="","",ROUND(MIN((F13+G13),PARAMETER!$E$23)*PARAMETER!$D$23,0)) | R13: =IF($A13="","",ROUND(MIN((F13+G13),PARAMETER!$E$26)*PARAMETER!$D$26,0)) | S13: =IF($A13="","",KARYAWAN!$U13*ABSENSI!K13) | T13: =IF($A13="","",F13+G13+H13+I13+J13+K13-L13-O13-P13-Q13-R13-S13) | U13: =IF($A13="","",M13+ROUND(MIN((F13+G13),PARAMETER!$E$22)*PARAMETER!$C$22,0)+ROUND(MIN((F13+G13),PARAMETER!$E$23)*PARAMETER!$C$23,0)) | V13: =IF($A13="","",F13+G13+H13+I13+J13+K13-L13+U13) | W13: =IF($A13="","",IF(E13="A",INDEX(TARIF_TER!$C$7:$C$50,MATCH(N13,TARIF_TER!$B$7:$B$50,1)),IF(E13="B",INDEX(TARIF_TER!$F$7:$F$46,MATCH(N13,TARIF_TER!$E$7:$E$46,1)),INDEX(TARIF_TER!$I$7:$I$47,MATCH(N13,TARIF_TER!$H$7:$H$47,1))))) | X13: =IF($A13="","",ROUND(N13*W13,0))
A14: =IF(KARYAWAN!A14="","",KARYAWAN!A14) | B14: =IF($A14="","",KARYAWAN!B14) | C14: =IF($A14="","",KARYAWAN!E14) | D14: =IF($A14="","",KARYAWAN!J14) | E14: =IF($A14="","",KARYAWAN!T14) | F14: =IF($A14="","",KARYAWAN!$U14*KARYAWAN!K14) | G14: =IF($A14="","",KARYAWAN!$U14*KARYAWAN!L14) | H14: =IF($A14="","",KARYAWAN!$U14*ABSENSI!D14*PARAMETER!$C$11) | I14: =IF($A14="","",KARYAWAN!$U14*ABSENSI!D14*PARAMETER!$C$12) | J14: =IF($A14="","",ROUND(KARYAWAN!$U14*ABSENSI!I14*(F14+G14)/PARAMETER!$C$9*PARAMETER!$C$10,0)) | K14: =IF($A14="","",KARYAWAN!$U14*ABSENSI!J14) | L14: =IF($A14="","",ROUND(KARYAWAN!$U14*ABSENSI!H14*F14/PARAMETER!$C$8,0)) | M14: =IF($A14="","",ROUND(MIN((F14+G14),PARAMETER!$E$24)*PARAMETER!$C$24+MIN((F14+G14),PARAMETER!$E$25)*PARAMETER!$C$25+MIN((F14+G14),PARAMETER!$E$26)*PARAMETER!$C$26,0)) | N14: =IF($A14="","",F14+G14+H14+I14+J14+K14-L14+M14) | O14: =IF($A14="","",X14) | P14: =IF($A14="","",ROUND(MIN((F14+G14),PARAMETER!$E$22)*PARAMETER!$D$22,0)) | Q14: =IF($A14="","",ROUND(MIN((F14+G14),PARAMETER!$E$23)*PARAMETER!$D$23,0)) | R14: =IF($A14="","",ROUND(MIN((F14+G14),PARAMETER!$E$26)*PARAMETER!$D$26,0)) | S14: =IF($A14="","",KARYAWAN!$U14*ABSENSI!K14) | T14: =IF($A14="","",F14+G14+H14+I14+J14+K14-L14-O14-P14-Q14-R14-S14) | U14: =IF($A14="","",M14+ROUND(MIN((F14+G14),PARAMETER!$E$22)*PARAMETER!$C$22,0)+ROUND(MIN((F14+G14),PARAMETER!$E$23)*PARAMETER!$C$23,0)) | V14: =IF($A14="","",F14+G14+H14+I14+J14+K14-L14+U14) | W14: =IF($A14="","",IF(E14="A",INDEX(TARIF_TER!$C$7:$C$50,MATCH(N14,TARIF_TER!$B$7:$B$50,1)),IF(E14="B",INDEX(TARIF_TER!$F$7:$F$46,MATCH(N14,TARIF_TER!$E$7:$E$46,1)),INDEX(TARIF_TER!$I$7:$I$47,MATCH(N14,TARIF_TER!$H$7:$H$47,1))))) | X14: =IF($A14="","",ROUND(N14*W14,0))
A15: =IF(KARYAWAN!A15="","",KARYAWAN!A15) | B15: =IF($A15="","",KARYAWAN!B15) | C15: =IF($A15="","",KARYAWAN!E15) | D15: =IF($A15="","",KARYAWAN!J15) | E15: =IF($A15="","",KARYAWAN!T15) | F15: =IF($A15="","",KARYAWAN!$U15*KARYAWAN!K15) | G15: =IF($A15="","",KARYAWAN!$U15*KARYAWAN!L15) | H15: =IF($A15="","",KARYAWAN!$U15*ABSENSI!D15*PARAMETER!$C$11) | I15: =IF($A15="","",KARYAWAN!$U15*ABSENSI!D15*PARAMETER!$C$12) | J15: =IF($A15="","",ROUND(KARYAWAN!$U15*ABSENSI!I15*(F15+G15)/PARAMETER!$C$9*PARAMETER!$C$10,0)) | K15: =IF($A15="","",KARYAWAN!$U15*ABSENSI!J15) | L15: =IF($A15="","",ROUND(KARYAWAN!$U15*ABSENSI!H15*F15/PARAMETER!$C$8,0)) | M15: =IF($A15="","",ROUND(MIN((F15+G15),PARAMETER!$E$24)*PARAMETER!$C$24+MIN((F15+G15),PARAMETER!$E$25)*PARAMETER!$C$25+MIN((F15+G15),PARAMETER!$E$26)*PARAMETER!$C$26,0)) | N15: =IF($A15="","",F15+G15+H15+I15+J15+K15-L15+M15) | O15: =IF($A15="","",X15) | P15: =IF($A15="","",ROUND(MIN((F15+G15),PARAMETER!$E$22)*PARAMETER!$D$22,0)) | Q15: =IF($A15="","",ROUND(MIN((F15+G15),PARAMETER!$E$23)*PARAMETER!$D$23,0)) | R15: =IF($A15="","",ROUND(MIN((F15+G15),PARAMETER!$E$26)*PARAMETER!$D$26,0)) | S15: =IF($A15="","",KARYAWAN!$U15*ABSENSI!K15) | T15: =IF($A15="","",F15+G15+H15+I15+J15+K15-L15-O15-P15-Q15-R15-S15) | U15: =IF($A15="","",M15+ROUND(MIN((F15+G15),PARAMETER!$E$22)*PARAMETER!$C$22,0)+ROUND(MIN((F15+G15),PARAMETER!$E$23)*PARAMETER!$C$23,0)) | V15: =IF($A15="","",F15+G15+H15+I15+J15+K15-L15+U15) | W15: =IF($A15="","",IF(E15="A",INDEX(TARIF_TER!$C$7:$C$50,MATCH(N15,TARIF_TER!$B$7:$B$50,1)),IF(E15="B",INDEX(TARIF_TER!$F$7:$F$46,MATCH(N15,TARIF_TER!$E$7:$E$46,1)),INDEX(TARIF_TER!$I$7:$I$47,MATCH(N15,TARIF_TER!$H$7:$H$47,1))))) | X15: =IF($A15="","",ROUND(N15*W15,0))
A16: =IF(KARYAWAN!A16="","",KARYAWAN!A16) | B16: =IF($A16="","",KARYAWAN!B16) | C16: =IF($A16="","",KARYAWAN!E16) | D16: =IF($A16="","",KARYAWAN!J16) | E16: =IF($A16="","",KARYAWAN!T16) | F16: =IF($A16="","",KARYAWAN!$U16*KARYAWAN!K16) | G16: =IF($A16="","",KARYAWAN!$U16*KARYAWAN!L16) | H16: =IF($A16="","",KARYAWAN!$U16*ABSENSI!D16*PARAMETER!$C$11) | I16: =IF($A16="","",KARYAWAN!$U16*ABSENSI!D16*PARAMETER!$C$12) | J16: =IF($A16="","",ROUND(KARYAWAN!$U16*ABSENSI!I16*(F16+G16)/PARAMETER!$C$9*PARAMETER!$C$10,0)) | K16: =IF($A16="","",KARYAWAN!$U16*ABSENSI!J16) | L16: =IF($A16="","",ROUND(KARYAWAN!$U16*ABSENSI!H16*F16/PARAMETER!$C$8,0)) | M16: =IF($A16="","",ROUND(MIN((F16+G16),PARAMETER!$E$24)*PARAMETER!$C$24+MIN((F16+G16),PARAMETER!$E$25)*PARAMETER!$C$25+MIN((F16+G16),PARAMETER!$E$26)*PARAMETER!$C$26,0)) | N16: =IF($A16="","",F16+G16+H16+I16+J16+K16-L16+M16) | O16: =IF($A16="","",X16) | P16: =IF($A16="","",ROUND(MIN((F16+G16),PARAMETER!$E$22)*PARAMETER!$D$22,0)) | Q16: =IF($A16="","",ROUND(MIN((F16+G16),PARAMETER!$E$23)*PARAMETER!$D$23,0)) | R16: =IF($A16="","",ROUND(MIN((F16+G16),PARAMETER!$E$26)*PARAMETER!$D$26,0)) | S16: =IF($A16="","",KARYAWAN!$U16*ABSENSI!K16) | T16: =IF($A16="","",F16+G16+H16+I16+J16+K16-L16-O16-P16-Q16-R16-S16) | U16: =IF($A16="","",M16+ROUND(MIN((F16+G16),PARAMETER!$E$22)*PARAMETER!$C$22,0)+ROUND(MIN((F16+G16),PARAMETER!$E$23)*PARAMETER!$C$23,0)) | V16: =IF($A16="","",F16+G16+H16+I16+J16+K16-L16+U16) | W16: =IF($A16="","",IF(E16="A",INDEX(TARIF_TER!$C$7:$C$50,MATCH(N16,TARIF_TER!$B$7:$B$50,1)),IF(E16="B",INDEX(TARIF_TER!$F$7:$F$46,MATCH(N16,TARIF_TER!$E$7:$E$46,1)),INDEX(TARIF_TER!$I$7:$I$47,MATCH(N16,TARIF_TER!$H$7:$H$47,1))))) | X16: =IF($A16="","",ROUND(N16*W16,0))
A17: =IF(KARYAWAN!A17="","",KARYAWAN!A17) | B17: =IF($A17="","",KARYAWAN!B17) | C17: =IF($A17="","",KARYAWAN!E17) | D17: =IF($A17="","",KARYAWAN!J17) | E17: =IF($A17="","",KARYAWAN!T17) | F17: =IF($A17="","",KARYAWAN!$U17*KARYAWAN!K17) | G17: =IF($A17="","",KARYAWAN!$U17*KARYAWAN!L17) | H17: =IF($A17="","",KARYAWAN!$U17*ABSENSI!D17*PARAMETER!$C$11) | I17: =IF($A17="","",KARYAWAN!$U17*ABSENSI!D17*PARAMETER!$C$12) | J17: =IF($A17="","",ROUND(KARYAWAN!$U17*ABSENSI!I17*(F17+G17)/PARAMETER!$C$9*PARAMETER!$C$10,0)) | K17: =IF($A17="","",KARYAWAN!$U17*ABSENSI!J17) | L17: =IF($A17="","",ROUND(KARYAWAN!$U17*ABSENSI!H17*F17/PARAMETER!$C$8,0)) | M17: =IF($A17="","",ROUND(MIN((F17+G17),PARAMETER!$E$24)*PARAMETER!$C$24+MIN((F17+G17),PARAMETER!$E$25)*PARAMETER!$C$25+MIN((F17+G17),PARAMETER!$E$26)*PARAMETER!$C$26,0)) | N17: =IF($A17="","",F17+G17+H17+I17+J17+K17-L17+M17) | O17: =IF($A17="","",X17) | P17: =IF($A17="","",ROUND(MIN((F17+G17),PARAMETER!$E$22)*PARAMETER!$D$22,0)) | Q17: =IF($A17="","",ROUND(MIN((F17+G17),PARAMETER!$E$23)*PARAMETER!$D$23,0)) | R17: =IF($A17="","",ROUND(MIN((F17+G17),PARAMETER!$E$26)*PARAMETER!$D$26,0)) | S17: =IF($A17="","",KARYAWAN!$U17*ABSENSI!K17) | T17: =IF($A17="","",F17+G17+H17+I17+J17+K17-L17-O17-P17-Q17-R17-S17) | U17: =IF($A17="","",M17+ROUND(MIN((F17+G17),PARAMETER!$E$22)*PARAMETER!$C$22,0)+ROUND(MIN((F17+G17),PARAMETER!$E$23)*PARAMETER!$C$23,0)) | V17: =IF($A17="","",F17+G17+H17+I17+J17+K17-L17+U17) | W17: =IF($A17="","",IF(E17="A",INDEX(TARIF_TER!$C$7:$C$50,MATCH(N17,TARIF_TER!$B$7:$B$50,1)),IF(E17="B",INDEX(TARIF_TER!$F$7:$F$46,MATCH(N17,TARIF_TER!$E$7:$E$46,1)),INDEX(TARIF_TER!$I$7:$I$47,MATCH(N17,TARIF_TER!$H$7:$H$47,1))))) | X17: =IF($A17="","",ROUND(N17*W17,0))
... A20: =IF(KARYAWAN!A20="","",KARYAWAN!A20) | B20: =IF($A20="","",KARYAWAN!B20) | C20: =IF($A20="","",KARYAWAN!E20) | D20: =IF($A20="","",KARYAWAN!J20) | E20: =IF($A20="","",KARYAWAN!T20) | F20: =IF($A20="","",KARYAWAN!$U20*KARYAWAN!K20) | G20: =IF($A20="","",KARYAWAN!$U20*KARYAWAN!L20) | H20: =IF($A20="","",KARYAWAN!$U20*ABSENSI!D20*PARAMETER!$C$11) | I20: =IF($A20="","",KARYAWAN!$U20*ABSENSI!D20*PARAMETER!$C$12) | J20: =IF($A20="","",ROUND(KARYAWAN!$U20*ABSENSI!I20*(F20+G20)/PARAMETER!$C$9*PARAMETER!$C$10,0)) | K20: =IF($A20="","",KARYAWAN!$U20*ABSENSI!J20) | L20: =IF($A20="","",ROUND(KARYAWAN!$U20*ABSENSI!H20*F20/PARAMETER!$C$8,0)) | M20: =IF($A20="","",ROUND(MIN((F20+G20),PARAMETER!$E$24)*PARAMETER!$C$24+MIN((F20+G20),PARAMETER!$E$25)*PARAMETER!$C$25+MIN((F20+G20),PARAMETER!$E$26)*PARAMETER!$C$26,0)) | N20: =IF($A20="","",F20+G20+H20+I20+J20+K20-L20+M20) | O20: =IF($A20="","",X20) | P20: =IF($A20="","",ROUND(MIN((F20+G20),PARAMETER!$E$22)*PARAMETER!$D$22,0)) | Q20: =IF($A20="","",ROUND(MIN((F20+G20),PARAMETER!$E$23)*PARAMETER!$D$23,0)) | R20: =IF($A20="","",ROUND(MIN((F20+G20),PARAMETER!$E$26)*PARAMETER!$D$26,0)) | S20: =IF($A20="","",KARYAWAN!$U20*ABSENSI!K20) | T20: =IF($A20="","",F20+G20+H20+I20+J20+K20-L20-O20-P20-Q20-R20-S20) | U20: =IF($A20="","",M20+ROUND(MIN((F20+G20),PARAMETER!$E$22)*PARAMETER!$C$22,0)+ROUND(MIN((F20+G20),PARAMETER!$E$23)*PARAMETER!$C$23,0)) | V20: =IF($A20="","",F20+G20+H20+I20+J20+K20-L20+U20) | W20: =IF($A20="","",IF(E20="A",INDEX(TARIF_TER!$C$7:$C$50,MATCH(N20,TARIF_TER!$B$7:$B$50,1)),IF(E20="B",INDEX(TARIF_TER!$F$7:$F$46,MATCH(N20,TARIF_TER!$E$7:$E$46,1)),INDEX(TARIF_TER!$I$7:$I$47,MATCH(N20,TARIF_TER!$H$7:$H$47,1))))) | X20: =IF($A20="","",ROUND(N20*W20,0))

Sheet RINGKASAN
A1: Ringkasan SDM
A3: VERSI DEMO: kapasitas & fitur dibatasi, data simulasi. Versi lengkap: WhatsApp 089623291732
A5: Departemen | B5: Headcount aktif | C5: Total biaya perusahaan (Rp) | D5: Gaji bersih (Rp) | E5: PPh 21 (Rp)
A6: =IF(PARAMETER!B42="","",PARAMETER!B42) | B6: =IF($A6="","",COUNTIFS(KARYAWAN!$E$6:$E$20,$A6,KARYAWAN!$U$6:$U$20,1)) | C6: =IF($A6="","",SUMIFS(PAYROLL!$V$6:$V$20,PAYROLL!$C$6:$C$20,$A6)) | D6: =IF($A6="","",SUMIFS(PAYROLL!$T$6:$T$20,PAYROLL!$C$6:$C$20,$A6)) | E6: =IF($A6="","",SUMIFS(PAYROLL!$O$6:$O$20,PAYROLL!$C$6:$C$20,$A6))
A7: =IF(PARAMETER!B43="","",PARAMETER!B43) | B7: =IF($A7="","",COUNTIFS(KARYAWAN!$E$6:$E$20,$A7,KARYAWAN!$U$6:$U$20,1)) | C7: =IF($A7="","",SUMIFS(PAYROLL!$V$6:$V$20,PAYROLL!$C$6:$C$20,$A7)) | D7: =IF($A7="","",SUMIFS(PAYROLL!$T$6:$T$20,PAYROLL!$C$6:$C$20,$A7)) | E7: =IF($A7="","",SUMIFS(PAYROLL!$O$6:$O$20,PAYROLL!$C$6:$C$20,$A7))
A8: =IF(PARAMETER!B44="","",PARAMETER!B44) | B8: =IF($A8="","",COUNTIFS(KARYAWAN!$E$6:$E$20,$A8,KARYAWAN!$U$6:$U$20,1)) | C8: =IF($A8="","",SUMIFS(PAYROLL!$V$6:$V$20,PAYROLL!$C$6:$C$20,$A8)) | D8: =IF($A8="","",SUMIFS(PAYROLL!$T$6:$T$20,PAYROLL!$C$6:$C$20,$A8)) | E8: =IF($A8="","",SUMIFS(PAYROLL!$O$6:$O$20,PAYROLL!$C$6:$C$20,$A8))
A9: =IF(PARAMETER!B45="","",PARAMETER!B45) | B9: =IF($A9="","",COUNTIFS(KARYAWAN!$E$6:$E$20,$A9,KARYAWAN!$U$6:$U$20,1)) | C9: =IF($A9="","",SUMIFS(PAYROLL!$V$6:$V$20,PAYROLL!$C$6:$C$20,$A9)) | D9: =IF($A9="","",SUMIFS(PAYROLL!$T$6:$T$20,PAYROLL!$C$6:$C$20,$A9)) | E9: =IF($A9="","",SUMIFS(PAYROLL!$O$6:$O$20,PAYROLL!$C$6:$C$20,$A9))
A10: =IF(PARAMETER!B46="","",PARAMETER!B46) | B10: =IF($A10="","",COUNTIFS(KARYAWAN!$E$6:$E$20,$A10,KARYAWAN!$U$6:$U$20,1)) | C10: =IF($A10="","",SUMIFS(PAYROLL!$V$6:$V$20,PAYROLL!$C$6:$C$20,$A10)) | D10: =IF($A10="","",SUMIFS(PAYROLL!$T$6:$T$20,PAYROLL!$C$6:$C$20,$A10)) | E10: =IF($A10="","",SUMIFS(PAYROLL!$O$6:$O$20,PAYROLL!$C$6:$C$20,$A10))
A11: =IF(PARAMETER!B47="","",PARAMETER!B47) | B11: =IF($A11="","",COUNTIFS(KARYAWAN!$E$6:$E$20,$A11,KARYAWAN!$U$6:$U$20,1)) | C11: =IF($A11="","",SUMIFS(PAYROLL!$V$6:$V$20,PAYROLL!$C$6:$C$20,$A11)) | D11: =IF($A11="","",SUMIFS(PAYROLL!$T$6:$T$20,PAYROLL!$C$6:$C$20,$A11)) | E11: =IF($A11="","",SUMIFS(PAYROLL!$O$6:$O$20,PAYROLL!$C$6:$C$20,$A11))
A12: =IF(PARAMETER!B48="","",PARAMETER!B48) | B12: =IF($A12="","",COUNTIFS(KARYAWAN!$E$6:$E$20,$A12,KARYAWAN!$U$6:$U$20,1)) | C12: =IF($A12="","",SUMIFS(PAYROLL!$V$6:$V$20,PAYROLL!$C$6:$C$20,$A12)) | D12: =IF($A12="","",SUMIFS(PAYROLL!$T$6:$T$20,PAYROLL!$C$6:$C$20,$A12)) | E12: =IF($A12="","",SUMIFS(PAYROLL!$O$6:$O$20,PAYROLL!$C$6:$C$20,$A12))
A13: =IF(PARAMETER!B49="","",PARAMETER!B49) | B13: =IF($A13="","",COUNTIFS(KARYAWAN!$E$6:$E$20,$A13,KARYAWAN!$U$6:$U$20,1)) | C13: =IF($A13="","",SUMIFS(PAYROLL!$V$6:$V$20,PAYROLL!$C$6:$C$20,$A13)) | D13: =IF($A13="","",SUMIFS(PAYROLL!$T$6:$T$20,PAYROLL!$C$6:$C$20,$A13)) | E13: =IF($A13="","",SUMIFS(PAYROLL!$O$6:$O$20,PAYROLL!$C$6:$C$20,$A13))
A14: TOTAL | B14: =SUM(B6:B13) | C14: =SUM(C6:C13) | D14: =SUM(D6:D13) | E14: =SUM(E6:E13)

Sheet FULL-SLIP_GAJI
B2: Fitur Versi Lengkap
B3: SLIP GAJI
B5: Slip gaji siap cetak: pilih ID karyawan, rincian pendapatan, potongan, dan gaji bersih.
B7: • Sheet ini hanya tersedia di versi lengkap, lengkap dengan rumus dan grafik yang bekerja dari data Anda.
B8: • Kapasitas data versi lengkap jauh lebih besar dibanding demo.
B9: • Pesan versi lengkap lewat WhatsApp 089623291732.

Sheet FULL-CUTI
B2: Fitur Versi Lengkap
B3: CUTI
B5: Saldo cuti tahunan per karyawan (hak, terpakai, menunggu, sisa, status).
B7: • Sheet ini hanya tersedia di versi lengkap, lengkap dengan rumus dan grafik yang bekerja dari data Anda.
B8: • Kapasitas data versi lengkap jauh lebih besar dibanding demo.
B9: • Pesan versi lengkap lewat WhatsApp 089623291732.

Sheet FULL-LOG_CUTI
B2: Fitur Versi Lengkap
B3: LOG CUTI
B5: Catatan pengajuan cuti (kapasitas 300): hari kerja dihitung otomatis dengan hari libur.
B7: • Sheet ini hanya tersedia di versi lengkap, lengkap dengan rumus dan grafik yang bekerja dari data Anda.
B8: • Kapasitas data versi lengkap jauh lebih besar dibanding demo.
B9: • Pesan versi lengkap lewat WhatsApp 089623291732.

Sheet FULL-LOWONGAN
B2: Fitur Versi Lengkap
B3: LOWONGAN
B5: Daftar lowongan: pelamar, dalam proses, diterima, sisa kebutuhan, hari terbuka.
B7: • Sheet ini hanya tersedia di versi lengkap, lengkap dengan rumus dan grafik yang bekerja dari data Anda.
B8: • Kapasitas data versi lengkap jauh lebih besar dibanding demo.
B9: • Pesan versi lengkap lewat WhatsApp 089623291732.

Sheet FULL-KANDIDAT
B2: Fitur Versi Lengkap
B3: KANDIDAT
B5: Pelacak kandidat (kapasitas 400) per tahap: lamaran sampai diterima.
B7: • Sheet ini hanya tersedia di versi lengkap, lengkap dengan rumus dan grafik yang bekerja dari data Anda.
B8: • Kapasitas data versi lengkap jauh lebih besar dibanding demo.
B9: • Pesan versi lengkap lewat WhatsApp 089623291732.

Sheet FULL-KINERJA
B2: Fitur Versi Lengkap
B3: KINERJA
B5: Penilaian KPI berbobot, rating, usulan bonus dan kenaikan gaji.
B7: • Sheet ini hanya tersedia di versi lengkap, lengkap dengan rumus dan grafik yang bekerja dari data Anda.
B8: • Kapasitas data versi lengkap jauh lebih besar dibanding demo.
B9: • Pesan versi lengkap lewat WhatsApp 089623291732.

Sheet FULL-PELATIHAN
B2: Fitur Versi Lengkap
B3: PELATIHAN
B5: Log pelatihan (kapasitas 300): jam dan biaya per karyawan dan departemen.
B7: • Sheet ini hanya tersedia di versi lengkap, lengkap dengan rumus dan grafik yang bekerja dari data Anda.
B8: • Kapasitas data versi lengkap jauh lebih besar dibanding demo.
B9: • Pesan versi lengkap lewat WhatsApp 089623291732.

Sheet FULL-DASHBOARD
B2: Fitur Versi Lengkap
B3: DASHBOARD
B5: Headcount, komposisi, turnover, biaya payroll, kinerja, pelatihan, rekrutmen, dalam angka dan grafik.
B7: • Sheet ini hanya tersedia di versi lengkap, lengkap dengan rumus dan grafik yang bekerja dari data Anda.
B8: • Kapasitas data versi lengkap jauh lebih besar dibanding demo.
B9: • Pesan versi lengkap lewat WhatsApp 089623291732.
